Workbook
Name cuatro1: #REF!
Name cuatro1: #REF!
Name cuatro10: #REF!
Name cuatro10: #REF!
Name cuatro2: #REF!
Name cuatro2: #REF!
Name cuatro3: #REF!
Name cuatro3: #REF!
Name cuatro4: #REF!
Name cuatro4: #REF!
Name cuatro5: #REF!
Name cuatro5: #REF!
Name cuatro6: #REF!
Name cuatro6: #REF!
Name cuatro7: #REF!
Name cuatro7: #REF!
Name cuatro8: #REF!
Name cuatro8: #REF!
Name cuatro9: #REF!
Name cuatro9: #REF!
Name DICIEMBRE: [1]PROMEDIO!#REF!
Name DICIEMBRE: #REF!
Name DICIEMBRE: [1]PROMEDIO!#REF!
Name FrequencyList: '[2]Report Form'!$D$4:$D$20
Name FrequencyList: '[3]Report Form'!$D$4:$D$20
Name FrequencyList2: '[4]Report Form'!$D$4:$D$20
Name FrequencyList2: '[5]Report Form'!$D$4:$D$20
Name junio: [1]PROMEDIO!#REF!
Name L: 'COMPOS CART'!$M$12
Name p: #REF!
Name PeriodList: '[2]Report Form'!$B$4:$B$34
Name PeriodList: '[3]Report Form'!$B$4:$B$34
Name PeriodList2: '[4]Report Form'!$B$4:$B$34
Name PeriodList2: '[5]Report Form'!$B$4:$B$34
Name Range_AllCurrencyTypes: [6]Control!$B$36:$B$38
Name Range_AllScaleTypes: [7]Control!$H$36:$H$39
Name Range_Country: [6]Control!$B$13
Name Range_DownloadDateTime: [6]Control!$B$14
Name Reporting_Country_Code: '[2]Report Form'!$M$2
Name Reporting_Country_Code: '[3]Report Form'!$M$2
Name Reporting_country_code_2: '[4]Report Form'!$M$2
Name Reporting_country_code_2: '[5]Report Form'!$M$2
Name Reporting_Country_Name: '[2]Report Form'!$M$3
Name Reporting_Country_Name: '[3]Report Form'!$M$3
Name Reporting_CountryCode: [6]Control!$B$28
Name Reporting_Currency_Code: '[2]Report Form'!$M$5
Name Reporting_Currency_Code: '[3]Report Form'!$M$5
Name Reporting_Currency_Code_2: '[4]Report Form'!$M$5
Name Reporting_Currency_Code_2: '[5]Report Form'!$M$5
Name Reporting_Currency_Name: '[2]Report Form'!$M$6
Name Reporting_Currency_Name: '[3]Report Form'!$M$6
Name reporting_currency_name_2: '[4]Report Form'!$M$6
Name reporting_currency_name_2: '[5]Report Form'!$M$6
Name Reporting_Scale_Name: '[2]Report Form'!$M$7
Name Reporting_Scale_Name: '[3]Report Form'!$M$7
Name Reporting_scale_name_2: '[4]Report Form'!$M$7
Name Reporting_scale_name_2: '[5]Report Form'!$M$7
Name t: #REF!
Name t: #REF!
Name wrqwer: #REF!

Sheet Homologación
C1: CATÁLOGO ÚNICO DE CUENTAS PARA USO DE LAS ENTIDADES DE LOS SECTORES FINANCIEROS PÚBLICO Y PRIVADO CODIFICACIÓN DE CUENTAS
A2: CUENTA | B2: largo | C2: CÓDIGO 2015 | D2: PLAN DE CUENTAS 2015 | E2: BP | F2: TH | G2: CFN | H2: BEV | I2: BEDE | J2: BFN | K2: BANEC | L2: CC | M2: ALM | N2: SGC | Q2: CÓDIGO 2021 | R2: PLAN DE CUENTAS 2021 | S2: HOMOLOGACION 2021 2015
A3: CUENTA | C3: CÓDIGO 2015 | D3: PLAN DE CUENTAS 2015 | E3: BP | F3: TH | G3: CFN | H3: BEV | I3: BEDE | J3: BNF | K3: BANEC | L3: CC | M3: ALM | N3: SGC | Q3: CÓDIGO 2021 | R3: PLAN DE CUENTAS 2021 | S3: HOMOLOGACION 2021 2015
B4: =LEN(C4) -> 1 | C4: 1 | D4: ACTIVO | E4: BP | F4: TH | G4: CFN | H4: BEV | I4: BEDE | J4: BFN | K4: BANEC | L4: CC | M4: ALM | N4: SGC | O4: GF | Q4: 1 | R4: ACTIVO | S4: =+C4 -> 1
A5: 11 | B5: =LEN(C5) -> 2 | C5: 11 | D5: FONDOS DISPONIBLES | E5: X | F5: X | G5: X | H5: X | I5: X | J5: X | K5: X | L5: X | M5: X | N5: X | O5: X | Q5: 11 | R5: FONDOS DISPONIBLES | S5: =+C5 -> 11
A6: 1101 | B6: =LEN(C6) -> 4 | C6: 1101 | D6: Caja | E6: X | F6: X | G6: X | H6: X | I6: X | J6: X | K6: X | L6: X | M6: X | N6: X | O6: X | Q6: 1101 | R6: Caja | S6: =+C6 -> 1101
A7: 1101 | B7: =LEN(C7) -> 6 | C7: 110105 | D7: Efectivo | E7: X | F7: X | G7: X | H7: X | I7: X | J7: X | K7: X | L7: X | M7: X | N7: X | O7: X | Q7: 110105 | R7: Efectivo | S7: =+C7 -> 110105
A8: 1101 | B8: =LEN(C8) -> 6 | C8: 110110 | D8: Caja chica | E8: X | F8: X | G8: X | H8: X | I8: X | J8: X | K8: X | L8: X | M8: X | N8: X | O8: X | Q8: 110110 | R8: Caja chica | S8: =+C8 -> 110110
A9: 1102 | B9: =LEN(C9) -> 4 | C9: 1102 | D9: Depósitos para encaje | E9: X | F9: X | G9: X | H9: X | I9: X | J9: X | K9: X | O9: X | Q9: 1102 | R9: Depósitos para encaje | S9: =+C9 -> 1102
A10: 1102 | B10: =LEN(C10) -> 6 | C10: 110205 | D10: Banco Central del Ecuador | E10: X | F10: X | G10: X | H10: X | I10: X | J10: X | K10: X | O10: X | Q10: 110205 | R10: Banco Central del Ecuador | S10: =+C10 -> 110205
A11: 1102 | B11: =LEN(C11) -> 6 | C11: 110210 | D11: Banco Nacional de Fomento | E11: X | F11: X | H11: X | I11: X | O11: X | Q11: 110210 | R11: Banco Nacional de Fomento | S11: =+C11 -> 110210
A12: 1102 | B12: =LEN(C12) -> 6 | C12: 110215 | D12: Bancos locales | E12: X | F12: X | H12: X | I12: X | O12: X | Q12: 110215 | R12: Bancos locales | S12: =+C12 -> 110215
A13: 1103 | B13: =LEN(C13) -> 4 | C13: 1103 | D13: Bancos y otras instituciones financieras | E13: X | F13: X | G13: X | H13: X | I13: X | J13: X | K13: X | L13: X | M13: X | N13: X | O13: X | Q13: 1103 | R13: Bancos y otras instituciones financieras | S13: =+C13 -> 1103
A14: 1103 | B14: =LEN(C14) -> 6 | C14: 110305 | D14: Banco Central del Ecuador | E14: X | G14: X | I14: X | J14: X | K14: X | N14: X | O14: X | Q14: 110305 | R14: Banco Central del Ecuador | S14: =+C14 -> 110305
A15: 1103 | B15: =LEN(C15) -> 6 | C15: 110310 | D15: Bancos e instituciones financieras locales | E15: X | F15: X | G15: X | H15: X | I15: X | J15: X | K15: X | L15: X | M15: X | N15: X | O15: X | Q15: 110310 | R15: Bancos e instituciones financieras locales | S15: =+C15 -> 110310
A16: 1103 | B16: =LEN(C16) -> 6 | C16: 110315 | D16: Bancos e instituciones financieras del exterior | E16: X | F16: X | G16: X | J16: X | K16: X | L16: X | M16: X | N16: X | O16: X | Q16: 110315 | R16: Bancos e instituciones financieras del exterior | S16: =+C16 -> 110315
A17: 1104 | B17: =LEN(C17) -> 4 | C17: 1104 | D17: Efectos de cobro inmediato | E17: X | F17: X | G17: X | H17: X | I17: X | J17: X | K17: X | L17: X | M17: X | N17: X | O17: X | Q17: 1104 | R17: Efectos de cobro inmediato | S17: =+C17 -> 1104
A18: 1105 | B18: =LEN(C18) -> 4 | C18: 1105 | D18: Remesas en tránsito | E18: X | F18: X | G18: X | H18: X | I18: X | J18: X | K18: X | L18: X | M18: X | N18: X | O18: X | Q18: 1105 | R18: Remesas en tránsito | S18: =+C18 -> 1105
A19: 1105 | B19: =LEN(C19) -> 6 | C19: 110505 | D19: Del país | E19: X | F19: X | G19: X | H19: X | I19: X | J19: X | K19: X | L19: X | M19: X | N19: X | O19: X | Q19: 110505 | R19: Del país | S19: =+C19 -> 110505
A20: 1105 | B20: =LEN(C20) -> 6 | C20: 110510 | D20: Del exterior | E20: X | F20: X | G20: X | H20: X | I20: X | J20: X | K20: X | L20: X | M20: X | N20: X | O20: X | Q20: 110510 | R20: Del exterior | S20: =+C20 -> 110510
A21: 12 | B21: =LEN(C21) -> 2 | C21: 12 | D21: OPERACIONES INTERBANCARIAS | E21: X | F21: X | G21: X | H21: X | I21: X | J21: X | K21: X | L21: X | M21: X | N21: X | O21: X | Q21: 12 | R21: OPERACIONES INTERBANCARIAS | S21: =+C21 -> 12
A22: 1201 | B22: =LEN(C22) -> 4 | C22: 1201 | D22: Fondos interbancarios vendidos | E22: X | G22: X | H22: X | I22: X | J22: X | K22: X | O22: X | Q22: 1201 | R22: Fondos interbancarios vendidos | S22: =+C22 -> 1201
A23: 1201 | B23: =LEN(C23) -> 6 | C23: 120105 | D23: Bancos | E23: X | G23: X | H23: X | I23: X | J23: X | K23: X | O23: X | Q23: 120105 | R23: Bancos | S23: =+C23 -> 120105
A24: 1201 | B24: =LEN(C24) -> 6 | C24: 120110 | D24: Otras instituciones del sistema financiero | E24: X | G24: X | H24: X | I24: X | J24: X | K24: X | O24: X | Q24: 120110 | R24: Otras instituciones del sistema financiero | S24: =+C24 -> 120110
A25: 1202 | B25: =LEN(C25) -> 4 | C25: 1202 | D25: Operaciones de reporto con instituciones financieras | E25: X | F25: X | G25: X | H25: X | I25: X | J25: X | K25: X | L25: X | M25: X | N25: X | O25: X | Q25: 1202 | R25: Operaciones de reporto con instituciones financieras | S25: =+C25 -> 1202
A26: 1202 | B26: =LEN(C26) -> 6 | C26: 120205 | D26: Instituciones financieras públicas | E26: X | F26: X | G26: X | H26: X | I26: X | J26: X | K26: X | L26: X | M26: X | N26: X | O26: X | Q26: 120205 | R26: Instituciones financieras públicas | S26: =+C26 -> 120205
A27: 1202 | B27: =LEN(C27) -> 6 | C27: 120210 | D27: Bancos | E27: X | F27: X | G27: X | H27: X | I27: X | J27: X | K27: X | L27: X | M27: X | N27: X | O27: X | Q27: 120210 | R27: Bancos | S27: =+C27 -> 120210
A28: 1202 | B28: =LEN(C28) -> 6 | C28: 120215 | D28: Otras instituciones del sistema financiero | E28: X | F28: X | G28: X | H28: X | I28: X | J28: X | K28: X | L28: X | M28: X | N28: X | O28: X | Q28: 120215 | R28: Otras instituciones del sistema financiero | S28: =+C28 -> 120215
A29: 1299 | B29: =LEN(C29) -> 4 | C29: 1299 | D29: (Provisión para operaciones interbancarias y de reporto) | E29: X | F29: X | G29: X | H29: X | I29: X | J29: X | K29: X | L29: X | M29: X | N29: X | O29: X | Q29: 1299 | R29: (Provisión para operaciones interbancarias y de reporto) | S29: =+C29 -> 1299
A30: 1299 | B30: =LEN(C30) -> 6 | C30: 129905 | D30: (Provisión fondos interbancarios vendidos) | E30: X | G30: X | H30: X | I30: X | J30: X | K30: X | O30: X | Q30: 129905 | R30: (Provisión fondos interbancarios vendidos) | S30: =+C30 -> 129905
A31: 1299 | B31: =LEN(C31) -> 6 | C31: 129910 | D31: (Provisión para operaciones de reporto con instituciones financieras) | E31: X | F31: X | G31: X | H31: X | I31: X | J31: X | K31: X | L31: X | M31: X | N31: X | O31: X | Q31: 129910 | R31: (Provisión para operaciones de reporto con instituciones financieras) | S31: =+C31 -> 129910
A32: 13 | B32: =LEN(C32) -> 2 | C32: 13 | D32: INVERSIONES | E32: X | F32: X | G32: X | H32: X | I32: X | J32: X | K32: X | L32: X | M32: X | N32: X | O32: X | Q32: 13 | R32: INVERSIONES | S32: =+C32 -> 13
A33: 1301 | B33: =LEN(C33) -> 4 | C33: 1301 | D33: A valor razonable con cambios en el estado de resultados de entidades del sector privado | E33: X | F33: X | G33: X | H33: X | I33: X | J33: X | K33: X | L33: X | M33: X | N33: X | O33: X | Q33: 1301 | R33: A valor razonable con cambios en el estado de resultados de entidades del sector privado | S33: =+C33 -> 1301
A34: 1301 | B34: =LEN(C34) -> 6 | C34: 130105 | D34: De 1 a 30 días | E34: X | F34: X | G34: X | H34: X | I34: X | J34: X | K34: X | L34: X | M34: X | N34: X | O34: X | Q34: 130105 | R34: De 1 a 30 días | S34: =+C34 -> 130105
A35: 1301 | B35: =LEN(C35) -> 6 | C35: 130110 | D35: De 31 a 90 días | E35: X | F35: X | G35: X | H35: X | I35: X | J35: X | K35: X | L35: X | M35: X | N35: X | O35: X | Q35: 130110 | R35: De 31 a 90 días | S35: =+C35 -> 130110
A36: 1301 | B36: =LEN(C36) -> 6 | C36: 130115 | D36: De 91 a 180 días | E36: X | F36: X | G36: X | H36: X | I36: X | J36: X | K36: X | L36: X | M36: X | N36: X | O36: X | Q36: 130115 | R36: De 91 a 180 días | S36: =+C36 -> 130115
A37: 1301 | B37: =LEN(C37) -> 6 | C37: 130120 | D37: De 181 a 360 días | E37: X | F37: X | G37: X | H37: X | I37: X | J37: X | K37: X | L37: X | M37: X | N37: X | O37: X | Q37: 130120 | R37: De 181 a 360 días | S37: =+C37 -> 130120
A38: 1301 | B38: =LEN(C38) -> 6 | C38: 130125 | D38: De más de 360 días | E38: X | F38: X | G38: X | H38: X | I38: X | J38: X | K38: X | L38: X | M38: X | N38: X | O38: X | Q38: 130125 | R38: De más de 360 días | S38: =+C38 -> 130125
A39: 1302 | B39: =LEN(C39) -> 4 | C39: 1302 | D39: A valor razonable con cambios en el estado de resultados del Estado o de entidades del sector público | E39: X | F39: X | G39: X | H39: X | I39: X | J39: X | K39: X | L39: X | M39: X | N39: X | O39: X | Q39: 1302 | R39: A valor razonable con cambios en el estado de resultados del Estado o de entidades del sector público | S39: =+C39 -> 1302
A40: 1302 | B40: =LEN(C40) -> 6 | C40: 130205 | D40: De 1 a 30 días | E40: X | F40: X | G40: X | H40: X | I40: X | J40: X | K40: X | L40: X | M40: X | N40: X | O40: X | Q40: 130205 | R40: De 1 a 30 días | S40: =+C40 -> 130205
...

Sheet BALANCE
D1: 0 | E1: 0 | F1: 0 | G1: 0 | H1: 0 | I1: 0 | J1: 0 | K1: 0 | L1: 0 | M1: 0 | N1: 0 | O1: 0 | P1: 0 | Q1: 0 | R1: 0 | S1: 0 | T1: 0 | U1: 0 | V1: 0 | W1: 0 | X1: 0 | Y1: 0 | Z1: 0 | AA1: 0 | AB1: 0 | AC1: 0 | AD1: 0 | AE1: 0 | AF1: 0 | AG1: 4.6566129e-10 | AH1: 0 | AI1: 5.8207661e-11 | AJ1: 2.2351742e-08
B2: ESTADO DE SITUACIÓN | D2: 0 | E2: 1.8189894e-11 | F2: 0 | G2: 3.2741809e-11 | H2: -2.3283064e-10 | I2: 0 | J2: 0 | K2: 0 | L2: 0 | M2: 0 | N2: 0 | O2: 0 | P2: -4.5474735e-12 | Q2: -5.4569682e-12 | R2: 0 | S2: 4.206413e-12 | T2: -1.5276669e-13 | U2: 1.2789769e-13 | V2: 0 | W2: 0 | X2: 0 | Y2: 0 | Z2: 1.9895197e-13 | AA2: -1.080025e-12 | AB2: 0 | AC2: 0 | AD2: 1.0004442e-11 | AE2: 0 | AF2: 0 | AG2: 3.6379788e-11 | AH2: 0 | AI2: 0 | AJ2: 0
B3: SISTEMA DE BANCOS PRIVADOS
B4: 44439
B5: (en miles de dólares)
B8: CÓDIGO | C8: CUENTA | D8: BP GUAYAQUIL | E8: BP PACIFICO | F8: BP PICHINCHA | G8: BP PRODUBANCO | H8: BANCOS PRIVADOS GRANDES | I8: BP AUSTRO | J8: BP BOLIVARIANO | K8: BP CITIBANK | L8: BP DINERS | M8: BP GENERAL RUMIÑAHUI | N8: BP INTERNACIONAL | O8: BP LOJA | P8: BP MACHALA | Q8: BP SOLIDARIO | R8: BANCOS PRIVADOS MEDIANOS | S8: BP PROCREDIT | T8: BP AMAZONAS | U8: BP COMERCIAL DE MANABI | V8: BP LITORAL | W8: BP COOPNACIONAL | X8: BP CAPITAL | Y8: BP FINCA S.A. | Z8: BP DELBANK | AA8: BP D-MIRO S.A. | AB8: BP BANCO DESARROLLO DE LOS PUEBLOS S.A., CODESARROLLO | AC8: BP VISIONFUND ECUADOR S.A. | AD8: BANCOS PRIVADOS PEQUEÑOS | AE8: TOTAL BANCOS PRIVADOS | AF8: BANCOS PRIVADOS COMERCIALES | AG8: BANCOS PRIVADOS CONSUMO | AH8: BANCOS PRIVADOS VIVIENDA | AI8: BANCOS PRIVADOS DE MICROCRÉDITO | AJ8: BANCA MULTIPLE
B9: ACTIVO | C9: ACTIVO | D9: #N/A | E9: #N/A | F9: #N/A | G9: #N/A | I9: #N/A | J9: #N/A | K9: #N/A | L9: #N/A | M9: #N/A | N9: #N/A | O9: #N/A | P9: #N/A | Q9: #N/A | S9: #N/A | T9: #N/A | U9: #N/A | V9: #N/A | W9: #N/A | X9: #N/A | Y9: #N/A | Z9: #N/A | AA9: #N/A | AB9: #N/A | AC9: #N/A
B10: 11 | C10: FONDOS DISPONIBLES | D10: 851347.57 | E10: 1203729.2 | F10: 1740514.5 | G10: 895515.05 | H10: 4691106.3 | I10: 430335.96 | J10: 871739.42 | K10: 297817.12 | L10: 72585.907 | M10: 163183.69 | N10: 736322.44 | O10: 150658.3 | P10: 163296.08 | Q10: 72369.493 | R10: 2958308.4 | S10: 67381.47 | T10: 29676.345 | U10: 10340.623 | V10: 1984.3271 | W10: 59570.614 | X10: 3134.4886 | Y10: 9134.2929 | Z10: 6793.6288 | AA10: 7038.1645 | AB10: 23371.86 | AC10: 4390.1098 | AD10: 222815.92 | AE10: 7872230.6 | AF10: 1034139.6 | AG10: 237753.93 | AH10: 0 | AI10: 20562.567 | AJ10: 6579774.5
B11: 1101 | C11: Caja | D11: 202092.29 | E11: 242545.55 | F11: 286144.05 | G11: 111773.52 | H11: 842555.41 | I11: 63654.693 | J11: 170070.44 | K11: 653.2 | L11: 3.8 | M11: 15984.809 | N11: 86571.521 | O11: 20668.291 | P11: 25276.415 | Q11: 18975.428 | R11: 401858.59 | S11: 5429.2029 | T11: 4596.1246 | U11: 2910.2387 | V11: 508.30004 | W11: 8038.5995 | X11: 424.26849 | Y11: 743.1339 | Z11: 1907.2755 | AA11: 1523.319 | AB11: 4598.4674 | AC11: 814.35751 | AD11: 31493.288 | AE11: 1275907.3 | AF11: 87224.721 | AG11: 16496.909 | AH11: 0 | AI11: 3080.8104 | AJ11: 1169104.9
B12: 110105 | C12: Efectivo | D12: 202092.29 | E12: 242545.55 | F12: 286110.05 | G12: 111773.52 | H12: 842521.41 | I12: 63652.593 | J12: 170070.23 | K12: 653.2 | L12: 0 | M12: 15984.059 | N12: 86561.221 | O12: 20665.571 | P12: 25276.315 | Q12: 18957.428 | R12: 401820.62 | S12: 5429.2029 | T12: 4595.7246 | U12: 2910.1387 | V12: 507.27255 | W12: 8018.5995 | X12: 423.56849 | Y12: 739.3839 | Z12: 1906.8755 | AA12: 1523.319 | AB12: 4593.6674 | AC12: 802.85751 | AD12: 31450.61 | AE12: 1275792.6 | AF12: 87214.421 | AG12: 16491.331 | AH12: 0 | AI12: 3065.5604 | AJ12: 1169021.3
B13: 110110 | C13: Caja chica | D13: 0 | E13: 0 | F13: 34 | G13: 0 | H13: 34 | I13: 2.1 | J13: 0.20547 | K13: 0 | L13: 3.8 | M13: 0.75 | N13: 10.3 | O13: 2.72 | P13: 0.1 | Q13: 18 | R13: 37.97547 | S13: 0 | T13: 0.4 | U13: 0.1 | V13: 1.02749 | W13: 20 | X13: 0.7 | Y13: 3.75 | Z13: 0.4 | AA13: 0 | AB13: 4.8 | AC13: 11.5 | AD13: 42.67749 | AE13: 114.65296 | AF13: 10.3 | AG13: 5.57749 | AH13: 0 | AI13: 15.25 | AJ13: 83.52547
B14: 1102 | C14: Depósitos para encaje | D14: 508927.33 | E14: 819280.33 | F14: 1054553.1 | G14: 385722.35 | H14: 2768483.1 | I14: 233168.16 | J14: 261221.21 | K14: 117329.07 | L14: 27355.617 | M14: 22889.849 | N14: 336604.29 | O14: 90549.539 | P14: 66904.258 | Q14: 19048.414 | R14: 1175070.4 | S14: 30382.774 | T14: 10810.449 | U14: 5253.0565 | V14: 1213.8774 | W14: 3920.0003 | X14: 836.40884 | Y14: 5192.1089 | Z14: 1569.1817 | AA14: 1997.9862 | AB14: 8100.2283 | AC14: 394.27054 | AD14: 69670.342 | AE14: 4013223.8 | AF14: 453933.36 | AG14: 51459.343 | AH14: 0 | AI14: 7584.3656 | AJ14: 3500246.8
B15: 110205 | C15: Banco Central del Ecuador | D15: 508927.14 | E15: 819280.33 | F15: 1054553.1 | G15: 385722.35 | H15: 2768482.9 | I15: 233164.08 | J15: 261221.21 | K15: 117329.07 | L15: 27355.617 | M15: 22889.849 | N15: 336604.29 | O15: 90519.542 | P15: 66904.258 | Q15: 19048.414 | R15: 1175036.3 | S15: 30382.774 | T15: 10810.449 | U15: 5253.0565 | V15: 1213.8774 | W15: 3920.0003 | X15: 836.40884 | Y15: 5192.1089 | Z15: 1569.1817 | AA15: 1997.9862 | AB15: 8100.2283 | AC15: 394.27054 | AD15: 69670.342 | AE15: 4013189.6 | AF15: 453933.36 | AG15: 51459.343 | AH15: 0 | AI15: 7584.3656 | AJ15: 3500212.5
B16: 110210 | C16: Banco Nacional de Fomento | D16: 0 | E16: 0 | F16: 0 | G16: 0 | H16: 0 | I16: 4.08304 | J16: 0 | K16: 0 | L16: 0 | M16: 0 | N16: 0 | O16: 29.99731 | P16: 0 | Q16: 0 | R16: 34.08035 | S16: 0 | T16: 0 | U16: 0 | V16: 0 | W16: 0 | X16: 0 | Y16: 0 | Z16: 0 | AA16: 0 | AB16: 0 | AC16: 0 | AD16: 0 | AE16: 34.08035 | AF16: 0 | AG16: 0 | AH16: 0 | AI16: 0 | AJ16: 34.08035
B17: 110215 | C17: Bancos locales | D17: 0.19135 | E17: 0 | F17: 0 | G17: 0 | H17: 0.19135 | I17: 0 | J17: 0 | K17: 0 | L17: 0 | M17: 0 | N17: 0 | O17: 0 | P17: 0 | Q17: 0 | R17: 0 | S17: 0 | T17: 0 | U17: 0 | V17: 0 | W17: 0 | X17: 0 | Y17: 0 | Z17: 0 | AA17: 0 | AB17: 0 | AC17: 0 | AD17: 0 | AE17: 0.19135 | AF17: 0 | AG17: 0 | AH17: 0 | AI17: 0 | AJ17: 0.19135
B18: 1103 | C18: Bancos y otras instituciones financieras | D18: 103605.12 | E18: 94441.238 | F18: 282503.16 | G18: 329668.7 | H18: 810218.22 | I18: 128102.01 | J18: 388864.83 | K18: 176761.3 | L18: 45226.49 | M18: 88124.944 | N18: 290434.5 | O18: 36646.547 | P18: 65857.718 | Q18: 34144.486 | R18: 1254162.8 | S18: 30397.39 | T18: 13945.767 | U18: 1899.0149 | V18: 206.19702 | W18: 47523.491 | X18: 1792.0048 | Y18: 3194.3974 | Z18: 3303.7433 | AA18: 3507.9051 | AB18: 10209.184 | AC18: 3181.4818 | AD18: 119160.58 | AE18: 2183541.6 | AF18: 467195.8 | AG18: 133557.63 | AH18: 0 | AI18: 9883.7843 | AJ18: 1572904.4
B19: 110305 | C19: Banco Central del Ecuador | D19: 0 | E19: 0 | F19: 0 | G19: 0 | H19: 0 | I19: 0 | J19: 0 | K19: 0 | L19: 0 | M19: 0 | N19: 0 | O19: 0 | P19: 0 | Q19: 0 | R19: 0 | S19: 0 | T19: 0 | U19: 0 | V19: 0 | W19: 0 | X19: 0 | Y19: 0.123 | Z19: 0 | AA19: 0 | AB19: 0 | AC19: 0 | AD19: 0.123 | AE19: 0.123 | AF19: 0 | AG19: 0 | AH19: 0 | AI19: 0.123 | AJ19: 0
B20: 110310 | C20: Bancos e instituciones financieras locales | D20: 84319.642 | E20: 3915.5001 | F20: 5986.2384 | G20: 252519.75 | H20: 346741.13 | I20: 116245.48 | J20: 142015.11 | K20: 39919.589 | L20: 37931.276 | M20: 57229.965 | N20: 124818.68 | O20: 19655.831 | P20: 54606.788 | Q20: 12016.406 | R20: 604439.13 | S20: 22238.099 | T20: 12471.694 | U20: 1695.8697 | V20: 206.19702 | W20: 47523.491 | X20: 1778.0417 | Y20: 2250.5918 | Z20: 2903.4106 | AA20: 3507.9051 | AB20: 9160.0934 | AC20: 3181.4818 | AD20: 106916.88 | AE20: 1058097.1 | AF20: 164738.27 | AG20: 95367.439 | AH20: 0 | AI20: 8939.9786 | AJ20: 789051.45
B21: 110315 | C21: Bancos e instituciones financieras del exterior | D21: 19285.474 | E21: 90525.737 | F21: 141946.25 | G21: 77148.949 | H21: 328906.41 | I21: 11856.526 | J21: 246849.72 | K21: 133735.14 | L21: 7295.2135 | M21: 30894.978 | N21: 165615.83 | O21: 16990.716 | P21: 11250.93 | Q21: 22128.081 | R21: 646617.14 | S21: 8159.2906 | T21: 1474.0735 | U21: 203.14513 | V21: 0 | W21: 0 | X21: 13.96315 | Y21: 0 | Z21: 400.33273 | AA21: 0 | AB21: 1049.0905 | AC21: 0 | AD21: 11299.896 | AE21: 986823.44 | AF21: 299350.97 | AG21: 38190.192 | AH21: 0 | AI21: 0 | AJ21: 649282.28
B22: 110320 | C22: EXCEDENTE DE FONDO DE LIQUIDEZ | D22: 0 | E22: 0 | F22: 134570.68 | G22: 0 | H22: 134570.68 | I22: 0 | J22: 0 | K22: 3106.565 | L22: 0 | M22: 0 | N22: 0 | O22: 0 | P22: 0 | Q22: 0 | R22: 3106.565 | S22: 0 | T22: 0 | U22: 0 | V22: 0 | W22: 0 | X22: 0 | Y22: 943.68267 | Z22: 0 | AA22: 0 | AB22: 0 | AC22: 0 | AD22: 943.68267 | AE22: 138620.93
B23: 1104 | C23: Efectos de cobro inmediato | D23: 36722.834 | E23: 16350.502 | F23: 50577.92 | G23: 30210.061 | H23: 133861.32 | I23: 5411.0924 | J23: 33749.507 | K23: 3073.552 | L23: 0 | M23: 806.63097 | N23: 22711.618 | O23: 0 | P23: 2879.1237 | Q23: 196.16484 | R23: 68827.689 | S23: 1172.1026 | T23: 324.00372 | U23: 278.19511 | V23: 41.47253 | W23: 88.52325 | X23: 81.80643 | Y23: 4.6527 | Z23: 13.42829 | AA23: 0 | AB23: 78.53879 | AC23: 0 | AD23: 2082.7234 | AE23: 204771.73 | AF23: 25785.17 | AG23: 848.1035 | AH23: 0 | AI23: 4.6527 | AJ23: 178133.8
B24: 1105 | C24: Remesas en tránsito | D24: 0 | E24: 31111.537 | F24: 66736.268 | G24: 38140.424 | H24: 135988.23 | I24: 0 | J24: 17833.428 | K24: 0 | L24: 0 | M24: 35377.461 | N24: 0.51 | O24: 2793.9245 | P24: 2378.5658 | Q24: 5 | R24: 58388.89 | S24: 0 | T24: 0 | U24: 0.11793 | V24: 14.48016 | W24: 0 | X24: 0 | Y24: 0 | Z24: 0 | AA24: 8.95427 | AB24: 385.44135 | AC24: 0 | AD24: 408.99371 | AE24: 194786.11 | AF24: 0.51 | AG24: 35391.941 | AH24: 0 | AI24: 8.95427 | AJ24: 159384.71
B25: 110505 | C25: Del país | D25: 0 | E25: 31111.537 | F25: 66736.268 | G25: 37905.942 | H25: 135753.75 | I25: 0 | J25: 17819.862 | K25: 0 | L25: 0 | M25: 35377.461 | N25: 0 | O25: 2786.9806 | P25: 2378.5658 | Q25: 0 | R25: 58362.87 | S25: 0 | T25: 0 | U25: 0 | V25: 14.48016 | W25: 0 | X25: 0 | Y25: 0 | Z25: 0 | AA25: 8.95427 | AB25: 385.44135 | AC25: 0 | AD25: 408.87578 | AE25: 194525.49 | AF25: 0 | AG25: 35391.941 | AH25: 0 | AI25: 8.95427 | AJ25: 159124.6
B26: 110510 | C26: Del exterior | D26: 0 | E26: 0 | F26: 0 | G26: 234.48169 | H26: 234.48169 | I26: 0 | J26: 13.5656 | K26: 0 | L26: 0 | M26: 0 | N26: 0.51 | O26: 6.94389 | P26: 0 | Q26: 5 | R26: 26.01949 | S26: 0 | T26: 0 | U26: 0.11793 | V26: 0 | W26: 0 | X26: 0 | Y26: 0 | Z26: 0 | AA26: 0 | AB26: 0 | AC26: 0 | AD26: 0.11793 | AE26: 260.61911 | AF26: 0.51 | AG26: 0 | AH26: 0 | AI26: 0 | AJ26: 260.10911
B27: 12 | C27: OPERACIONES INTERBANCARIAS | D27: 0 | E27: 0 | F27: 0 | G27: 0 | H27: 0 | I27: 0 | J27: 0 | K27: 0 | L27: 0 | M27: 0 | N27: 0 | O27: 0 | P27: 0 | Q27: 0 | R27: 0 | S27: 0 | T27: 0 | U27: 0 | V27: 0 | W27: 0 | X27: 0 | Y27: 0 | Z27: 0 | AA27: 0 | AB27: 0 | AC27: 0 | AD27: 0 | AE27: 0 | AF27: 0 | AG27: 0 | AH27: 0 | AI27: 0 | AJ27: 0
B28: 1201 | C28: Fondos interbancarios vendidos | D28: 0 | E28: 0 | F28: 0 | G28: 0 | H28: 0 | I28: 0 | J28: 0 | K28: 0 | L28: 0 | M28: 0 | N28: 0 | O28: 0 | P28: 0 | Q28: 0 | R28: 0 | S28: 0 | T28: 0 | U28: 0 | V28: 0 | W28: 0 | X28: 0 | Y28: 0 | Z28: 0 | AA28: 0 | AB28: 0 | AC28: 0 | AD28: 0 | AE28: 0 | AF28: 0 | AG28: 0 | AH28: 0 | AI28: 0 | AJ28: 0
B29: 120105 | C29: Bancos | D29: 0 | E29: 0 | F29: 0 | G29: 0 | H29: 0 | I29: 0 | J29: 0 | K29: 0 | L29: 0 | M29: 0 | N29: 0 | O29: 0 | P29: 0 | Q29: 0 | R29: 0 | S29: 0 | T29: 0 | U29: 0 | V29: 0 | W29: 0 | X29: 0 | Y29: 0 | Z29: 0 | AA29: 0 | AB29: 0 | AC29: 0 | AD29: 0 | AE29: 0 | AF29: 0 | AG29: 0 | AH29: 0 | AI29: 0 | AJ29: 0
B30: 120110 | C30: Otras instituciones del sistema financiero | D30: 0 | E30: 0 | F30: 0 | G30: 0 | H30: 0 | I30: 0 | J30: 0 | K30: 0 | L30: 0 | M30: 0 | N30: 0 | O30: 0 | P30: 0 | Q30: 0 | R30: 0 | S30: 0 | T30: 0 | U30: 0 | V30: 0 | W30: 0 | X30: 0 | Y30: 0 | Z30: 0 | AA30: 0 | AB30: 0 | AC30: 0 | AD30: 0 | AE30: 0 | AF30: 0 | AG30: 0 | AH30: 0 | AI30: 0 | AJ30: 0
B31: 1202 | C31: Operaciones de reporto con instituciones financieras | D31: 0 | E31: 0 | F31: 0 | G31: 0 | H31: 0 | I31: 0 | J31: 0 | K31: 0 | L31: 0 | M31: 0 | N31: 0 | O31: 0 | P31: 0 | Q31: 0 | R31: 0 | S31: 0 | T31: 0 | U31: 0 | V31: 0 | W31: 0 | X31: 0 | Y31: 0 | Z31: 0 | AA31: 0 | AB31: 0 | AC31: 0 | AD31: 0 | AE31: 0 | AF31: 0 | AG31: 0 | AH31: 0 | AI31: 0 | AJ31: 0
B32: 120205 | C32: Instituciones financieras públicas | D32: 0 | E32: 0 | F32: 0 | G32: 0 | H32: 0 | I32: 0 | J32: 0 | K32: 0 | L32: 0 | M32: 0 | N32: 0 | O32: 0 | P32: 0 | Q32: 0 | R32: 0 | S32: 0 | T32: 0 | U32: 0 | V32: 0 | W32: 0 | X32: 0 | Y32: 0 | Z32: 0 | AA32: 0 | AB32: 0 | AC32: 0 | AD32: 0 | AE32: 0 | AF32: 0 | AG32: 0 | AH32: 0 | AI32: 0 | AJ32: 0
B33: 120210 | C33: Bancos | D33: 0 | E33: 0 | F33: 0 | G33: 0 | H33: 0 | I33: 0 | J33: 0 | K33: 0 | L33: 0 | M33: 0 | N33: 0 | O33: 0 | P33: 0 | Q33: 0 | R33: 0 | S33: 0 | T33: 0 | U33: 0 | V33: 0 | W33: 0 | X33: 0 | Y33: 0 | Z33: 0 | AA33: 0 | AB33: 0 | AC33: 0 | AD33: 0 | AE33: 0 | AF33: 0 | AG33: 0 | AH33: 0 | AI33: 0 | AJ33: 0
B34: 120215 | C34: Otras instituciones del sistema financiero | D34: 0 | E34: 0 | F34: 0 | G34: 0 | H34: 0 | I34: 0 | J34: 0 | K34: 0 | L34: 0 | M34: 0 | N34: 0 | O34: 0 | P34: 0 | Q34: 0 | R34: 0 | S34: 0 | T34: 0 | U34: 0 | V34: 0 | W34: 0 | X34: 0 | Y34: 0 | Z34: 0 | AA34: 0 | AB34: 0 | AC34: 0 | AD34: 0 | AE34: 0 | AF34: 0 | AG34: 0 | AH34: 0 | AI34: 0 | AJ34: 0
... B90: 139910 | C90: (Provisión general para inversiones) | D90: -6057.6105 | E90: -2635 | F90: 0 | G90: 0 | H90: -8692.6105 | I90: 0 | J90: -1156.1564 | K90: 0 | L90: 0 | M90: -6704.2211 | N90: -2.3 | O90: 0 | P90: 0 | Q90: 0 | R90: -7862.6775 | S90: 0 | T90: 0 | U90: -78.69071 | V90: 0 | W90: -110.06781 | X90: 0 | Y90: 0 | Z90: 0 | AA90: 0 | AB90: 0 | AC90: 0 | AD90: -188.75852 | AE90: -16744.047 | AF90: -2.3 | AG90: -6704.2211 | AH90: 0 | AI90: 0 | AJ90: -10037.525
A91: 2 | B91: 14 | C91: CARTERA DE CRÉDITOS | D91: 3680242.8 | E91: 4109265.9 | F91: 6866034.2 | G91: 3511766.6 | H91: 18167310 | I91: 1174443.8 | J91: 2370883.9 | K91: 184852.06 | L91: 1785415.2 | M91: 610152.75 | N91: 2428345.8 | O91: 354916.54 | P91: 528634.4 | Q91: 532636.33 | R91: 9970280.8 | S91: 433689.51 | T91: 125240.75 | U91: 30152.521 | V91: 26897.07 | W91: 86662.114 | X91: 14591.048 | Y91: 66210.444 | Z91: 15485.992 | AA91: 74316.385 | AB91: 153865.92 | AC91: 77705.929 | AD91: 1104817.7 | AE91: 29242408 | AF91: 2613197.9 | AG91: 2422465 | AH91: 0 | AI91: 218232.76 | AJ91: 23988512
A92: 4 | B92: 1401 | C92: CARTERA DE CRÉDITOS PRODUCTIVO POR VENCER | D92: 1962543.7 | E92: 875507.94 | F92: 2724189.3 | G92: 2264074.9 | H92: 7826315.9 | I92: 546136.56 | J92: 1763520.1 | K92: 200456.66 | L92: 89846.324 | M92: 47644.449 | N92: 2019830.3 | O92: 89331.174 | P92: 341579.8 | Q92: 33.75639 | R92: 5098379.1 | S92: 322474.05 | T92: 61827.193 | U92: 12831.412 | V92: 3996.6694 | W92: 78805.76 | X92: 1036.2916 | Y92: 0 | Z92: 6272.3455 | AA92: 0 | AB92: 13666.176 | AC92: 0 | AD92: 500909.9 | AE92: 13425605 | AF92: 2220287 | AG92: 141487.44 | AH92: 0 | AI92: 0 | AJ92: 11063830
A93: 6 | B93: 140105 | C93: DE 1 A 30 DÍAS | D93: 191837.3 | E93: 57109.117 | F93: 323351.8 | G93: 211224.62 | H93: 783522.83 | I93: 40655.791 | J93: 135235.47 | K93: 39562.386 | L93: 41635.41 | M93: 6105.5604 | N93: 146885.16 | O93: 4234.0088 | P93: 12582.924 | Q93: 0 | R93: 426896.71 | S93: 11630.607 | T93: 5403.9779 | U93: 344.22073 | V93: 211.74078 | W93: 1245.6691 | X93: 285.10442 | Y93: 0 | Z93: 510.20573 | AA93: 0 | AB93: 689.20597 | AC93: 0 | AD93: 20320.732 | AE93: 1230740.3 | AF93: 186447.54 | AG93: 47952.711 | AH93: 0 | AI93: 0 | AJ93: 996340.02
A94: 6 | B94: 140110 | C94: DE 31 A 90 DÍAS | D94: 302152.44 | E94: 71146.733 | F94: 374440.57 | G94: 201051.49 | H94: 948791.24 | I94: 52689.109 | J94: 225206.37 | K94: 69975.35 | L94: 16184.823 | M94: 8306.2152 | N94: 232545.5 | O94: 5252.0365 | P94: 17164.665 | Q94: 33.75639 | R94: 627357.83 | S94: 24604.351 | T94: 8997.9737 | U94: 1033.9001 | V94: 399.98943 | W94: 10492.294 | X94: 400.83031 | Y94: 0 | Z94: 849.53712 | AA94: 0 | AB94: 1368.3347 | AC94: 0 | AD94: 48147.21 | AE94: 1624296.3 | AF94: 302520.85 | AG94: 24891.027 | AH94: 0 | AI94: 0 | AJ94: 1296884.4
A95: 6 | B95: 140115 | C95: DE 91 A 180 DÍAS | D95: 266516.49 | E95: 105895.73 | F95: 443678.65 | G95: 259101.27 | H95: 1075192.1 | I95: 71966.871 | J95: 249255.94 | K95: 48877.396 | L95: 16220.749 | M95: 10345.019 | N95: 336710.48 | O95: 8531.1704 | P95: 24101.855 | Q95: 0 | R95: 766009.48 | S95: 28078.277 | T95: 10817.213 | U95: 769.63818 | V95: 494.3601 | W95: 11772.552 | X95: 233.40025 | Y95: 0 | Z95: 920.99092 | AA95: 0 | AB95: 2042.7355 | AC95: 0 | AD95: 55129.167 | AE95: 1896330.8 | AF95: 385587.88 | AG95: 27060.128 | AH95: 0 | AI95: 0 | AJ95: 1483682.8
A96: 6 | B96: 140120 | C96: DE 181 A 360 DÍAS | D96: 240314.91 | E96: 126402.01 | F96: 455196.08 | G96: 299852.55 | H96: 1121765.5 | I96: 102130.82 | J96: 305529.2 | K96: 12900.81 | L96: 8789.0018 | M96: 8092.7226 | N96: 320130.29 | O96: 14764.63 | P96: 49392.015 | Q96: 0 | R96: 821729.5 | S96: 57390.787 | T96: 10024.537 | U96: 1690.927 | V96: 972.77359 | W96: 23921.861 | X96: 4.2461 | Y96: 0 | Z96: 1562.5037 | AA96: 0 | AB96: 3833.5572 | AC96: 0 | AD96: 99401.192 | AE96: 2042896.2 | AF96: 333031.1 | AG96: 17854.498 | AH96: 0 | AI96: 0 | AJ96: 1692010.6
A97: 6 | B97: 140125 | C97: DE MÁS DE 360 DÍAS | D97: 961722.57 | E97: 514954.35 | F97: 1127522.2 | G97: 1292845 | H97: 3897044.1 | I97: 278693.97 | J97: 848293.08 | K97: 29140.72 | L97: 7016.3408 | M97: 14794.932 | N97: 983558.87 | O97: 56549.328 | P97: 238338.34 | Q97: 0 | R97: 2456385.6 | S97: 200770.03 | T97: 26583.492 | U97: 8992.7259 | V97: 1917.8055 | W97: 31373.384 | X97: 112.71048 | Y97: 0 | Z97: 2429.108 | AA97: 0 | AB97: 5732.343 | AC97: 0 | AD97: 277911.6 | AE97: 6631341.3 | AF97: 1012699.6 | AG97: 23729.078 | AH97: 0 | AI97: 0 | AJ97: 5594912.6
...

Sheet PYG
B2: ESTADO DE PÉRDIDAS Y GANANCIAS
B3: SISTEMA DE BANCOS PRIVADOS
B4: 44439
B5: (en miles de dólares)
B6: CÓDIGO | D6: BP GUAYAQUIL | E6: BP PACIFICO | F6: BP PICHINCHA | G6: BP PRODUBANCO | I6: BP AUSTRO | J6: BP BOLIVARIANO | K6: BP CITIBANK | L6: BP DINERS | M6: BP GENERAL RUMIÑAHUI | N6: BP INTERNACIONAL | O6: BP LOJA | P6: BP MACHALA | Q6: BP SOLIDARIO | S6: BP PROCREDIT | T6: BP AMAZONAS | U6: BP COMERCIAL DE MANABI | V6: BP LITORAL | W6: BP COOPNACIONAL | X6: BP CAPITAL | Y6: BP FINCA S.A. | Z6: BP DELBANK | AA6: BP D MIRO S.A. | AB6: BP BANCO DESARROLLO DE LOS PUEBLOS S.A., CODESARROLLO | AC6: BP VISIONFUND ECUADOR S.A. | AF6: BANCA ESPECIALIZADA
A7: 1 | B7: CODIGO | C7: CUENTA | D7: BP GUAYAQUIL | E7: BP PACIFICO | F7: BP PICHINCHA | G7: BP PRODUBANCO | H7: BANCOS PRIVADOS GRANDES | I7: BP AUSTRO | J7: BP BOLIVARIANO | K7: BP CITIBANK | L7: BP DINERS | M7: BP GENERAL RUMIÑAHUI | N7: BP INTERNACIONAL | O7: BP LOJA | P7: BP MACHALA | Q7: BP SOLIDARIO | R7: BANCOS PRIVADOS MEDIANOS | S7: BP PROCREDIT | T7: BP AMAZONAS | U7: BP COMERCIAL DE MANABI | V7: BP LITORAL | W7: BP COOPNACIONAL | X7: BP CAPITAL | Y7: BP FINCA S.A. | Z7: BP DELBANK | AA7: BP D MIRO S.A. | AB7: BP BANCODESARROLLO | AC7: BP VISIONFUND ECUADOR S.A. | AD7: BANCOS PRIVADOS PEQUEÑOS | AE7: TOTAL BANCOS PRIVADOS | AF7: BANCOS PRIVADOS COMERCIALES | AG7: BANCOS PRIVADOS CONSUMO | AH7: BANCOS PRIVADOS VIVIENDA | AI7: BANCOS PRIVADOS DE MICROCRÉDITO | AJ7: BANCA MULTIPLE
A8: 2
A9: 3 | B9: 5 | C9: TOTAL INGRESOS | D9: 402524.28 | E9: 488835.76 | F9: 945707.78 | G9: 354650 | H9: 2191717.8 | I9: 143517.05 | J9: 209544.25 | K9: 26579.097 | L9: 301525.91 | M9: 74677.503 | N9: 210463 | O9: 39717.433 | P9: 51033.153 | Q9: 93681.138 | R9: 1150738.5 | S9: 32289.009 | T9: 14476.433 | U9: 3634.0048 | V9: 3011.0741 | W9: 8059.38 | X9: 1978.9057 | Y9: 10911.976 | Z9: 4377.2483 | AA9: 13972.208 | AB9: 24161.022 | AC9: 12132.35 | AD9: 129003.61 | AE9: 3471460 | AF9: 237042.1 | AG9: 379214.49 | AH9: 0 | AI9: 37016.533 | AJ9: 2818186.9
A11: 5 | B11: 51 | C11: INTERESES Y DESCUENTOS GANADOS | D11: 274029.58 | E11: 315132.99 | F11: 635423.38 | G11: 250135.3 | H11: 1474721.3 | I11: 104396.19 | J11: 159887.25 | K11: 12510.992 | L11: 149579.17 | M11: 61454.807 | N11: 166376.53 | O11: 34583.589 | P11: 44499.92 | Q11: 69622.94 | R11: 802911.39 | S11: 27043.628 | T11: 10724.565 | U11: 2991.0627 | V11: 2659.8091 | W11: 7422.6906 | X11: 1579.3235 | Y11: 8047.8449 | Z11: 1430.3599 | AA11: 11709.227 | AB11: 17379.926 | AC11: 10847.921 | AD11: 101836.36 | AE11: 2379469 | AF11: 178887.52 | AG11: 213693.79 | AH11: 0 | AI11: 30604.993 | AJ11: 1956282.7
A12: 6 | B12: 5101 | C12: Depósitos | D12: 656.52043 | E12: 33.78399 | F12: 75.86967 | G12: 1156.5777 | H12: 1922.7518 | I12: 2530.3063 | J12: 1680.6005 | K12: 157.705 | L12: 42.53233 | M12: 748.1086 | N12: 1501.7388 | O12: 121.85043 | P12: 450.05632 | Q12: 94.63167 | R12: 7327.53 | S12: 160.26238 | T12: 102.37617 | U12: 0.11885 | V12: 0.15416 | W12: 853.31618 | X12: 1.95332 | Y12: 1.3989 | Z12: 27.66156 | AA12: 22.8316 | AB12: 80.81663 | AC12: 56.70009 | AD12: 1307.5898 | AE12: 10557.872 | AF12: 1659.4438 | AG12: 790.79509 | AH12: 0 | AI12: 80.93059 | AJ12: 8026.7021
A13: 7 | B13: 5102 | C13: Operaciones interbancarias | D13: 0 | E13: 0 | F13: 4.36112 | G13: 0 | H13: 4.36112 | I13: 0 | J13: 0 | K13: 0 | L13: 0 | M13: 0 | N13: 0 | O13: 0 | P13: 0 | Q13: 0 | R13: 0 | S13: 0 | T13: 0 | U13: 0 | V13: 0 | W13: 0 | X13: 0 | Y13: 0 | Z13: 0 | AA13: 0 | AB13: 0 | AC13: 0 | AD13: 0 | AE13: 4.36112 | AF13: 0 | AG13: 0 | AH13: 0 | AI13: 0 | AJ13: 4.36112
A14: 8 | B14: 5103 | C14: Intereses y descuentos de inversiones en títulos valores | D14: 7884.1334 | E14: 12848.721 | F14: 24320.881 | G14: 5789.4521 | H14: 50843.188 | I14: 11631.815 | J14: 5711.4247 | K14: 2692.959 | L14: 1341.7153 | M14: 1774.6651 | N14: 11923.694 | O14: 1088.5994 | P14: 3264.4822 | Q14: 1694.6364 | R14: 41123.991 | S14: 312.31936 | T14: 1461.0145 | U14: 165.77557 | V14: 108.02627 | W14: 1155.0738 | X14: 41.7456 | Y14: 83.23393 | Z14: 110.88598 | AA14: 737.56347 | AB14: 244.77339 | AC14: 37.25495 | AD14: 4457.6669 | AE14: 96424.846 | AF14: 14616.653 | AG14: 3224.4066 | AH14: 0 | AI14: 858.05235 | AJ14: 77725.734
A15: 9 | B15: 5104 | C15: Intereses y descuentos de cartera de créditos | D15: 265488.93 | E15: 302227.03 | F15: 608339.09 | G15: 243189.27 | H15: 1419244.3 | I15: 90230.835 | J15: 152231.19 | K15: 9646.3 | L15: 148178.16 | M15: 58932.033 | N15: 152951.09 | O15: 33373.139 | P15: 40785.382 | Q15: 67833.672 | R15: 754161.8 | S15: 26571.047 | T15: 9157.3797 | U15: 2818.8348 | V15: 2551.6287 | W15: 5414.3006 | X15: 1535.6246 | Y15: 7963.2121 | Z15: 1291.8124 | AA15: 10948.832 | AB15: 17054.335 | AC15: 10753.966 | AD15: 96060.973 | AE15: 2269467.1 | AF15: 162597.39 | AG15: 209661.82 | AH15: 0 | AI15: 29666.01 | AJ15: 1867541.9
A16: 10 | B16: 510405 | C16: Cartera de créditos productivo | D16: 96146.015 | E16: 39984.04 | F16: 136365.78 | G16: 120820.33 | H16: 393316.17 | I16: 28213.583 | J16: 92090.672 | K16: 6716.544 | L16: 908.94075 | M16: 2977.3405 | N16: 107148.45 | O16: 5818.3552 | P16: 22050.346 | Q16: 0 | R16: 265924.24 | S16: 17863.546 | T16: 2856.2016 | U16: 866.68925 | V16: 256.61856 | W16: 4091.8769 | X16: 47.62969 | Y16: 0 | Z16: 445.93083 | AA16: 0 | AB16: 684.91055 | AC16: 0 | AD16: 27113.403 | AE16: 686353.81 | AF16: 113865 | AG16: 4142.8998 | AH16: 0 | AI16: 0 | AJ16: 568345.91
A17: 11 | B17: 510410 | C17: Cartera de créditos de consumo | D17: 123987.67 | E17: 151113.17 | F17: 215427.59 | G17: 90397.05 | H17: 580925.48 | I17: 45652.44 | J17: 53781.411 | K17: 0 | L17: 136708.19 | M17: 46881.489 | N17: 30664.697 | O17: 12570.27 | P17: 15222.633 | Q17: 28525.329 | R17: 370006.46 | S17: 261.70458 | T17: 5178.3825 | U17: 852.83649 | V17: 1622.044 | W17: 76.47376 | X17: 931.91606 | Y17: 366.20007 | Z17: 413.38187 | AA17: 0 | AB17: 3287.906 | AC17: 0.1837 | AD17: 12991.029 | AE17: 963922.97 | AF17: 30664.697 | AG17: 185211.72 | AH17: 0 | AI17: 366.38377 | AJ17: 747680.16
A18: 12 | B18: 510415 | C18: Cartera de crédito inmobiliario | D18: 12429.285 | E18: 27666.055 | F18: 48893.262 | G18: 16962.871 | H18: 105951.47 | I18: 3365.5852 | J18: 4551.8368 | K18: 0 | L18: 0 | M18: 5492.4187 | N18: 7373.2427 | O18: 2410.2579 | P18: 1262.9728 | Q18: 1.9709 | R18: 24458.285 | S18: 951.68994 | T18: 79.90662 | U18: 1.75604 | V18: 3.44354 | W18: 9.35666 | X18: 0.13643 | Y18: 0 | Z18: 115.9596 | AA18: 0 | AB18: 312.25549 | AC18: 0 | AD18: 1474.5043 | AE18: 131884.26 | AF18: 7373.2427 | AG18: 5495.8622 | AH18: 0 | AI18: 0 | AJ18: 119015.16
A19: 13 | B19: 510420 | C19: Cartera de créditos para microcrédito | D19: 20715.002 | E19: 657.90663 | F19: 127219.85 | G19: 1771.6229 | H19: 150364.38 | I19: 598.29381 | J19: 0 | K19: 0 | L19: 0 | M19: 0 | N19: 336.35799 | O19: 6669.742 | P19: 661.44602 | Q19: 37203.209 | R19: 45469.048 | S19: 5558.085 | T19: 8.11049 | U19: 806.34358 | V19: 129.75091 | W19: 1229.4782 | X19: 73.8361 | Y19: 6068.0054 | Z19: 8.07208 | AA19: 10534.861 | AB19: 5681.792 | AC19: 10179.43 | AD19: 40277.765 | AE19: 236111.19 | AF19: 336.35799 | AG19: 129.75091 | AH19: 0 | AI19: 26782.296 | AJ19: 208862.79
A20: 14 | B20: 510421 | C20: Cartera de crédito productivo | D20: 0 | E20: 0 | F20: 0 | G20: 0 | H20: 0 | I20: 0 | J20: 0 | K20: 0 | L20: 0 | M20: 0 | N20: 0 | O20: 0 | P20: 0 | Q20: 0 | R20: 0 | S20: 0 | T20: 0 | U20: 0 | V20: 0 | W20: 0 | X20: 0 | Y20: 0 | Z20: 0 | AA20: 0 | AB20: 0 | AC20: 0 | AD20: 0 | AE20: 0 | AF20: 0 | AG20: 0 | AH20: 0 | AI20: 0 | AJ20: 0
A21: 15 | B21: 510425 | C21: Cartera de crédito comercial ordinario | D21: 0 | E21: 0 | F21: 0 | G21: 0 | H21: 0 | I21: 0 | J21: 0 | K21: 0 | L21: 0 | M21: 0 | N21: 0 | O21: 0 | P21: 0 | Q21: 0 | R21: 0 | S21: 0 | T21: 0 | U21: 0 | V21: 0 | W21: 0 | X21: 0 | Y21: 0 | Z21: 0 | AA21: 0 | AB21: 0 | AC21: 0 | AD21: 0 | AE21: 0 | AF21: 0 | AG21: 0 | AH21: 0 | AI21: 0 | AJ21: 0
... A36: 30 | B36: 4105 | C36: Otros intereses | D36: 0 | E36: 0 | F36: 6.44316 | G36: 0 | H36: 6.44316 | I36: 0 | J36: 0 | K36: 0 | L36: 0 | M36: 0 | N36: 0 | O36: 0 | P36: 0 | Q36: 0 | R36: 0 | S36: 0 | T36: 0.70914 | U36: 0 | V36: 0 | W36: 0 | X36: 0 | Y36: 0 | Z36: 0 | AA36: 0 | AB36: 0 | AC36: 0 | AD36: 0.70914 | AE36: 7.1523 | AF36: 0 | AG36: 0 | AH36: 0 | AI36: 0 | AJ36: 7.1523
A37: 31 | B37: MARGEN NETO INTERESES | C37: MARGEN NETO INTERESES | D37: 176291.82 | E37: 183262.08 | F37: 497336.54 | G37: 175104.34 | H37: 1031994.8 | I37: 58870.143 | J37: 100006.18 | K37: 12451.179 | L37: 100871.86 | M37: 40773.667 | N37: 102913.22 | O37: 23414.072 | P37: 28134.432 | Q37: 47767.972 | R37: 515202.73 | S37: 15388.603 | T37: 3970.9707 | U37: 2493.2203 | V37: 2083.6296 | W37: 5854.8562 | X37: 664.72616 | Y37: 3898.9985 | Z37: 1078.7761 | AA37: 6781.7533 | AB37: 11054.481 | AC37: 8164.9144 | AD37: 61434.93 | AE37: 1608632.4 | AF37: 115364.39 | AG37: 143729.16 | AH37: 0 | AI37: 18845.666 | AJ37: 1330693.2
A39: 33 | B39: 52 | C39: COMISIONES GANADAS | D39: 25154.623 | E39: 29368.712 | F39: 30165.535 | G39: 14722.19 | H39: 99411.059 | I39: 7384.3537 | J39: 16773.085 | K39: 1556.33 | L39: 39371.025 | M39: 2914.9053 | N39: 14334.415 | O39: 787.43964 | P39: 727.71544 | Q39: 2582.064 | R39: 86431.333 | S39: 33.43968 | T39: 173.16509 | U39: 14.228 | V39: 0.006 | W39: 0 | X39: 0 | Y39: 0 | Z39: 48.92544 | AA39: 0 | AB39: 47.03894 | AC39: 0 | AD39: 316.80315 | AE39: 186159.2 | AF39: 15890.745 | AG39: 42285.936 | AH39: 0 | AI39: 0 | AJ39: 127982.51
A40: 34 | B40: 5201 | C40: Cartera de créditos | D40: 16.98241 | E40: 0 | F40: 0 | G40: 0 | H40: 16.98241 | I40: 0 | J40: 0 | K40: 0 | L40: 0 | M40: 0 | N40: 0 | O40: 0 | P40: 0.05617 | Q40: 0 | R40: 0.05617 | S40: 0 | T40: 0 | U40: 0 | V40: 0 | W40: 0 | X40: 0 | Y40: 0 | Z40: 0 | AA40: 0 | AB40: 0 | AC40: 0 | AD40: 0 | AE40: 17.03858 | AF40: 0 | AG40: 0 | AH40: 0 | AI40: 0 | AJ40: 17.03858
A41: 35 | B41: 520105 | C41: Cartera de créditos comercial | D41: 2.82237 | E41: 0 | F41: 0 | G41: 0 | H41: 2.82237 | I41: 0 | J41: 0 | K41: 0 | L41: 0 | M41: 0 | N41: 0 | O41: 0 | P41: 0.05617 | Q41: 0 | R41: 0.05617 | S41: 0 | T41: 0 | U41: 0 | V41: 0 | W41: 0 | X41: 0 | Y41: 0 | Z41: 0 | AA41: 0 | AB41: 0 | AC41: 0 | AD41: 0 | AE41: 2.87854 | AF41: 0 | AG41: 0 | AH41: 0 | AI41: 0 | AJ41: 2.87854
A42: 36 | B42: 520110 | C42: Cartera de créditos de consumo | D42: 10.30673 | E42: 0 | F42: 0 | G42: 0 | H42: 10.30673 | I42: 0 | J42: 0 | K42: 0 | L42: 0 | M42: 0 | N42: 0 | O42: 0 | P42: 0 | Q42: 0 | R42: 0 | S42: 0 | T42: 0 | U42: 0 | V42: 0 | W42: 0 | X42: 0 | Y42: 0 | Z42: 0 | AA42: 0 | AB42: 0 | AC42: 0 | AD42: 0 | AE42: 10.30673 | AF42: 0 | AG42: 0 | AH42: 0 | AI42: 0 | AJ42: 10.30673
A43: 37 | B43: 520115 | C43: Cartera de créditos de vivienda | D43: 0 | E43: 0 | F43: 0 | G43: 0 | H43: 0 | I43: 0 | J43: 0 | K43: 0 | L43: 0 | M43: 0 | N43: 0 | O43: 0 | P43: 0 | Q43: 0 | R43: 0 | S43: 0 | T43: 0 | U43: 0 | V43: 0 | W43: 0 | X43: 0 | Y43: 0 | Z43: 0 | AA43: 0 | AB43: 0 | AC43: 0 | AD43: 0 | AE43: 0 | AF43: 0 | AG43: 0 | AH43: 0 | AI43: 0 | AJ43: 0
A44: 38 | B44: 520120 | C44: Cartera de créditos para la microempresa | D44: 3.85331 | E44: 0 | F44: 0 | G44: 0 | H44: 3.85331 | I44: 0 | J44: 0 | K44: 0 | L44: 0 | M44: 0 | N44: 0 | O44: 0 | P44: 0 | Q44: 0 | R44: 0 | S44: 0 | T44: 0 | U44: 0 | V44: 0 | W44: 0 | X44: 0 | Y44: 0 | Z44: 0 | AA44: 0 | AB44: 0 | AC44: 0 | AD44: 0 | AE44: 3.85331 | AF44: 0 | AG44: 0 | AH44: 0 | AI44: 0 | AJ44: 3.85331
A45: 39 | B45: 520125 | C45: Cartera de créditos reestructurada | D45: 0 | E45: 0 | F45: 0 | G45: 0 | H45: 0 | I45: 0 | J45: 0 | K45: 0 | L45: 0 | M45: 0 | N45: 0 | O45: 0 | P45: 0 | Q45: 0 | R45: 0 | S45: 0 | T45: 0 | U45: 0 | V45: 0 | W45: 0 | X45: 0 | Y45: 0 | Z45: 0 | AA45: 0 | AB45: 0 | AC45: 0 | AD45: 0 | AE45: 0 | AF45: 0 | AG45: 0 | AH45: 0 | AI45: 0 | AJ45: 0
A46: 40 | B46: 5202 | C46: Deudores por aceptación | D46: 0 | E46: 0 | F46: 0 | G46: 0 | H46: 0 | I46: 0 | J46: 0 | K46: 2.375 | L46: 0 | M46: 0 | N46: 0 | O46: 0 | P46: 0 | Q46: 0 | R46: 2.375 | S46: 0 | T46: 0 | U46: 0 | V46: 0 | W46: 0 | X46: 0 | Y46: 0 | Z46: 0 | AA46: 0 | AB46: 0 | AC46: 0 | AD46: 0 | AE46: 2.375 | AF46: 2.375 | AG46: 0 | AH46: 0 | AI46: 0 | AJ46: 0
A47: 41 | B47: 5203 | C47: Avales | D47: 0 | E47: 26.36767 | F47: 1465.5589 | G47: 297.66633 | H47: 1789.5929 | I47: 695.38135 | J47: 758.0313 | K47: 0 | L47: 0 | M47: 25.47061 | N47: 613.9625 | O47: 69.64107 | P47: 5.2 | Q47: 0 | R47: 2167.6868 | S47: 0 | T47: 0 | U47: 0 | V47: 0 | W47: 0 | X47: 0 | Y47: 0 | Z47: 0 | AA47: 0 | AB47: 0 | AC47: 0 | AD47: 0 | AE47: 3957.2797 | AF47: 613.9625 | AG47: 25.47061 | AH47: 0 | AI47: 0 | AJ47: 3317.8466
A48: 42 | B48: 5204 | C48: Fianzas | D48: 2937.2466 | E48: 2682.3415 | F48: 4042.2793 | G48: 2293.1607 | H48: 11955.028 | I48: 298.79033 | J48: 1399.2196 | K48: 1469.924 | L48: 0 | M48: 131.29442 | N48: 2438.0694 | O48: 0 | P48: 122.81186 | Q48: 3.74808 | R48: 5863.8577 | S48: 24.27702 | T48: 20.39027 | U48: 14.228 | V48: 0 | W48: 0 | X48: 0 | Y48: 0 | Z48: 0 | AA48: 0 | AB48: 22.63069 | AC48: 0 | AD48: 81.52598 | AE48: 17900.412 | AF48: 3907.9934 | AG48: 131.29442 | AH48: 0 | AI48: 0 | AJ48: 13861.124
A49: 43 | B49: 5205 | C49: Cartas de Crédito | D49: 1600.7695 | E49: 791.73966 | F49: 883.05087 | G49: 1186.4868 | H49: 4462.0469 | I49: 70.6267 | J49: 1431.3487 | K49: 8.452 | L49: 0 | M49: 6.29637 | N49: 2263.7725 | O49: 0 | P49: 10 | Q49: 0 | R49: 3790.4963 | S49: 8.23067 | T49: 0 | U49: 0 | V49: 0 | W49: 0 | X49: 0 | Y49: 0 | Z49: 0 | AA49: 0 | AB49: 0 | AC49: 0 | AD49: 8.23067 | AE49: 8260.7739 | AF49: 2272.2245 | AG49: 6.29637 | AH49: 0 | AI49: 0 | AJ49: 5982.253
A50: 44 | B50: 5290 | C50: Otras | D50: 20599.624 | E50: 25868.264 | F50: 23774.646 | G50: 10944.876 | H50: 81187.409 | I50: 6319.5553 | J50: 13184.485 | K50: 75.579 | L50: 39371.025 | M50: 2751.8439 | N50: 9018.6108 | O50: 717.79857 | P50: 589.64741 | Q50: 2578.3159 | R50: 74606.861 | S50: 0.93199 | T50: 152.77482 | U50: 0 | V50: 0.006 | W50: 0 | X50: 0 | Y50: 0 | Z50: 48.92544 | AA50: 0 | AB50: 24.40825 | AC50: 0 | AD50: 227.0465 | AE50: 156021.32 | AF50: 9094.1898 | AG50: 42122.875 | AH50: 0 | AI50: 0 | AJ50: 104804.25
... A61: 55 | B61: 540510 | C61: Tarifa periódica | D61: 0 | E61: 0 | F61: 0 | G61: 0 | H61: 0 | I61: 0 | J61: 0 | K61: 0 | L61: 0 | M61: 0 | N61: 0 | O61: 0 | P61: 0 | Q61: 0 | R61: 0 | S61: 0 | T61: 0 | U61: 0 | V61: 0 | W61: 0 | X61: 0 | Y61: 0 | Z61: 0 | AA61: 0 | AB61: 0 | AC61: 0 | AD61: 0 | AE61: 0 | AF61: 0 | AG61: 0 | AH61: 0 | AI61: 0 | AJ61: 0
B62: 5406 | C62: Servicios Financieros con cargo máximo | D62: 57218.499 | E62: 50659.914 | F62: 68249.611 | G62: 36060.803 | H62: 212188.83 | I62: 12336.661 | J62: 14483.654 | K62: 898.466 | L62: 56578.344 | M62: 3663.929 | N62: 11842.502 | O62: 2164.819 | P62: 3426.5793 | Q62: 2648.8748 | R62: 108043.83 | S62: 551.29426 | T62: 419.36686 | U62: 326.81234 | V62: 102.27602 | W62: 496.18411 | X62: 31.12234 | Y62: 6.53985 | Z62: 86.25228 | AA62: 35.3859 | AB62: 278.8755 | AC62: 382.4514 | AD62: 2716.5609 | AE62: 322949.22 | AF62: 12740.968 | AG62: 60344.549 | AH62: 0 | AI62: 424.37715 | AJ62: 249439.32
B63: 5407 | C63: Servicios Financieros con cargo diferenciado | D63: 21571.917 | E63: 21919.16 | F63: 46713.259 | G63: 13236.264 | H63: 103440.6 | I63: 2591.641 | J63: 10094.498 | K63: 290.988 | L63: 8409.5557 | M63: 2150.251 | N63: 7311.7423 | O63: 276.21595 | P63: 786.91965 | Q63: 8638.961 | R63: 40550.773 | S63: 13.53682 | T63: 1212.1293 | U63: 43.78299 | V63: 37.09739 | W63: 0 | X63: 0 | Y63: 0 | Z63: 2043.3073 | AA63: 9.5803 | AB63: 161.2373 | AC63: 0 | AD63: 3520.6714 | AE63: 147512.04 | AF63: 7602.7303 | AG63: 10596.904 | AH63: 0 | AI63: 9.5803 | AJ63: 129302.83
A64: 56 | B64: 5490 | C64: Otros servicios | D64: 0 | E64: 0 | F64: 0 | G64: 0 | H64: 0 | I64: 0 | J64: 0 | K64: 0 | L64: 0 | M64: 0 | N64: 0.00275 | O64: 0 | P64: 0 | Q64: 0 | R64: 0.00275 | S64: 0 | T64: 0 | U64: 0 | V64: 0 | W64: 3.39933 | X64: 0 | Y64: 0 | Z64: 0 | AA64: 0.08205 | AB64: 0 | AC64: 0 | AD64: 3.48138 | AE64: 3.48413 | AF64: 0.00275 | AG64: 0 | AH64: 0 | AI64: 0.08205 | AJ64: 3.39933
A65: 57 | B65: 549005 | C65: Tarifados con costo máximo | D65: 0 | E65: 0 | F65: 0 | G65: 0 | H65: 0 | I65: 0 | J65: 0 | K65: 0 | L65: 0 | M65: 0 | N65: 0 | O65: 0 | P65: 0 | Q65: 0 | R65: 0 | S65: 0 | T65: 0 | U65: 0 | V65: 0 | W65: 0 | X65: 0 | Y65: 0 | Z65: 0 | AA65: 0 | AB65: 0 | AC65: 0 | AD65: 0 | AE65: 0 | AF65: 0 | AG65: 0 | AH65: 0 | AI65: 0 | AJ65: 0
A66: 58 | B66: 549010 | C66: Tarifados diferenciados | D66: 0 | E66: 0 | F66: 0 | G66: 0 | H66: 0 | I66: 0 | J66: 0 | K66: 0 | L66: 0 | M66: 0 | N66: 0 | O66: 0 | P66: 0 | Q66: 0 | R66: 0 | S66: 0 | T66: 0 | U66: 0 | V66: 0 | W66: 0 | X66: 0 | Y66: 0 | Z66: 0 | AA66: 0 | AB66: 0 | AC66: 0 | AD66: 0 | AE66: 0 | AF66: 0 | AG66: 0 | AH66: 0 | AI66: 0 | AJ66: 0
A67: 59 | B67: 549090 | C67: Otros | D67: 0 | E67: 0 | F67: 0 | G67: 0 | H67: 0 | I67: 0 | J67: 0 | K67: 0 | L67: 0 | M67: 0 | N67: 0 | O67: 0 | P67: 0 | Q67: 0 | R67: 0 | S67: 0 | T67: 0 | U67: 0 | V67: 0 | W67: 0 | X67: 0 | Y67: 0 | Z67: 0 | AA67: 0 | AB67: 0 | AC67: 0 | AD67: 0 | AE67: 0 | AF67: 0 | AG67: 0 | AH67: 0 | AI67: 0 | AJ67: 0
...

Sheet BALANCE %
B2: ESTADO DE SITUACIÓN CONSOLIDADO
B3: SISTEMA DE BANCOS PRIVADOS
B4: 44439
B5: (en porcentajes)
AF6: BANCA ESPECIALIZADA
A7: 1 | B7: CODIGO | C7: CUENTA | D7: BP GUAYAQUIL | E7: BP PACIFICO | F7: BP PICHINCHA | G7: BP PRODUBANCO | H7: BANCOS PRIVADOS GRANDES | I7: BP AUSTRO | J7: BP BOLIVARIANO | K7: BP CITIBANK | L7: BP DINERS | M7: BP GENERAL RUMIÑAHUI | N7: BP INTERNACIONAL | O7: BP LOJA | P7: BP MACHALA | Q7: BP SOLIDARIO | R7: BANCOS PRIVADOS MEDIANOS | S7: BP PROCREDIT | T7: BP AMAZONAS | U7: BP COMERCIAL DE MANABI | V7: BP LITORAL | W7: BP COOPNACIONAL | X7: BP CAPITAL | Y7: BP FINCA S.A. | Z7: BP DELBANK | AA7: BP D MIRO S.A. | AB7: BP BANCODESARROLLO | AC7: BP VISIONFUND ECUADOR S.A. | AD7: BANCOS PRIVADOS PEQUEÑOS | AE7: TOTAL BANCOS PRIVADOS | AF7: BANCOS PRIVADOS COMERCIALES | AG7: BANCOS PRIVADOS CONSUMO | AH7: BANCOS PRIVADOS VIVIENDA | AI7: BANCOS PRIVADOS DE MICROCRÉDITO | AJ7: BANCA MULTIPLE
A8: 2 | C8: ACTIVO
A9: 3 | B9: 11 | C9: FONDOS DISPONIBLES | D9: 0.14124837 | E9: 0.17645495 | F9: 0.13763707 | G9: 0.16174999 | H9: 0.15117414 | I9: 0.19301642 | J9: 0.21514263 | K9: 0.47099807 | L9: 0.032676797 | M9: 0.17065795 | N9: 0.17973773 | O9: 0.24873969 | P9: 0.17927079 | Q9: 0.093772097 | R9: 0.17954961 | S9: 0.12233575 | T9: 0.11595506 | U9: 0.17358297 | V9: 0.052915424 | W9: 0.30934863 | X9: 0.099456918 | Y9: 0.10019538 | Z9: 0.21229612 | AA9: 0.061446226 | AB9: 0.1091621 | AC9: 0.050504332 | AD9: 0.13369396 | AE9: 0.1600892 | AF9: 0.21868224 | AG9: 0.073950721 | AH9: #DIV/0! | AI9: 0.070267648 | AJ9: 0.1607277
A10: 3 | B10: 12 | C10: OPERACIONES INTERBANCARIAS | D10: 0 | E10: 0 | F10: 0 | G10: 0 | H10: 0 | I10: 0 | J10: 0 | K10: 0 | L10: 0 | M10: 0 | N10: 0 | O10: 0 | P10: 0 | Q10: 0 | R10: 0 | S10: 0 | T10: 0 | U10: 0 | V10: 0 | W10: 0 | X10: 0 | Y10: 0 | Z10: 0 | AA10: 0 | AB10: 0 | AC10: 0 | AD10: 0 | AE10: 0 | AF10: 0 | AG10: 0 | AH10: #DIV/0! | AI10: 0 | AJ10: 0
A11: 3 | B11: 13 | C11: INVERSIONES | D11: 0.18743984 | E11: 0.13950554 | F11: 0.21372311 | G11: 0.13787769 | H11: 0.17877042 | I11: 0.18870505 | J11: 0.15631716 | K11: 0.21033271 | L11: 0.097945219 | M11: 0.14892316 | N11: 0.17575636 | O11: 0.10916456 | P11: 0.18320417 | Q11: 0.15704952 | R11: 0.15909468 | S11: 0.052902191 | T11: 0.2585979 | U11: 0.14892794 | V11: 0.14179635 | W11: 0.20621135 | X11: 0.13490603 | Y11: 0.092750894 | Z11: 0.15581305 | AA11: 0.19681184 | AB11: 0.10955305 | AC11: 0.021810753 | AD11: 0.12888905 | AE11: 0.17048727 | AF11: 0.18037957 | AG11: 0.11361837 | AH11: #DIV/0! | AI11: 0.11240982 | AJ11: 0.17422592
A12: 3 | B12: 0 | C12: INVERSIONES DEL SECTOR PRIVADO | D12: 0.031844765 | E12: 0.038016623 | F12: 0.040015705 | G12: 0.056495587 | H12: 0.040929415 | I12: 0.088182809 | J12: 0.051857193 | K12: 0.012512488 | L12: 0.0073696415 | M12: 0.056282704 | N12: 0.058616775 | O12: 0.05154884 | P12: 0.037285006 | Q12: 0.10270568 | R12: 0.052767301 | S12: 0.012365853 | T12: 0.11434113 | U12: 0.081864708 | V12: 0.063585162 | W12: 0.13357709 | X12: 0.03539391 | Y12: 0.046005495 | Z12: 0.10378516 | AA12: 0.16248768 | AB12: 0.04600524 | AC12: 0.0077364139 | AD12: 0.064095871 | AE12: 0.045680983 | AF12: 0.052452156 | AG12: 0.022572884 | AH12: #DIV/0! | AI12: 0.080231166 | AJ12: 0.046466626
A13: 3 | B13: 0 | C13: INVERSIONES DEL SECTOR PUBLICO | D13: 0.15660011 | E13: 0.086754455 | F13: 0.17014417 | G13: 0.078127282 | H13: 0.13276428 | I13: 0.087151991 | J13: 0.092573717 | K13: 0.19782022 | L13: 0.070539646 | M13: 0.099222967 | N13: 0.087610973 | O13: 0.05745887 | P13: 0.14444331 | Q13: 0.054343845 | R13: 0.091846475 | S13: 0.039719332 | T13: 0.13815924 | U13: 0.067544853 | V13: 0.07821119 | W13: 0.073205833 | X13: 0.084812863 | Y13: 0.0467454 | Z13: 0.050543551 | AA13: 0.034324163 | AB13: 0.063547808 | AC13: 0.014074339 | AD13: 0.063363603 | AE13: 0.11670221 | AF13: 0.10234709 | AG13: 0.079160017 | AH13: #DIV/0! | AI13: 0.032178654 | AJ13: 0.12191305
A14: 3 | B14: 1307 | C14: De disponibilidad restringida | D14: 0 | E14: 0.015248991 | F14: 0.013040703 | G14: 0.0032801122 | H14: 0.0092517778 | I14: 0.013488306 | J14: 0.012171588 | K14: 0 | L14: 0.020035931 | M14: 0.00042877912 | N14: 0.029529173 | O14: 0.00016510188 | P14: 0.0014758522 | Q14: 0 | R14: 0.014974395 | S14: 0.00081700632 | T14: 0.0060975337 | U14: 0.00083932549 | V14: 0 | W14: 0 | X14: 0.01469926 | Y14: 0 | Z14: 0.0015624648 | AA14: 0 | AB14: 0 | AC14: 0 | AD14: 0.0015443324 | AE14: 0.010907979 | AF14: 0.025580818 | AG14: 0.013970744 | AH14: #DIV/0! | AI14: 0 | AJ14: 0.0090504567
A15: 3 | B15: 1399 | C15: (Provisión para inversiones) | D15: -0.0010050274 | E15: -0.00051453149 | F15: -0.0094774587 | G15: -2.5292043e-05 | H15: -0.0041750497 | I15: -0.0001180603 | J15: -0.00028533587 | K15: 0 | L15: 0 | M15: -0.0070112928 | N15: -5.6143444e-07 | O15: -8.2550941e-06 | P15: 0 | Q15: 0 | R15: -0.00049349125 | S15: 0 | T15: 0 | U15: -0.0013209424 | V15: 0 | W15: -0.00057157923 | X15: 0 | Y15: 0 | Z15: -7.812324e-05 | AA15: 0 | AB15: 0 | AC15: 0 | AD15: -0.00011475889 | AE15: -0.0028038931 | AF15: -4.8636487e-07 | AG15: -0.0020852736 | AH15: #DIV/0! | AI15: 0 | AJ15: -0.0032042139
A16: 3 | B16: 14 | C16: CARTERA DE CRÉDITOS | D16: 0.61059468 | E16: 0.60237828 | F16: 0.54295488 | G16: 0.63430337 | H16: 0.58545412 | I16: 0.52676736 | J16: 0.58512691 | K16: 0.29234371 | L16: 0.80376003 | M16: 0.63809942 | N16: 0.5927639 | O16: 0.58597389 | P16: 0.58034894 | Q16: 0.69015856 | R16: 0.60512962 | S16: 0.78739349 | T16: 0.48935607 | U16: 0.50615559 | V16: 0.71725565 | W16: 0.45003407 | X16: 0.46297208 | Y16: 0.72627196 | Z16: 0.48392635 | AA16: 0.64881425 | AB16: 0.71865598 | AC16: 0.89393801 | AD16: 0.66291247 | AE16: 0.59467183 | AF16: 0.55259463 | AG16: 0.75348086 | AH16: #DIV/0! | AI16: 0.74575817 | AJ16: 0.58598033
A17: 3 | B17: 1401+1409+1417+1425+1433+1441+1449+1457+1465+149105+149205+149305+149405+149505+149605 | C17: CARTERA DE CRÉDITOS PRODUCTIVO | D17: 0.3290403 | E17: 0.2279986 | F17: 0.23494085 | G17: 0.41568574 | H17: 0.28393959 | I17: 0.29076119 | J17: 0.4365694 | K17: 0.3228733 | L17: 0.051828857 | M17: 0.0700818 | N17: 0.51408877 | O17: 0.20584509 | P17: 0.3850483 | Q17: 4.376933e-05 | R17: 0.32683301 | S17: 0.62335457 | T17: 0.24804809 | U17: 0.26488302 | V17: 0.14510652 | W17: 0.4121994 | X17: 0.035206906 | Y17: 0 | Z17: 0.31045801 | AA17: 0 | AB17: 0.089642195 | AC17: 0 | AD17: 0.322604 | AE17: 0.2996219 | AF17: 0.48852129 | AG17: 0.058345568 | AH17: #DIV/0! | AI17: 0 | AJ17: 0.29889133
A18: 3 | B18: 1402+1410+1418+1426+1434+1442+1450+1458+1466+149120+149220+149320+149420+149520+149620 | C18: CARTERA DE CREDITOS CONSUMO | D18: 0.23884982 | E18: 0.27145592 | F18: 0.21515626 | G18: 0.19878705 | H18: 0.2292145 | I18: 0.24570082 | J18: 0.15361448 | K18: 0 | L18: 0.85408688 | M18: 0.52780158 | N18: 0.08039953 | O18: 0.27130734 | P18: 0.18199357 | Q18: 0.34194441 | R18: 0.27284656 | S18: 0.007924312 | T18: 0.24917321 | U18: 0.15663732 | V18: 0.58284368 | W18: 0.0044690231 | X18: 0.45443025 | Y18: 0.053851607 | Z18: 0.14085338 | AA18: 0 | AB18: 0.26790763 | AC18: 0.00034610524 | AD18: 0.1087909 | AE18: 0.23975247 | AF18: 0.069649284 | AG18: 0.75388051 | AH18: #DIV/0! | AI18: 0.01687941 | AJ18: 0.2206182
A19: 3 | B19: 1403+1411+1419+1427+1435+1443+1451+1459+1467+149130+149230+149330+149430+149530+149630 | C19: CARTERA DE CRÉDITOS INMOBILIARIO | D19: 0.034424215 | E19: 0.077392246 | F19: 0.059676212 | G19: 0.046247912 | H19: 0.05627021 | I19: 0.022392176 | J19: 0.01754508 | K19: 0 | L19: 0 | M19: 0.098026849 | N19: 0.02742123 | O19: 0.060419981 | P19: 0.021382827 | Q19: 8.2702619e-05 | R19: 0.023258947 | S19: 0.042705437 | T19: 0.006456835 | U19: 0.00042732663 | V19: 0.0031527066 | W19: 0.0008441178 | X19: 3.1729871e-08 | Y19: 0 | Z19: 0.056485133 | AA19: 0 | AB19: 0.056137759 | AC19: 0 | AD19: 0.02358516 | AE19: 0.044101675 | AF19: 0.023754729 | AG19: 0.029191567 | AH19: #DIV/0! | AI19: 0 | AJ19: 0.047938312
A20: 3 | B20: 1404+1412+1420+1428+1436+1444+1452+1460+1468+149140+149240+149340+149440+149540+149640 | C20: CARTERA DE CRÉDITOS MICROCRÉDITO | D20: 0.035735503 | E20: 0.0015565858 | F20: 0.1036837 | G20: 0.003494452 | H20: 0.05015946 | I20: 0.0028610674 | J20: 0 | K20: 0 | L20: 0 | M20: 1.7778647e-08 | N20: 0.00073796463 | O20: 0.10903239 | P20: 0.006378142 | Q20: 0.44544087 | R20: 0.025796153 | S20: 0.13094544 | T20: 0.00073498596 | U20: 0.12442689 | V20: 0.041300945 | W20: 0.046613755 | X20: 0.025498013 | Y20: 0.73910313 | Z20: 0.0038424909 | AA20: 0.70978885 | AB20: 0.3644258 | AC20: 0.96380961 | AD20: 0.24100417 | AE20: 0.048464409 | AF20: 0.00063929115 | AG20: 0.0004817375 | AH20: #DIV/0! | AI20: 0.79437729 | AJ20: 0.052425356
A21: 3 | B21: 1408+1416+1424+1432+1440+1448+1456+1464+1472+149135+149235+149335+149435+149535+149635 | C21: CARTERA DE CRÉDITOS VIVIENDA DE INTERÉS SOCIAL Y PÚBLICO | D21: 0 | E21: 0.0078426533 | F21: 0.00066042799 | G21: 0 | H21: 0.0019932259 | I21: 0 | J21: 0 | K21: 0 | L21: 0 | M21: 0.0032527156 | N21: 0.00010084352 | O21: 0 | P21: 0 | Q21: 0 | R21: 0.00021384556 | S21: 0 | T21: 0 | U21: 0 | V21: 0 | W21: 0 | X21: 0 | Y21: 0 | Z21: 0 | AA21: 0 | AB21: 0 | AC21: 0 | AD21: 0 | AE21: 0.0013294713 | AF21: 8.7359703e-05 | AG21: 0.00096741103 | AH21: #DIV/0! | AI21: 0 | AJ21: 0.001510894
A22: 3 | B22: 1473+1475+1477+1479+1481+1483+1485+1487+1489+149150+149250+149350+149450+149550+149650 | C22: CARTERA DE CRÉDITOS EDUCATIVO | D22: 0.0004387019 | E22: 0.050186855 | F22: 0.0013141448 | G22: 7.1658334e-05 | H22: 0.011666367 | I22: 0 | J22: 0.00089865453 | K22: 0 | L22: 0 | M22: 0 | N22: 0 | O22: 0.00039353252 | P22: 0.0031664027 | Q22: 0 | R22: 0.00041052214 | S22: 0.00037856396 | T22: 0 | U22: 0 | V22: 0 | W22: 0 | X22: 0 | Y22: 0 | Z22: 0 | AA22: 0 | AB22: 0 | AC22: 0 | AD22: 0.00012510997 | AE22: 0.0075038205 | AF22: 0 | AG22: 0 | AH22: #DIV/0! | AI22: 0 | AJ22: 0.0090135926
A23: 3 | B23: 1474+1476+1478+1480+1482+1484+1486+1488+1490+149145+149245+149345+149445+149545+149645 | C23: CARTERA DE CRÉDITO INVERSIÓN PÚBLICA | D23: 0 | E23: 0 | F23: 0 | G23: 0 | H23: 0 | I23: 0 | J23: 0 | K23: 0 | L23: 0 | M23: 0 | N23: 0 | O23: 0 | P23: 0 | Q23: 0 | R23: 0 | S23: 0 | T23: 0 | U23: 0 | V23: 0 | W23: 0 | X23: 0 | Y23: 0 | Z23: 0 | AA23: 0 | AB23: 0 | AC23: 0 | AD23: 0 | AE23: 0 | AF23: 0 | AG23: 0 | AH23: #DIV/0! | AI23: 0 | AJ23: 0
A24: 3 | B24: 1499 | C24: (PROVISIONES PARA CRÉDITOS INCOBRABLES) | D24: -0.027893862 | E24: -0.034054581 | F24: -0.072476717 | G24: -0.029983439 | H24: -0.047789235 | I24: -0.034947904 | J24: -0.023500705 | K24: -0.030529595 | L24: -0.10215571 | M24: -0.061063545 | N24: -0.02998444 | O24: -0.061024437 | P24: -0.017620298 | Q24: -0.097353198 | R24: -0.044229411 | S24: -0.01791483 | T24: -0.015057054 | U24: -0.040218958 | V24: -0.055148192 | W24: -0.014092233 | X24: -0.052163114 | Y24: -0.066682774 | Z24: -0.027712655 | AA24: -0.060974597 | AB24: -0.059457408 | AC24: -0.070217708 | AD24: -0.033196872 | AE24: -0.046101913 | AF24: -0.030057333 | AG24: -0.089385935 | AH24: #DIV/0! | AI24: -0.065498524 | AJ24: -0.044417355
A25: 3 | B25: 149905 | C25: (CARTERA DE CRÉDITOS PRODUCTIVO) | D25: -0.0052423099 | E25: -0.0033429664 | F25: -0.016412518 | G25: -0.0061022684 | H25: -0.0095302334 | I25: -0.0065069961 | J25: -0.0069924303 | K25: -0.010207088 | L25: -0.0016777405 | M25: -0.0045649812 | N25: -0.014726667 | O25: -0.012513895 | P25: -0.0040403739 | Q25: -4.6329208e-07 | R25: -0.0078280065 | S25: -0.0099649452 | T25: -0.0033901923 | U25: -0.0036226049 | V25: -0.0018405412 | W25: -0.0040956429 | X25: -0.00083713585 | Y25: 0 | Z25: -0.0028631617 | AA25: 0 | AB25: -0.0016895542 | AC25: 0 | AD25: -0.0047458651 | AE25: -0.0087977321 | AF25: -0.014122353 | AG25: -0.0025383522 | AH25: #DIV/0! | AI25: 0 | AJ25: -0.0087371197
A26: 3 | B26: 149910 | C26: (CARTERA DE CRÉDITOS DE CONSUMO) | D26: -0.0041677475 | E26: -0.0084810176 | F26: -0.0065630949 | G26: -0.0044942833 | H26: -0.0061503568 | I26: -0.011942077 | J26: -0.0045424302 | K26: 0 | L26: -0.022079417 | M26: -0.014037933 | N26: -0.0036766887 | O26: -0.0058065947 | P26: -0.0045663726 | Q26: -0.022688116 | R26: -0.0089673091 | S26: -0.00021121233 | T26: -0.0064859722 | U26: -0.011777456 | V26: -0.025444746 | W26: -2.9761087e-05 | X26: -0.021767927 | Y26: -0.0027646418 | Z26: -0.0077140246 | AA26: 0 | AB26: -0.0046136345 | AC26: -3.608381e-06 | AD26: -0.0033666105 | AE26: -0.0069998591 | AF26: -0.0031850775 | AG26: -0.019727 | AH26: #DIV/0! | AI26: -0.00086235148 | AJ26: -0.0064848733
A27: 3 | B27: 149915 | C27: (CARTERA DE CRÉDITOS INMOBILIARIO) | D27: -0.00079646985 | E27: -0.0019949537 | F27: -0.0015240511 | G27: -0.00093843896 | H27: -0.001381769 | I27: -0.00044965365 | J27: -0.00051033532 | K27: 0 | L27: 0 | M27: -0.0016991711 | N27: -0.00076034115 | O27: -0.0012294888 | P27: -0.00044485771 | Q27: -4.3613167e-05 | R27: -0.00054584649 | S27: -0.00072246422 | T27: -7.0214358e-05 | U27: -4.2733418e-06 | V27: -8.0535518e-05 | W27: -6.1590744e-06 | X27: -3.1729871e-08 | Y27: 0 | Z27: -0.0021167326 | AA27: 0 | AB27: -0.0012412272 | AC27: 0 | AD27: -0.00045232207 | AE27: -0.0010701835 | AF27: -0.0006586757 | AG27: -0.00050630074 | AH27: #DIV/0! | AI27: 0 | AJ27: -0.0011696543
