Workbook

Sheet BALANCE
B2: ESTADO DE SITUACIÓN
B3: SISTEMA DE BANCOS PRIVADOS
B4: 31/12/2025
B5: (en miles de dólares)
B8: CÓDIGO | C8: CUENTA | D8: BP GUAYAQUIL | E8: BP PACIFICO | F8: BP PICHINCHA | G8: BP PRODUBANCO | H8: BANCOS PRIVADOS GRANDES | I8: BP AUSTRO | J8: BP BOLIVARIANO | K8: BP CITIBANK | L8: BP DINERS | M8: BP GENERAL RUMIÑAHUI | N8: BP INTERNACIONAL | O8: BP LOJA | P8: BP MACHALA | Q8: BP SOLIDARIO | R8: BANCOS PRIVADOS MEDIANOS | S8: BP PROCREDIT | T8: BP AMAZONAS | U8: BP BANCO COMERCIAL DE MANABI | V8: BP LITORAL | W8: BP COOPNACIONAL | X8: BP CAPITAL | Y8: BP DELBANK | Z8: BANCO ATLÁNTIDA S.A. | AA8: BP BANCO DESARROLLO DE LOS PUEBLOS S.A., CODESARROLLO | AB8: BP VISIONFUND ECUADOR S.A. | AC8: BANCOS PRIVADOS PEQUEÑOS | AD8: TOTAL BANCOS PRIVADOS | AE8: BANCOS PRIVADOS COMERCIALES | AF8: BANCOS PRIVADOS CONSUMO | AG8: BANCOS PRIVADOS VIVIENDA | AH8: BANCOS PRIVADOS MICROCRÉDITO | AI8: BANCA MÚLTIPLE
C9: ACTIVO
B10: 11 | C10: FONDOS DISPONIBLES | D10: 1012534 | E10: 1235542.8 | F10: 2498737.9 | G10: 981717.15 | H10: 5728532 | I10: 475145.08 | J10: 623981.53 | K10: 171488.36 | L10: 200616.25 | M10: 195315.74 | N10: 870369.02 | O10: 217427.37 | P10: 226529.59 | Q10: 72438.662 | R10: 3053311.6 | S10: 112879.01 | T10: 38903.616 | U10: 14053.52 | V10: 4211.866 | W10: 62878.608 | X10: 3006.965 | Y10: 7719.4678 | Z10: 11644.528 | AA10: 50258.056 | AB10: 13248.125 | AC10: 318803.76 | AD10: 9100647.3 | AE10: 1041857.4 | AF10: 400143.85 | AG10: 0 | AH10: 24892.653 | AI10: 7633753.4
B11: 1101 | C11: Caja | D11: 210660.51 | E11: 260202.89 | F11: 395013.43 | G11: 103733.6 | H11: 969610.43 | I11: 76237.982 | J11: 154205.18 | K11: 132.99 | L11: 3.1 | M11: 13313.452 | N11: 83146.229 | O11: 21448.534 | P11: 24352.66 | Q11: 17828.551 | R11: 390668.68 | S11: 4176.5703 | T11: 2098.6154 | U11: 2936.4617 | V11: 374.12083 | W11: 7113.5681 | X11: 191.42857 | Y11: 2215.0576 | Z11: 876.53716 | AA11: 4769.7263 | AB11: 1436.0947 | AC11: 26188.181 | AD11: 1386467.3 | AE11: 83279.219 | AF11: 13690.673 | AG11: 0 | AH11: 2312.6319 | AI11: 1287184.8
B12: 110105 | C12: Efectivo | D12: 210660.51 | E12: 260202.89 | F12: 394956.68 | G12: 103733.6 | H12: 969553.68 | I12: 76237.382 | J12: 154205.18 | K12: 132.99 | L12: 0 | M12: 13312.952 | N12: 83138.099 | O12: 21447.004 | P12: 24352.46 | Q12: 17810.351 | R12: 390636.42 | S12: 4176.5703 | T12: 2098.2154 | U12: 2935.4617 | V12: 373.80348 | W12: 7098.5681 | X12: 190.77857 | Y12: 2214.6576 | Z12: 876.53716 | AA12: 4764.3263 | AB12: 1423.4947 | AC12: 26152.413 | AD12: 1386342.5 | AE12: 83271.089 | AF12: 13686.756 | AG12: 0 | AH12: 2300.0319 | AI12: 1287084.6
B13: 110110 | C13: Caja chica | D13: 0 | E13: 0 | F13: 56.75 | G13: 0 | H13: 56.75 | I13: 0.6 | J13: 0 | K13: 0 | L13: 3.1 | M13: 0.5 | N13: 8.13 | O13: 1.53 | P13: 0.2 | Q13: 18.2 | R13: 32.26 | S13: 0 | T13: 0.4 | U13: 1 | V13: 0.31735 | W13: 15 | X13: 0.65 | Y13: 0.4 | Z13: 0 | AA13: 5.4 | AB13: 12.6 | AC13: 35.76735 | AD13: 124.77735 | AE13: 8.13 | AF13: 3.91735 | AG13: 0 | AH13: 12.6 | AI13: 100.13
B14: 1102 | C14: Depósitos para encaje | D14: 298492.71 | E14: 849788.36 | F14: 895328.25 | G14: 363803.85 | H14: 2407413.2 | I14: 192744.4 | J14: 198527.55 | K14: 75780.873 | L14: 119850.19 | M14: 49009.257 | N14: 490640.51 | O14: 114617.96 | P14: 57433.899 | Q14: 20940.562 | R14: 1319545.2 | S14: 65464.185 | T14: 21862.63 | U14: 4683.2675 | V14: 3672.5645 | W14: 8464.6794 | X14: 2715.4893 | Y14: 3706.0755 | Z14: 6551.7481 | AA14: 13224.602 | AB14: 3172.3963 | AC14: 133517.64 | AD14: 3860476 | AE14: 566421.38 | AF14: 172532.01 | AG14: 0 | AH14: 9724.1444 | AI14: 3111798.5
B15: 110205 | C15: Banco Central del Ecuador | D15: 298492.53 | E15: 849788.36 | F15: 895328.25 | G15: 363803.85 | H15: 2407413 | I15: 192744.4 | J15: 198527.55 | K15: 75780.873 | L15: 119850.19 | M15: 49009.257 | N15: 490640.51 | O15: 114615.83 | P15: 57433.899 | Q15: 20940.562 | R15: 1319543.1 | S15: 65464.185 | T15: 21862.63 | U15: 4683.2675 | V15: 3672.5645 | W15: 8464.6794 | X15: 2715.4893 | Y15: 3706.0755 | Z15: 6551.7481 | AA15: 13224.602 | AB15: 3172.3963 | AC15: 133517.64 | AD15: 3860473.7 | AE15: 566421.38 | AF15: 172532.01 | AG15: 0 | AH15: 9724.1444 | AI15: 3111796.2
B16: 110210 | C16: Banco Nacional de Fomento | D16: 0 | E16: 0 | F16: 0 | G16: 0 | H16: 0 | I16: 0 | J16: 0 | K16: 0 | L16: 0 | M16: 0 | N16: 0 | O16: 2.13793 | P16: 0 | Q16: 0 | R16: 2.13793 | S16: 0 | T16: 0 | U16: 0 | V16: 0 | W16: 0 | X16: 0 | Y16: 0 | Z16: 0 | AA16: 0 | AB16: 0 | AC16: 0 | AD16: 2.13793 | AE16: 0 | AF16: 0 | AG16: 0 | AH16: 0 | AI16: 2.13793
B17: 110215 | C17: Bancos locales | D17: 0.18693 | E17: 0 | F17: 0 | G17: 0 | H17: 0.18693 | I17: 0 | J17: 0 | K17: 0 | L17: 0 | M17: 0 | N17: 0 | O17: 0 | P17: 0 | Q17: 0 | R17: 0 | S17: 0 | T17: 0 | U17: 0 | V17: 0 | W17: 0 | X17: 0 | Y17: 0 | Z17: 0 | AA17: 0 | AB17: 0 | AC17: 0 | AD17: 0.18693 | AE17: 0 | AF17: 0 | AG17: 0 | AH17: 0 | AI17: 0.18693
B18: 1103 | C18: Bancos y otras instituciones financieras | D18: 470697.27 | E18: 116940.9 | F18: 1174063.4 | G18: 493553.19 | H18: 2255254.8 | I18: 202939.7 | J18: 254025.63 | K18: 95281.333 | L18: 80762.952 | M18: 132559.93 | N18: 278364.68 | O18: 81351.469 | P18: 142205.58 | Q18: 33291.05 | R18: 1300782.3 | S18: 42159.694 | T18: 14808.612 | U18: 5618.3098 | V18: 157.12811 | W18: 47286.443 | X18: 100.04713 | Y18: 1753.6679 | Z18: 4216.2425 | AA18: 32199.184 | AB18: 8639.3342 | AC18: 156938.66 | AD18: 3712975.8 | AE18: 373646.01 | AF18: 213480.01 | AG18: 0 | AH18: 12855.577 | AI18: 3112994.2
B19: 110305 | C19: Banco Central del Ecuador | D19: 0 | E19: 0 | F19: 0 | G19: 0 | H19: 0 | I19: 0 | J19: 0 | K19: 0 | L19: 0 | M19: 0 | N19: 0 | O19: 0 | P19: 0 | Q19: 0 | R19: 0 | S19: 0 | T19: 0 | U19: 0 | V19: 0 | W19: 0 | X19: 0 | Y19: 0 | Z19: 0 | AA19: 0 | AB19: 0 | AC19: 0 | AD19: 0 | AE19: 0 | AF19: 0 | AG19: 0 | AH19: 0 | AI19: 0
B20: 110310 | C20: Bancos e instituciones financieras locales | D20: 29231.685 | E20: 39208.346 | F20: 1012181.3 | G20: 184073.64 | H20: 1264695 | I20: 190908.65 | J20: 137619.1 | K20: 18031.522 | L20: 59535.479 | M20: 82077.494 | N20: 97061.581 | O20: 52312.821 | P20: 129311.8 | Q20: 11511.54 | R20: 778369.98 | S20: 38551.967 | T20: 13753.664 | U20: 4799.5376 | V20: 157.12811 | W20: 47286.443 | X20: 91.17285 | Y20: 1617.7859 | Z20: 4216.2425 | AA20: 29205.296 | AB20: 8639.3342 | AC20: 148318.57 | AD20: 2191383.5 | AE20: 115093.1 | AF20: 141770.1 | AG20: 0 | AH20: 12855.577 | AI20: 1921664.7
B21: 110315 | C21: Bancos e instituciones financieras del exterior | D21: 441465.59 | E21: 77732.558 | F21: 161882.12 | G21: 309479.55 | H21: 990559.81 | I21: 12031.052 | J21: 116406.54 | K21: 77249.811 | L21: 21227.473 | M21: 50482.432 | N21: 181303.1 | O21: 29038.648 | P21: 12893.778 | Q21: 21779.509 | R21: 522412.34 | S21: 3607.7272 | T21: 1054.9479 | U21: 818.77228 | V21: 0 | W21: 0 | X21: 8.87428 | Y21: 135.88199 | Z21: 0 | AA21: 2993.8879 | AB21: 0 | AC21: 8620.0916 | AD21: 1521592.2 | AE21: 258552.91 | AF21: 71709.905 | AG21: 0 | AH21: 0 | AI21: 1191329.4
... B750: +1+4 | C750: TOTAL ACTIVO Y GASTOS | D750: 10723674 | E750: 10819535 | F750: 23941863 | G750: 9935022.6 | H750: 55420094 | I750: 3688634 | J750: 6652903.9 | K750: 849954.32 | L750: 3868918.7 | M750: 1541110 | N750: 6496440.4 | O750: 1103601.8 | P750: 1357910.1 | Q750: 917687.32 | R750: 26477160 | S750: 786439.26 | T750: 463058.42 | U750: 151904.26 | V750: 48121.282 | W750: 248872.9 | X750: 87055.749 | Y750: 44275.044 | Z750: 142695.9 | AA750: 376224.59 | AB750: 194708.43 | AC750: 2543355.8 | AD750: 84440611 | AE750: 7346394.7 | AF750: 5458149.9 | AG750: 0 | AH750: 337404.34 | AI750: 71298662
C752: PASIVOS
B753: 21 | C753: OBLIGACIONES CON EL PÚBLICO | D753: 7713105.9 | E753: 7847569.2 | F753: 17657367 | G753: 7218086.1 | H753: 40436128 | I753: 2851376.1 | J753: 4723713.8 | K753: 646608.33 | L753: 1836693.5 | M753: 1139618.6 | N753: 4950342.4 | O753: 827237.62 | P753: 1028061.9 | Q753: 342953.33 | R753: 18346606 | S753: 625854.49 | T753: 346735.32 | U753: 116051.07 | V753: 29376.024 | W753: 196738.7 | X753: 59356.148 | Y753: 22297.447 | Z753: 98133.093 | AA753: 258898.53 | AB753: 62058.228 | AC753: 1815499.1 | AD753: 60598233 | AE753: 5596950.7 | AF753: 3005688.1 | AG753: 0 | AH753: 160191.32 | AI753: 51835402
B754: 2101 | C754: Depósitos a la vista | D754: 4192096.6 | E754: 3510597 | F754: 11818453 | G754: 4086242 | H754: 23607388 | I754: 1427745.9 | J754: 2514328 | K754: 646524.08 | L754: 186163.69 | M754: 438605.41 | N754: 2690834 | O754: 452040.49 | P754: 532327.51 | Q754: 89338.118 | R754: 8977907.2 | S754: 360460.32 | T754: 123051.89 | U754: 47615.149 | V754: 16599.158 | W754: 108469.64 | X754: 4202.416 | Y754: 9151.0389 | Z754: 25688.659 | AA754: 130387.66 | AB754: 14515.083 | AC754: 840141.01 | AD754: 33425437 | AE754: 3337358.1 | AF754: 641368.26 | AG754: 0 | AH754: 40203.741 | AI754: 29406506
B755: 210105 | C755: Depósitos monetarios que generan INTERESES | D755: 779877.64 | E755: 674840.5 | F755: 209976.64 | G755: 29489.693 | H755: 1694184.5 | I755: 58038.07 | J755: 597703.94 | K755: 137029.82 | L755: 0 | M755: 42544.4 | N755: 1192171.5 | O755: 0 | P755: 20923.914 | Q755: 11057.151 | R755: 2059468.8 | S755: 76439.69 | T755: 2887.9631 | U755: 3933.7155 | V755: 0 | W755: 0 | X755: 1671.1403 | Y755: 0 | Z755: 0 | AA755: 4065.2725 | AB755: 0 | AC755: 88997.781 | AD755: 3842651 | AE755: 1329201.3 | AF755: 42544.4 | AG755: 0 | AH755: 0 | AI755: 2470905.3
B756: 210110 | C756: Depósitos monetarios que no generan INTERESES | D756: 917808.53 | E756: 1022321.8 | F756: 3488745.9 | G756: 1669177.9 | H756: 7098054.1 | I756: 182989.23 | J756: 826382.84 | K756: 505116.32 | L756: 0 | M756: 55135.568 | N756: 326982.8 | O756: 88453.131 | P756: 166463.69 | Q756: 80.44795 | R756: 2151604 | S756: 0 | T756: 24020.545 | U756: 8854.1995 | V756: 7964.2761 | W756: 110.53401 | X756: 36.5142 | Y756: 2575.8454 | Z756: 0 | AA756: 0 | AB756: 0 | AC756: 43561.914 | AD756: 9293220 | AE756: 832099.12 | AF756: 63099.844 | AG756: 0 | AH756: 0 | AI756: 8398021.1
B757: 210115 | C757: Depósitos monetarios de instituciones financieras | D757: 385452.55 | E757: 10769.629 | F757: 448630.2 | G757: 192182.9 | H757: 1037035.3 | I757: 148739.07 | J757: 278682.82 | K757: 1984.809 | L757: 0 | M757: 4144.3556 | N757: 175769.86 | O757: 3250.006 | P757: 30656.838 | Q757: 5.38474 | R757: 643233.14 | S757: 1185.6536 | T757: 1710.7163 | U757: 1080.0412 | V757: 0 | W757: 0 | X757: 0 | Y757: 0 | Z757: 0 | AA757: 5205.0201 | AB757: 0 | AC757: 9181.4312 | AD757: 1689449.9 | AE757: 177754.67 | AF757: 4144.3556 | AG757: 0 | AH757: 0 | AI757: 1507550.8
B758: 210120 | C758: EJECUCIÓN PRESUPUESTARIA | D758: 2589.9418 | E758: 0.10005 | F758: 0 | G758: 0 | H758: 2590.0419 | I758: 0 | J758: 5558.0049 | K758: 0 | L758: 0 | M758: 0 | N758: 0 | O758: 72.57798 | P758: 413.65876 | Q758: 0 | R758: 6044.2416 | S758: 0 | T758: 0 | U758: 0 | V758: 0 | W758: 0 | X758: 0 | Y758: 0 | Z758: 0 | AA758: 0 | AB758: 0 | AC758: 0 | AD758: 8634.2835 | AE758: 0 | AF758: 0 | AG758: 0 | AH758: 0 | AI758: 8634.2835
B759: 210125 | C759: Depósitos de otras instituciones para encaje | D759: 0 | E759: 0 | F759: 0 | G759: 0 | H759: 0 | I759: 0 | J759: 0 | K759: 0 | L759: 0 | M759: 0 | N759: 0 | O759: 0 | P759: 0 | Q759: 0 | R759: 0 | S759: 0 | T759: 0 | U759: 0 | V759: 0 | W759: 0 | X759: 0 | Y759: 0 | Z759: 0 | AA759: 0 | AB759: 0 | AC759: 0 | AD759: 0 | AE759: 0 | AF759: 0 | AG759: 0 | AH759: 0 | AI759: 0
B760: 210130 | C760: Cheques certificados | D760: 6698.8545 | E760: 9251.4455 | F760: 16149.092 | G760: 8447.9776 | H760: 40547.37 | I760: 1406.637 | J760: 6680.8914 | K760: 2119.077 | L760: 0 | M760: 388.83846 | N760: 2812.4074 | O760: 237.27344 | P760: 986.12628 | Q760: 14.29581 | R760: 14645.547 | S760: 91.63723 | T760: 207.09813 | U760: 45.37173 | V760: 55.87421 | W760: 0.0117 | X760: 153.40232 | Y760: 4.44268 | Z760: 0 | AA760: 16.02143 | AB760: 0 | AC760: 573.85943 | AD760: 55766.776 | AE760: 4931.4844 | AF760: 444.71267 | AG760: 0 | AH760: 0 | AI760: 50390.579
B761: 210131 | C761: Cheques de emergencia | D761: 5754.6602 | E761: 5917.4362 | F761: 8318.496 | G761: 3206.199 | H761: 23196.791 | I761: 950.673 | J761: 3517.2016 | K761: 0 | L761: 0 | M761: 936.36896 | N761: 1793.8017 | O761: 17.62256 | P761: 1540.7718 | Q761: 464.81932 | R761: 9221.2589 | S761: 21.18986 | T761: 0 | U761: 347.2 | V761: 181.87996 | W761: 100.54859 | X761: 0 | Y761: 13.61283 | Z761: 0 | AA761: 0 | AB761: 0 | AC761: 664.43124 | AD761: 33082.482 | AE761: 1793.8017 | AF761: 1118.2489 | AG761: 0 | AH761: 0 | AI761: 30170.431
B762: 210135 | C762: Depósitos de ahorro | D762: 2036522.8 | E762: 1713328.2 | F762: 7569637.5 | G762: 2134820.4 | H762: 13454309 | I762: 1025411.3 | J762: 737232.2 | K762: 0 | L762: 170412.51 | M762: 331007 | N762: 968951.9 | O762: 355478.92 | P762: 308785.15 | Q762: 75255.614 | R762: 3972534.6 | S762: 281643.34 | T762: 78080.065 | U762: 33238.729 | V762: 8393.2852 | W762: 108244.63 | X762: 2280.2489 | Y762: 6138.6033 | Z762: 25685.883 | AA762: 120851.63 | AB762: 14451.107 | AC762: 679007.52 | AD762: 18105851 | AE762: 968951.9 | AF762: 509812.8 | AG762: 0 | AH762: 40136.99 | AI762: 16586949
B763: 210140 | C763: Otros depósitos | D763: 26.57289 | E763: 54380.593 | F763: 14670.681 | G763: 18693.416 | H763: 87771.262 | I763: 131.44344 | J763: 37884.076 | K763: 0 | L763: 5956.4863 | M763: 2543.5986 | N763: 1874.8429 | O763: 3448.9729 | P763: 74.95104 | Q763: 1586.9101 | R763: 53501.281 | S763: 0 | T763: 15873.39 | U763: 2.71882 | V763: 0.8 | W763: 0 | X763: 61.11033 | Y763: 411.35886 | Z763: 2.77546 | AA763: 184.77091 | AB763: 63.67604 | AC763: 16600.601 | AD763: 157873.14 | AE763: 1874.8429 | AF763: 8500.8849 | AG763: 0 | AH763: 66.4515 | AI763: 147430.96
B764: 210145 | C764: Fondos de tarjetahabientes | D764: 19885.7 | E764: 12398.889 | F764: 6188.5114 | G764: 8478.9931 | H764: 46952.093 | I764: 6865.8452 | J764: 2421.2948 | K764: 0 | L764: 9794.6888 | M764: 593.48318 | N764: 2444.4368 | O764: 85.51726 | P764: 339.19874 | Q764: 634.53042 | R764: 23178.995 | S764: 0 | T764: 240.44148 | U764: 0 | V764: 0 | W764: 0 | X764: 0 | Y764: 0 | Z764: 0 | AA764: 0 | AB764: 0 | AC764: 240.44148 | AD764: 70371.53 | AE764: 2444.4368 | AF764: 10388.172 | AG764: 0 | AH764: 0 | AI764: 57538.921
... B950: 2 | C950: TOTAL PASIVOS | D950: 8813834.7 | E950: 8764021.4 | F950: 19331677 | G950: 8362070.7 | H950: 45271603 | I950: 3078390.2 | J950: 5576518.5 | K950: 690837.14 | L950: 2714086.5 | M950: 1255990.6 | N950: 5475944.3 | O950: 914818.88 | P950: 1156629.5 | Q950: 616580.41 | R950: 21479796 | S950: 665281.14 | T950: 376292.74 | U950: 120451.51 | V950: 31147.688 | W950: 201300.46 | X950: 65567.478 | Y950: 27001.861 | Z950: 112055.39 | AA950: 299198.1 | AB950: 138960.77 | AC950: 2037257.1 | AD950: 68788657 | AE950: 6166781.4 | AF950: 4001224.8 | AG950: 0 | AH950: 251016.16 | AI950: 58369634
C952: PATRIMONIO
B953: 31 | C953: CAPITAL SOCIAL | D953: 646103 | E953: 645966.04 | F953: 1457000 | G953: 547720 | H953: 3296789 | I953: 199570 | J953: 445000 | K953: 76065.364 | L953: 400000 | M953: 101836.15 | N953: 413420.07 | O953: 61527 | P953: 71946 | Q953: 111107.14 | R953: 1880471.7 | S953: 52979 | T953: 35465.01 | U953: 15763.1 | V953: 11210.657 | W953: 24866.788 | X953: 16050 | Y953: 11671.864 | Z953: 14920 | AA953: 28587.8 | AB953: 20456.1 | AC953: 231970.32 | AD953: 5409231.1 | AE953: 489485.43 | AF953: 513046.8 | AG953: 0 | AH953: 35376.1 | AI953: 4371322.7
B954: 3101 | C954: Capital pagado | D954: 646103 | E954: 645966.04 | F954: 1463000 | G954: 547720 | H954: 3302789 | I954: 199570 | J954: 445000 | K954: 76065.364 | L954: 400000 | M954: 101836.15 | N954: 413420.07 | O954: 61527 | P954: 71946 | Q954: 111107.14 | R954: 1880471.7 | S954: 52979 | T954: 35465.01 | U954: 15763.1 | V954: 11210.657 | W954: 24866.788 | X954: 16050 | Y954: 11671.864 | Z954: 14920 | AA954: 28587.8 | AB954: 20456.1 | AC954: 231970.32 | AD954: 5415231.1 | AE954: 489485.43 | AF954: 513046.8 | AG954: 0 | AH954: 35376.1 | AI954: 4377322.7
B955: 3102 | C955: (Acciones en tesorería) | D955: 0 | E955: 0 | F955: -6000 | G955: 0 | H955: -6000 | I955: 0 | J955: 0 | K955: 0 | L955: 0 | M955: 0 | N955: 0 | O955: 0 | P955: 0 | Q955: 0 | R955: 0 | S955: 0 | T955: 0 | U955: 0 | V955: 0 | W955: 0 | X955: 0 | Y955: 0 | Z955: 0 | AA955: 0 | AB955: 0 | AC955: 0 | AD955: -6000 | AE955: 0 | AF955: 0 | AG955: 0 | AH955: 0 | AI955: -6000
B956: 3103 | C956: Aportes de socios | D956: 0 | E956: 0 | F956: 0 | G956: 0 | H956: 0 | I956: 0 | J956: 0 | K956: 0 | L956: 0 | M956: 0 | N956: 0 | O956: 0 | P956: 0 | Q956: 0 | R956: 0 | S956: 0 | T956: 0 | U956: 0 | V956: 0 | W956: 0 | X956: 0 | Y956: 0 | Z956: 0 | AA956: 0 | AB956: 0 | AC956: 0 | AD956: 0 | AE956: 0 | AF956: 0 | AG956: 0 | AH956: 0 | AI956: 0
B957: 32 | C957: PRIMA O DESCUENTO EN COLOCACIÓN DE ACCIONES Y CERTIFICADOS | D957: 0 | E957: 0 | F957: 0 | G957: 1104.7742 | H957: 1104.7742 | I957: 0 | J957: 0 | K957: 0 | L957: 0 | M957: 0 | N957: 0 | O957: 0 | P957: 0 | Q957: 0 | R957: 0 | S957: 0 | T957: 0 | U957: 0 | V957: 0 | W957: 0 | X957: 0 | Y957: 0 | Z957: 0 | AA957: 0 | AB957: 0 | AC957: 0 | AD957: 1104.7742 | AE957: 0 | AF957: 0 | AG957: 0 | AH957: 0 | AI957: 1104.7742
B958: 3201 | C958: Prima EN COLOCACIÓN de acciones y certificados de aportación | D958: 0 | E958: 0 | F958: 0 | G958: 1104.7742 | H958: 1104.7742 | I958: 0 | J958: 0 | K958: 0 | L958: 0 | M958: 0 | N958: 0 | O958: 0 | P958: 0 | Q958: 0 | R958: 0 | S958: 0 | T958: 0 | U958: 0 | V958: 0 | W958: 0 | X958: 0 | Y958: 0 | Z958: 0 | AA958: 0 | AB958: 0 | AC958: 0 | AD958: 1104.7742 | AE958: 0 | AF958: 0 | AG958: 0 | AH958: 0 | AI958: 1104.7742
...

Sheet PYG
B3: ESTADO DE PÉRDIDAS Y GANANCIAS
B4: SISTEMA DE BANCOS PRIVADOS
B5: 31/12/2025
B6: (en miles de dólares)
B8: CÓDIGO | C8: CUENTA | D8: BP GUAYAQUIL | E8: BP PACIFICO | F8: BP PICHINCHA | G8: BP PRODUBANCO | H8: BANCOS PRIVADOS GRANDES | I8: BP AUSTRO | J8: BP BOLIVARIANO | K8: BP CITIBANK | L8: BP DINERS | M8: BP GENERAL RUMIÑAHUI | N8: BP INTERNACIONAL | O8: BP LOJA | P8: BP MACHALA | Q8: BP SOLIDARIO | R8: BANCOS PRIVADOS MEDIANOS | S8: BP PROCREDIT | T8: BP AMAZONAS | U8: BP BANCO COMERCIAL DE MANABI | V8: BP LITORAL | W8: BP COOPNACIONAL | X8: BP CAPITAL | Y8: BP DELBANK | Z8: BANCO ATLÁNTIDA S.A. | AA8: BP BANCO DESARROLLO DE LOS PUEBLOS S.A., CODESARROLLO | AB8: BP VISIONFUND ECUADOR S.A. | AC8: BANCOS PRIVADOS PEQUEÑOS | AD8: TOTAL BANCOS PRIVADOS | AE8: BANCOS PRIVADOS COMERCIALES | AF8: BANCOS PRIVADOS CONSUMO | AG8: BANCOS PRIVADOS VIVIENDA | AH8: BANCOS PRIVADOS MICROCRÉDITO | AI8: BANCA MÚLTIPLE
B9: 5 | C9: INGRESOS | D9: 1141648.7 | E9: 1148450 | F9: 2639590.7 | G9: 933402.64 | H9: 5863092 | I9: 347384.93 | J9: 538528.74 | K9: 66719.813 | L9: 601913.03 | M9: 165798.87 | N9: 515723.58 | O9: 109582.39 | P9: 115769.42 | Q9: 155204.06 | R9: 2616624.8 | S9: 66573.908 | T9: 46694.442 | U9: 13222.642 | V9: 5377.9936 | W9: 13352.44 | X9: 10853.671 | Y9: 5478.9117 | Z9: 18689.402 | AA9: 40152.618 | AB9: 33350.923 | AC9: 253746.95 | AD9: 8733463.8 | AE9: 582443.4 | AF9: 773089.89 | AG9: 0 | AH9: 52040.326 | AI9: 7325890.2
B11: 51 | C11: INTERESES Y DESCUENTOS GANADOS | D11: 811373.86 | E11: 740517.5 | F11: 1854667.2 | G11: 660468.14 | H11: 4067026.7 | I11: 258538.69 | J11: 409127.21 | K11: 41936.962 | L11: 287242.27 | M11: 131281.35 | N11: 411192.59 | O11: 95915.067 | P11: 101606.91 | Q11: 115824.69 | R11: 1852665.7 | S11: 62106.599 | T11: 34072.388 | U11: 10370.381 | V11: 4587.0167 | W11: 11760.401 | X11: 6183.4066 | Y11: 3269.5239 | Z11: 10901.823 | AA11: 32512.74 | AB11: 28908.403 | AC11: 204672.68 | AD11: 6124365.1 | AE11: 453129.55 | AF11: 423110.64 | AG11: 0 | AH11: 39810.226 | AI11: 5208314.7
B12: 5101 | C12: Depósitos | D12: 2190.6773 | E12: 1578.4875 | F12: 30453.859 | G12: 11106.899 | H12: 45329.923 | I12: 5561.3059 | J12: 5318.4078 | K12: 2319.673 | L12: 523.8508 | M12: 4217.0865 | N12: 6948.3826 | O12: 2122.9008 | P12: 3394.3579 | Q12: 183.68303 | R12: 30589.648 | S12: 635.53972 | T12: 765.60765 | U12: 168.50418 | V12: 0.19109 | W12: 2264.9207 | X12: 7.63455 | Y12: 43.19513 | Z12: 240.37982 | AA12: 145.46343 | AB12: 117.98436 | AC12: 4389.4207 | AD12: 80308.992 | AE12: 9268.0556 | AF12: 4741.1284 | AG12: 0 | AH12: 358.36418 | AI12: 65941.444
B13: 5102 | C13: Operaciones interbancarias | D13: 0 | E13: 0 | F13: 14.41666 | G13: 2.01639 | H13: 16.43305 | I13: 0 | J13: 6.55554 | K13: 4.306 | L13: 0 | M13: 0 | N13: 17.79166 | O13: 0 | P13: 0 | Q13: 0 | R13: 28.6532 | S13: 0 | T13: 0 | U13: 0 | V13: 0 | W13: 0 | X13: 0 | Y13: 0 | Z13: 0 | AA13: 0 | AB13: 0 | AC13: 0 | AD13: 45.08625 | AE13: 22.09766 | AF13: 0 | AG13: 0 | AH13: 0 | AI13: 22.98859
B14: 5103 | C14: INTERESES y descuentos de inversiones en títulos valores | D14: 90618.347 | E14: 57079.332 | F14: 131822.24 | G14: 28989.466 | H14: 308509.39 | I14: 21458.496 | J14: 20945.142 | K14: 12777.769 | L14: 11316.139 | M14: 5716.9666 | N14: 26669.997 | O14: 4472.989 | P14: 7166.4339 | Q14: 3028.9459 | R14: 113552.88 | S14: 4187.5924 | T14: 2874.6928 | U14: 2027.1818 | V14: 159.82145 | W14: 6543.4205 | X14: 305.45248 | Y14: 182.61067 | Z14: 3570.5354 | AA14: 1860.355 | AB14: 74.03136 | AC14: 21785.694 | AD14: 443847.96 | AE14: 39447.766 | AF14: 17192.927 | AG14: 0 | AH14: 3644.5667 | AI14: 383562.7
B15: 5104 | C15: INTERESES Y DESCUENTOS DE CARTERA DE CRÉDITOS | D15: 718564.84 | E15: 681826.86 | F15: 1690900 | G15: 619320.97 | H15: 3710612.7 | I15: 230801.1 | J15: 382340.74 | K15: 25047.873 | L15: 274196.86 | M15: 121347.29 | N15: 377250.22 | O15: 89319.177 | P15: 91046.114 | Q15: 112612.06 | R15: 1703961.4 | S15: 57283.467 | T15: 28857.598 | U15: 8134.4175 | V15: 4427.0042 | W15: 2952.06 | X15: 5714.0586 | Y15: 3043.7181 | Z15: 7090.9083 | AA15: 30506.922 | AB15: 28716.387 | AC15: 176726.54 | AD15: 5591300.6 | AE15: 402298.1 | AF15: 399971.15 | AG15: 0 | AH15: 35807.295 | AI15: 4753224.1
B16: 510405 | C16: CARTERA DE CRÉDITOS PRODUCTIVO | D16: 239113.93 | E16: 132906.35 | F16: 492276.72 | G16: 273629.9 | H16: 1137926.9 | I16: 55928.247 | J16: 230169.17 | K16: 24926.136 | L16: 2709.3381 | M16: 6934.8973 | N16: 268583.92 | O16: 18482.447 | P16: 54221.475 | Q16: 0.02377 | R16: 661955.65 | S16: 28844.605 | T16: 10994.809 | U16: 2520.5389 | V16: 667.6398 | W16: 2430.9499 | X16: -3.46367 | Y16: 2019.5917 | Z16: 366.80253 | AA16: 3380.6066 | AB16: 0 | AC16: 51222.08 | AD16: 1851104.6 | AE16: 293510.05 | AF16: 10311.875 | AG16: 0 | AH16: 366.80253 | AI16: 1546915.9
B17: 510410 | C17: CARTERA DE CRÉDITOS DE CONSUMO | D17: 329300.8 | E17: 458001.96 | F17: 614487.06 | G17: 267965.78 | H17: 1669755.6 | I17: 149732.8 | J17: 132724.59 | K17: 0 | L17: 239143.59 | M17: 96806.779 | N17: 81515.988 | O17: 35909.159 | P17: 23815.408 | Q17: 40643.401 | R17: 800291.71 | S17: 1652.4724 | T17: 13385.744 | U17: 3113.97 | V17: 2957.9953 | W17: 53.70063 | X17: 3136.1332 | Y17: 541.81368 | Z17: 428.21297 | AA17: 12665.701 | AB17: 257.28973 | AC17: 38193.033 | AD17: 2508240.4 | AE17: 81515.988 | AF17: 338908.36 | AG17: 0 | AH17: 685.5027 | AI17: 2087130.5
B18: 510415 | C18: CARTERA DE CRÉDITOS INMOBILIARIO | D18: 22966.016 | E18: 41130.534 | F18: 85605.117 | G18: 30141.8 | H18: 179843.47 | I18: 5735.5732 | J18: 13400.603 | K18: 0 | L18: 32.87026 | M18: 10743.47 | N18: 15128.372 | O18: 5631.0311 | P18: 4234.4872 | Q18: 0 | R18: 54906.407 | S18: 2454.9851 | T18: 345.36954 | U18: 0 | V18: 0 | W18: 20.28524 | X18: 0 | Y18: 102.72215 | Z18: 4.5243 | AA18: 2289.6282 | AB18: 0 | AC18: 5217.5145 | AD18: 239967.39 | AE18: 15128.372 | AF18: 10776.34 | AG18: 0 | AH18: 4.5243 | AI18: 214058.15
B19: 510420 | C19: CARTERA DE CRÉDITOS PARA MICROCRÉDITO | D19: 83057.39 | E19: 610.06873 | F19: 382893.25 | G19: 5554.2029 | H19: 472114.92 | I19: 1731.0952 | J19: 84.83012 | K19: 0 | L19: 6.90606 | M19: 71.06555 | N19: 829.16849 | O19: 22612.717 | P19: 1202.9199 | Q19: 67024.754 | R19: 93563.457 | S19: 19389.147 | T19: 542.29569 | U19: 1349.8963 | V19: 187.65793 | W19: 445.70641 | X19: 1912.2488 | Y19: 52.3321 | Z19: 5565.734 | AA19: 10464.906 | AB19: 27756.928 | AC19: 67666.852 | AD19: 633345.22 | AE19: 829.16849 | AF19: 265.62954 | AG19: 0 | AH19: 33322.662 | AI19: 598927.76
B20: 510427 | C20: CARTERA DE CRÉDITO DE VIVIENDA DE INTERÉS SOCIAL Y PÚBLICO | D20: 0 | E20: 101.59694 | F20: 4376.6598 | G20: 0 | H20: 4478.2567 | I20: 0 | J20: 0 | K20: 0 | L20: 0 | M20: 492.92766 | N20: 14.36358 | O20: 0 | P20: 0 | Q20: 0 | R20: 507.29124 | S20: 0 | T20: 0 | U20: 0 | V20: 0 | W20: 0 | X20: 0 | Y20: 0 | Z20: 0 | AA20: 0 | AB20: 0 | AC20: 0 | AD20: 4985.548 | AE20: 14.36358 | AF20: 492.92766 | AG20: 0 | AH20: 0 | AI20: 4478.2567
B21: 510428 | C21: CARTERA DE CRÉDITO EDUCATIVO | D21: 149.0496 | E21: 11706.238 | F21: 3133.6639 | G21: 87.65435 | H21: 15076.606 | I21: 0 | J21: 214.70103 | K21: 0 | L21: 0 | M21: 0 | N21: 0 | O21: 18.20949 | P21: 110.23831 | Q21: 0 | R21: 343.14883 | S21: 3.3075 | T21: 0 | U21: 0 | V21: 0 | W21: 0 | X21: 0 | Y21: 0 | Z21: 0 | AA21: 0 | AB21: 0 | AC21: 3.3075 | AD21: 15423.062 | AE21: 0 | AF21: 0 | AG21: 0 | AH21: 0 | AI21: 15423.062
... B33: 4105 | C33: Otros INTERESES | D33: 0 | E33: 0 | F33: 7.91529 | G33: 0 | H33: 7.91529 | I33: 0 | J33: 0 | K33: 0 | L33: 0 | M33: 0 | N33: 0 | O33: 0 | P33: 0 | Q33: 0 | R33: 0 | S33: 0 | T33: 0.74169 | U33: 0 | V33: 0 | W33: 0 | X33: 2.05594 | Y33: 0 | Z33: 0 | AA33: 0 | AB33: 0 | AC33: 2.79763 | AD33: 10.71292 | AE33: 0 | AF33: 0 | AG33: 0 | AH33: 0 | AI33: 10.71292
C34: MARGEN NETO INTERESES | D34: 480964.56 | E34: 406459.26 | F34: 1236929 | G34: 369780.99 | H34: 2494133.8 | I34: 133690.45 | J34: 208722.37 | K34: 41376.667 | L34: 161866.29 | M34: 73153.521 | N34: 207508.02 | O34: 60519.322 | P34: 58725.505 | Q34: 76556.605 | R34: 1022118.7 | S34: 20953.342 | T34: 12782.802 | U34: 5568.3814 | V34: 3608.8799 | W34: 7610.8679 | X34: 2102.3488 | Y34: 1917.1388 | Z34: 4248.4807 | AA34: 19223.63 | AB34: 20500.198 | AC34: 98516.07 | AD34: 3614768.6 | AE34: 248884.69 | AF34: 238628.69 | AG34: 0 | AH34: 24748.679 | AI34: 3102506.6
B36: 52 | C36: COMISIONES GANADAS | D36: 98259.677 | E36: 56721.755 | F36: 68220.751 | G36: 34244.031 | H36: 257446.21 | I36: 17237.633 | J36: 41792.309 | K36: 3458.709 | L36: 72691.162 | M36: 6421.5154 | N36: 32923.346 | O36: 1138.0241 | P36: 1643.4657 | Q36: 3513.7799 | R36: 180819.94 | S36: 179.71074 | T36: 424.50522 | U36: 240.99461 | V36: 0 | W36: 0 | X36: 0 | Y36: 34.97712 | Z36: 0 | AA36: 222.17452 | AB36: 0 | AC36: 1102.3622 | AD36: 439368.52 | AE36: 36382.055 | AF36: 79112.677 | AG36: 0 | AH36: 0 | AI36: 323873.79
B37: 5201 | C37: Cartera de créditos | D37: 96.75831 | E37: 0 | F37: 0 | G37: 0 | H37: 96.75831 | I37: 0 | J37: 0 | K37: 0 | L37: 0 | M37: 0.0014 | N37: 0 | O37: 0 | P37: 0 | Q37: 0 | R37: 0.0014 | S37: 0 | T37: 0 | U37: 0 | V37: 0 | W37: 0 | X37: 0 | Y37: 0 | Z37: 0 | AA37: 0 | AB37: 0 | AC37: 0 | AD37: 96.75971 | AE37: 0 | AF37: 0.0014 | AG37: 0 | AH37: 0 | AI37: 96.75831
B38: 520105 | C38: Cartera de créditos productivo | D38: 3.45132 | E38: 0 | F38: 0 | G38: 0 | H38: 3.45132 | I38: 0 | J38: 0 | K38: 0 | L38: 0 | M38: 0.0014 | N38: 0 | O38: 0 | P38: 0 | Q38: 0 | R38: 0.0014 | S38: 0 | T38: 0 | U38: 0 | V38: 0 | W38: 0 | X38: 0 | Y38: 0 | Z38: 0 | AA38: 0 | AB38: 0 | AC38: 0 | AD38: 3.45272 | AE38: 0 | AF38: 0.0014 | AG38: 0 | AH38: 0 | AI38: 3.45132
B39: 520110 | C39: Cartera de créditos de consumo | D39: 76.4841 | E39: 0 | F39: 0 | G39: 0 | H39: 76.4841 | I39: 0 | J39: 0 | K39: 0 | L39: 0 | M39: 0 | N39: 0 | O39: 0 | P39: 0 | Q39: 0 | R39: 0 | S39: 0 | T39: 0 | U39: 0 | V39: 0 | W39: 0 | X39: 0 | Y39: 0 | Z39: 0 | AA39: 0 | AB39: 0 | AC39: 0 | AD39: 76.4841 | AE39: 0 | AF39: 0 | AG39: 0 | AH39: 0 | AI39: 76.4841
B40: 520115 | C40: Cartera de créditos de vivienda | D40: 0 | E40: 0 | F40: 0 | G40: 0 | H40: 0 | I40: 0 | J40: 0 | K40: 0 | L40: 0 | M40: 0 | N40: 0 | O40: 0 | P40: 0 | Q40: 0 | R40: 0 | S40: 0 | T40: 0 | U40: 0 | V40: 0 | W40: 0 | X40: 0 | Y40: 0 | Z40: 0 | AA40: 0 | AB40: 0 | AC40: 0 | AD40: 0 | AE40: 0 | AF40: 0 | AG40: 0 | AH40: 0 | AI40: 0
B41: 520120 | C41: Cartera de créditos PARA MICROCRÉDITO | D41: 16.82289 | E41: 0 | F41: 0 | G41: 0 | H41: 16.82289 | I41: 0 | J41: 0 | K41: 0 | L41: 0 | M41: 0 | N41: 0 | O41: 0 | P41: 0 | Q41: 0 | R41: 0 | S41: 0 | T41: 0 | U41: 0 | V41: 0 | W41: 0 | X41: 0 | Y41: 0 | Z41: 0 | AA41: 0 | AB41: 0 | AC41: 0 | AD41: 16.82289 | AE41: 0 | AF41: 0 | AG41: 0 | AH41: 0 | AI41: 16.82289
B42: 520125 | C42: Cartera de créditos reestructurada | D42: 0 | E42: 0 | F42: 0 | G42: 0 | H42: 0 | I42: 0 | J42: 0 | K42: 0 | L42: 0 | M42: 0 | N42: 0 | O42: 0 | P42: 0 | Q42: 0 | R42: 0 | S42: 0 | T42: 0 | U42: 0 | V42: 0 | W42: 0 | X42: 0 | Y42: 0 | Z42: 0 | AA42: 0 | AB42: 0 | AC42: 0 | AD42: 0 | AE42: 0 | AF42: 0 | AG42: 0 | AH42: 0 | AI42: 0
B43: 5202 | C43: Deudores por aceptación | D43: 0 | E43: 0 | F43: 0 | G43: 0 | H43: 0 | I43: 0 | J43: 383.42979 | K43: 0.484 | L43: 0 | M43: 0 | N43: 0 | O43: 0 | P43: 0 | Q43: 0 | R43: 383.91379 | S43: 0 | T43: 0 | U43: 0 | V43: 0 | W43: 0 | X43: 0 | Y43: 0 | Z43: 0 | AA43: 0 | AB43: 0 | AC43: 0 | AD43: 383.91379 | AE43: 0.484 | AF43: 0 | AG43: 0 | AH43: 0 | AI43: 383.42979
B44: 5203 | C44: Avales | D44: 0 | E44: 146.4117 | F44: 343.23203 | G44: 204.72042 | H44: 694.36415 | I44: 70.88362 | J44: 1591.5643 | K44: 0 | L44: 0 | M44: 23.47357 | N44: 724.16323 | O44: 117.32244 | P44: 25.41428 | Q44: 0 | R44: 2552.8214 | S44: 0 | T44: 0 | U44: 229.47083 | V44: 0 | W44: 0 | X44: 0 | Y44: 0 | Z44: 0 | AA44: 0 | AB44: 0 | AC44: 229.47083 | AD44: 3476.6564 | AE44: 724.16323 | AF44: 23.47357 | AG44: 0 | AH44: 0 | AI44: 2729.0196
B45: 5204 | C45: Fianzas | D45: 5286.2295 | E45: 4091.9315 | F45: 5131.2726 | G45: 4067.5778 | H45: 18577.011 | I45: 420.18007 | J45: 4388.9039 | K45: 3189.786 | L45: 12.6375 | M45: 247.8802 | N45: 5691.5616 | O45: 0 | P45: 454.5584 | Q45: 2.62167 | R45: 14408.129 | S45: 97.06601 | T45: 83.38729 | U45: 11.52378 | V45: 0 | W45: 0 | X45: 0 | Y45: 0 | Z45: 0 | AA45: 20.43507 | AB45: 0 | AC45: 212.41215 | AD45: 33197.553 | AE45: 8881.3476 | AF45: 260.5177 | AG45: 0 | AH45: 0 | AI45: 24055.688
B46: 5205 | C46: Cartas de Crédito | D46: 2450.2708 | E46: 938.7358 | F46: 7780.4615 | G46: 1718.8833 | H46: 12888.351 | I46: 239.26742 | J46: 2750.5189 | K46: 1.8 | L46: 0 | M46: 0 | N46: 4260.2109 | O46: 0 | P46: 39.94324 | Q46: 0 | R46: 7291.7405 | S46: 81.47512 | T46: 0 | U46: 0 | V46: 0 | W46: 0 | X46: 0 | Y46: 0 | Z46: 0 | AA46: 0 | AB46: 0 | AC46: 81.47512 | AD46: 20261.567 | AE46: 4262.0109 | AF46: 0 | AG46: 0 | AH46: 0 | AI46: 15999.556
B47: 5290 | C47: Otras | D47: 90426.418 | E47: 51544.676 | F47: 54965.785 | G47: 28252.85 | H47: 225189.73 | I47: 16507.302 | J47: 32677.892 | K47: 266.639 | L47: 72678.525 | M47: 6150.1602 | N47: 22247.41 | O47: 1020.7017 | P47: 1123.5497 | Q47: 3511.1583 | R47: 156183.34 | S47: 1.16961 | T47: 341.11793 | U47: 0 | V47: 0 | W47: 0 | X47: 0 | Y47: 34.97712 | Z47: 0 | AA47: 201.73945 | AB47: 0 | AC47: 579.00411 | AD47: 381952.07 | AE47: 22514.049 | AF47: 78828.685 | AG47: 0 | AH47: 0 | AI47: 280609.34
... B83: 4390 | C83: Otras | D83: 0 | E83: 0 | F83: 0 | G83: 0 | H83: 0 | I83: 0 | J83: 0 | K83: 0 | L83: 0 | M83: 0 | N83: 0 | O83: 0 | P83: 0 | Q83: 0 | R83: 0 | S83: 0 | T83: 0 | U83: 0 | V83: 0 | W83: 0 | X83: 0 | Y83: 0 | Z83: 0 | AA83: 0 | AB83: 0 | AC83: 0 | AD83: 0 | AE83: 0 | AF83: 0 | AG83: 0 | AH83: 0 | AI83: 0
C84: MARGEN BRUTO FINANCIERO | D84: 733941.98 | E84: 593557.38 | F84: 1707271.2 | G84: 558169.88 | H84: 3592940.5 | I84: 174471.72 | J84: 321554.28 | K84: 46976.086 | L84: 405783.01 | M84: 97679.329 | N84: 287523.2 | O84: 67732.352 | P84: 67992.807 | Q84: 105360.58 | R84: 1575073.4 | S84: 21723.158 | T84: 17875.071 | U84: 7718.9149 | V84: 3917.0539 | W84: 8712.4412 | X84: 2495.4519 | Y84: 3494.1582 | Z84: 6279.5542 | AA84: 18840.208 | AB84: 20886.197 | AC84: 111942.21 | AD84: 5279956 | AE84: 334499.29 | AF84: 507379.39 | AG84: 0 | AH84: 27165.751 | AI84: 4410911.6
B86: 44 | C86: PROVISIONES | D86: 233770.16 | E86: 192768.46 | F86: 650051.95 | G86: 223608.84 | H86: 1300199.4 | I86: 40273.219 | J86: 65599.784 | K86: 2957.022 | L86: 148967.27 | M86: 29611.548 | N86: 67539.279 | O86: 24029.032 | P86: 19376.457 | Q86: 30391.288 | R86: 428744.9 | S86: 5471.1537 | T86: 3913.9019 | U86: 611.84817 | V86: 215.02603 | W86: 69.62345 | X86: 1013.0203 | Y86: 280.51467 | Z86: 1796.3132 | AA86: 8169.7871 | AB86: 3152.2985 | AC86: 24693.487 | AD86: 1753637.8 | AE86: 70496.301 | AF86: 178793.85 | AG86: 0 | AH86: 4948.6118 | AI86: 1499399
B87: 4401 | C87: Inversiones | D87: 0 | E87: 0.00176 | F87: 3776.1786 | G87: 10.9437 | H87: 3787.1241 | I87: 472.70278 | J87: 0 | K87: 0 | L87: 0 | M87: 0 | N87: 0 | O87: 0 | P87: 0 | Q87: 0 | R87: 472.70278 | S87: 0 | T87: 0 | U87: 149.71337 | V87: 0 | W87: 0 | X87: 0 | Y87: 0 | Z87: 0 | AA87: 5.47909 | AB87: 0 | AC87: 155.19246 | AD87: 4415.0193 | AE87: 0 | AF87: 0 | AG87: 0 | AH87: 0 | AI87: 4415.0193
B88: 4402 | C88: CARTERA DE CRÉDITOS | D88: 218148.61 | E88: 174876.2 | F88: 587780.59 | G88: 191245.7 | H88: 1172051.1 | I88: 23450.642 | J88: 58933.854 | K88: 2885.76 | L88: 142643.78 | M88: 28321.92 | N88: 59678.173 | O88: 23297.389 | P88: 16951.267 | Q88: 30169.275 | R88: 386332.06 | S88: 3474.061 | T88: 2900.0141 | U88: 280.91016 | V88: 173.8514 | W88: 41.21628 | X88: 885.01102 | Y88: 255.23713 | Z88: 1751.5159 | AA88: 7390.8119 | AB88: 2930.9055 | AC88: 20083.534 | AD88: 1578466.7 | AE88: 62563.933 | AF88: 171139.55 | AG88: 0 | AH88: 4682.4214 | AI88: 1340080.8
B89: 440210 | C89: CRÉDITO PRODUCTIVO | D89: 11980.924 | E89: 16984.548 | F89: 136595.14 | G89: 16489.912 | H89: 182050.53 | I89: 1849.7122 | J89: 12847.42 | K89: 2885.76 | L89: 3157.0066 | M89: 0 | N89: 13803.086 | O89: 3687.7309 | P89: 8604.1394 | Q89: 0 | R89: 46834.855 | S89: 1808.3095 | T89: 1117.2153 | U89: 68.68374 | V89: 25.17192 | W89: 0.13748 | X89: 3.72261 | Y89: 186.53299 | Z89: 175.69909 | AA89: 304.49738 | AB89: 0 | AC89: 3689.97 | AD89: 232575.35 | AE89: 16688.846 | AF89: 3182.1785 | AG89: 0 | AH89: 175.69909 | AI89: 212528.63
B90: 440220 | C90: CRÉDITO DE CONSUMO | D90: 166014.9 | E90: 150148.23 | F90: 285689.35 | G90: 170496.18 | H90: 772348.65 | I90: 20768.346 | J90: 45215.522 | K90: 0 | L90: 138948.16 | M90: 28321.92 | N90: 44561.278 | O90: 17499.512 | P90: 7149.6718 | Q90: 9598.7622 | R90: 312063.17 | S90: 216.47319 | T90: 1737.447 | U90: 79.34045 | V90: 121.39663 | W90: 7.71614 | X90: 562.86815 | Y90: 67.59737 | Z90: 121.2138 | AA90: 2613.709 | AB90: 52.38639 | AC90: 5580.1481 | AD90: 1089992 | AE90: 44561.278 | AF90: 167391.47 | AG90: 0 | AH90: 173.60019 | AI90: 877865.61
B91: 440230 | C91: CRÉDITO INMOBILIARIO | D91: 1553.0406 | E91: 6967.4677 | F91: 15369.58 | G91: 2498.8263 | H91: 26388.914 | I91: 706.45247 | J91: 800.93 | K91: 0 | L91: 0 | M91: 0 | N91: 1278.4129 | O91: 404.62843 | P91: 241.94144 | Q91: 0 | R91: 3432.3652 | S91: 10.63782 | T91: 6.96654 | U91: 0 | V91: 0 | W91: 0 | X91: 0 | Y91: 0.49499 | Z91: 1.2452 | AA91: 246.22323 | AB91: 0 | AC91: 265.56778 | AD91: 30086.847 | AE91: 1278.4129 | AF91: 0 | AG91: 0 | AH91: 1.2452 | AI91: 28807.189
B92: 440235 | C92: CRÉDITO DE VIVIENDA DE INTERÉS SOCIAL Y PÚBLICO | D92: 0 | E92: 348.18229 | F92: 135.84722 | G92: 0 | H92: 484.02951 | I92: 0 | J92: 0 | K92: 0 | L92: 0 | M92: 0 | N92: 0.24413 | O92: 0 | P92: 0 | Q92: 0 | R92: 0.24413 | S92: 0 | T92: 0 | U92: 0 | V92: 0 | W92: 0 | X92: 0 | Y92: 0 | Z92: 0 | AA92: 0 | AB92: 0 | AC92: 0 | AD92: 484.27364 | AE92: 0.24413 | AF92: 0 | AG92: 0 | AH92: 0 | AI92: 484.02951
...

Sheet BALANCE %
B3: ESTADO DE SITUACIÓN CONSOLIDADO
B4: SISTEMA DE BANCOS PRIVADOS
B5: 31/12/2025
B6: (en porcentajes)
B8: CÓDIGO | C8: CUENTA | D8: BP GUAYAQUIL | E8: BP PACIFICO | F8: BP PICHINCHA | G8: BP PRODUBANCO | H8: BANCOS PRIVADOS GRANDES | I8: BP AUSTRO | J8: BP BOLIVARIANO | K8: BP CITIBANK | L8: BP DINERS | M8: BP GENERAL RUMIÑAHUI | N8: BP INTERNACIONAL | O8: BP LOJA | P8: BP MACHALA | Q8: BP SOLIDARIO | R8: BANCOS PRIVADOS MEDIANOS | S8: BP PROCREDIT | T8: BP AMAZONAS | U8: BP BANCO COMERCIAL DE MANABI | V8: BP LITORAL | W8: BP COOPNACIONAL | X8: BP CAPITAL | Y8: BP DELBANK | Z8: BANCO ATLÁNTIDA S.A. | AA8: BP BANCO DESARROLLO DE LOS PUEBLOS S.A., CODESARROLLO | AB8: BP VISIONFUND ECUADOR S.A. | AC8: BANCOS PRIVADOS PEQUEÑOS | AD8: TOTAL BANCOS PRIVADOS | AE8: BANCOS PRIVADOS COMERCIALES | AF8: BANCOS PRIVADOS CONSUMO | AG8: BANCOS PRIVADOS VIVIENDA | AH8: BANCOS PRIVADOS MICROCRÉDITO | AI8: BANCA MÚLTIPLE
C9: ACTIVO
B10: 11 | C10: FONDOS DISPONIBLES | D10: 0.10401303 | E10: 0.12509018 | F10: 0.11598963 | G10: 0.10803661 | H10: 0.11401978 | I10: 0.14121236 | J10: 0.10088554 | K10: 0.21306848 | L10: 0.060608149 | M10: 0.14046056 | N10: 0.14388977 | O10: 0.21643479 | P10: 0.1812971 | Q10: 0.094651477 | R10: 0.12657 | S10: 0.15891682 | T10: 0.093133348 | U10: 0.10131992 | V10: 0.098118005 | W10: 0.26645154 | X10: 0.039507497 | Y10: 0.19892412 | Z10: 0.093890821 | AA10: 0.14865752 | AB10: 0.079872142 | AC10: 0.13930543 | AD10: 0.11872435 | AE10: 0.15201363 | AF10: 0.084355917 | AG10: 0 | AH10: 0.085869702 | AI10: 0.11786582
B11: 12 | C11: OPERACIONES INTERBANCARIAS | D11: 0 | E11: 0 | F11: 0 | G11: 0 | H11: 0 | I11: 0 | J11: 0 | K11: 0 | L11: 0 | M11: 0 | N11: 0 | O11: 0 | P11: 0 | Q11: 0 | R11: 0 | S11: 0 | T11: 0 | U11: 0 | V11: 0 | W11: 0 | X11: 0 | Y11: 0 | Z11: 0 | AA11: 0 | AB11: 0 | AC11: 0 | AD11: 0 | AE11: 0 | AF11: 0 | AG11: 0 | AH11: 0 | AI11: 0
B12: 13 | C12: INVERSIONES | D12: 0.15520984 | E12: 0.1942001 | F12: 0.21062203 | G12: 0.1696505 | H12: 0.18924676 | I12: 0.20031243 | J12: 0.18010838 | K12: 0.31829912 | L12: 0.081626781 | M12: 0.16850648 | N12: 0.12970145 | O12: 0.13500869 | P12: 0.12142123 | Q12: 0.090338397 | R12: 0.15295019 | S12: 0.097167095 | T12: 0.21949281 | U12: 0.29849813 | V12: 0.091344894 | W12: 0.56032853 | X12: 0.075767405 | Y12: 0.049556261 | Z12: 0.28115768 | AA12: 0.18230881 | AB12: 0.028108311 | AC12: 0.19537246 | AD12: 0.17800682 | AE12: 0.15184902 | AF12: 0.10718306 | AG12: 0 | AH12: 0.1363695 | AI12: 0.18614841
C13: INVERSIONES DEL SECTOR PRIVADO | D13: 0.008003797 | E13: 0.04724842 | F13: 0.036377404 | G13: 0.09228086 | H13: 0.04312791 | I13: 0.073176102 | J13: 0.024075802 | K13: 0.077032897 | L13: 0.0026326877 | M13: 0.060208088 | N13: 0.060204261 | O13: 0.065215605 | P13: 0.016214818 | Q13: 0.041989443 | R13: 0.042765062 | S13: 0.003802035 | T13: 0.11732124 | U13: 0.21094263 | V13: 0.015142149 | W13: 0.48198154 | X13: 0.000181606 | Y13: 0 | Z13: 0.10550277 | AA13: 0.12468179 | AB13: 0 | AC13: 0.1095064 | AD13: 0.044995475 | AE13: 0.062180496 | AF13: 0.019623824 | AG13: 0 | AH13: 0.045136864 | AI13: 0.045034519
C14: INVERSIONES DEL SECTOR PUBLICO | D14: 0.13698846 | E14: 0.13662178 | F14: 0.15350368 | G14: 0.066286098 | H14: 0.13121032 | I14: 0.11404083 | J14: 0.14827537 | K14: 0.24126622 | L14: 0.06673125 | M14: 0.10256925 | N14: 0.062910048 | O14: 0.069698516 | P14: 0.097339157 | Q14: 0.048348955 | R14: 0.1022937 | S14: 0.09091282 | T14: 0.10153882 | U14: 0.08530484 | V14: 0.076202744 | W14: 0.078427496 | X14: 0.070134831 | Y14: 0.048332226 | Z14: 0.16466816 | AA14: 0.057627023 | AB14: 0.028108311 | AC14: 0.084063895 | AD14: 0.12070245 | AE14: 0.083854927 | AF14: 0.077322688 | AG14: 0 | AH14: 0.086532212 | AI14: 0.12793182
B15: 1307 | C15: De disponibilidad restringida | D15: 0.010226659 | E15: 0.010619272 | F15: 0.02311989 | G15: 0.011088597 | H15: 0.015988147 | I15: 0.013235983 | J15: 0.0079441317 | K15: 0 | L15: 0.012262843 | M15: 0.0072942273 | N15: 0.0065871399 | O15: 9.9543491e-05 | P15: 0.0078672588 | Q15: 0 | R15: 0.0080493704 | S15: 0.0024522397 | T15: 0.00074421969 | U15: 0.0052657911 | V15: 0 | W15: 0 | X15: 0.005450968 | Y15: 0.0012884574 | Z15: 0.01098675 | AA15: 0 | AB15: 0 | AC15: 0.0020146501 | AD15: 0.013072566 | AE15: 0.0058135931 | AF15: 0.010695346 | AG15: 0 | AH15: 0.0047004208 | AI15: 0.014052306
B16: 1399 | C16: (Provisión para inversiones) | D16: -9.078624e-06 | E16: -0.0002893778 | F16: -0.0023789445 | G16: -5.056041e-06 | H16: -0.0010796165 | I16: -0.00014048651 | J16: -0.00018692775 | K16: 0 | L16: 0 | M16: -0.001565088 | N16: 0 | O16: -4.977175e-06 | P16: 0 | Q16: 0 | R16: -0.00015794446 | S16: 0 | T16: -0.00011146518 | U16: -0.0030151326 | V16: 0 | W16: -8.0504386e-05 | X16: 0 | Y16: -6.4422872e-05 | Z16: 0 | AA16: 0 | AB16: 0 | AC16: -0.00021248251 | AD16: -0.00076367028 | AE16: 0 | AF16: -0.00045879748 | AG16: 0 | AH16: 0 | AI16: -0.00087023041
B17: 14 | C17: CARTERA DE CRÉDITOS | D17: 0.67654236 | E17: 0.61794319 | F17: 0.56940454 | G17: 0.67017338 | H17: 0.6179312 | I17: 0.52754745 | J17: 0.66540337 | K17: 0.4297836 | L17: 0.76953226 | M17: 0.63901952 | N17: 0.67716246 | O17: 0.603164 | P17: 0.63660907 | Q17: 0.7451697 | R17: 0.65247685 | S17: 0.69764482 | T17: 0.56288265 | U17: 0.42978584 | V17: 0.73065234 | W17: 0.14347556 | X17: 0.68707083 | Y17: 0.68880279 | Z17: 0.52677581 | AA17: 0.61087875 | AB17: 0.86574897 | AC17: 0.58989184 | AD17: 0.62796587 | AE17: 0.64811205 | AF17: 0.73092128 | AG17: 0 | AH17: 0.72072733 | AI17: 0.61787828
C18: CARTERA DE CRÉDITOS PRODUCTIVO | D18: 0.34607966 | E18: 0.24997195 | F18: 0.2528779 | G18: 0.41567744 | H18: 0.29980974 | I18: 0.18069562 | J18: 0.48174692 | K18: 0.45102874 | L18: 0.054093944 | M18: 0.067026265 | N18: 0.57072975 | O18: 0.18877277 | P18: 0.46413152 | Q18: 2.5476274e-05 | R18: 0.35006283 | S18: 0.4431912 | T18: 0.28381499 | U18: 0.23270159 | V18: 0.21500343 | W18: 0.14159333 | X18: 0.0078959612 | Y18: 0.54046924 | Z18: 0.06775265 | AA18: 0.09336188 | AB18: 0 | AC18: 0.24898843 | AD18: 0.3141075 | AE18: 0.55667292 | AF18: 0.05934114 | AG18: 0 | AH18: 0.028986368 | AI18: 0.30837412
C19: CARTERA DE CRÉDITOS CONSUMO | D19: 0.28330458 | E19: 0.34457536 | F19: 0.24136852 | G19: 0.2463718 | H19: 0.27068876 | I19: 0.34509145 | J19: 0.17337619 | K19: 0 | L19: 0.77366053 | M19: 0.53941582 | N19: 0.10780367 | O19: 0.2800279 | P19: 0.15552272 | Q19: 0.4020413 | R19: 0.28933777 | S19: 0.017517437 | T19: 0.28015245 | U19: 0.15601505 | V19: 0.54238322 | W19: 0.0020087482 | X19: 0.4657482 | Y19: 0.12551983 | Z19: 0.11026478 | AA19: 0.27561445 | AB19: 0.02136511 | AC19: 0.14226757 | AD19: 0.27272369 | AE19: 0.095143971 | AF19: 0.70289995 | AG19: 0 | AH19: 0.059398729 | AI19: 0.26096408
C20: CARTERA DE CRÉDITOS INMOBILIARIO | D20: 0.024093455 | E20: 0.049955917 | F20: 0.047674386 | G20: 0.035190611 | H20: 0.041296072 | I20: 0.017769259 | J20: 0.026614951 | K20: 0 | L20: 4.9923418e-05 | M20: 0.087983312 | N20: 0.026128043 | O20: 0.058695897 | P20: 0.035316729 | Q20: 5.0959e-08 | R20: 0.025205762 | S20: 0.038683892 | T20: 0.0084384325 | U20: 0 | V20: 0.00084925839 | W20: 0.00091381528 | X20: 0 | Y20: 0.036884301 | Z20: 0.0010040126 | AA20: 0.094094246 | AB20: 0 | AC20: 0.02823718 | AD20: 0.035842444 | AE20: 0.023059752 | AF20: 0.025834376 | AG20: 0 | AH20: 0.00042954305 | AI20: 0.038086631
C21: CARTERA DE CRÉDITOS MICROCRÉDITO | D21: 0.046679776 | E21: 0.0016287272 | F21: 0.099281057 | G21: 0.0067179592 | H21: 0.053149908 | I21: 0.0043532459 | J21: 0.00013465733 | K21: 0 | L21: 0.003223202 | M21: 0.00023469954 | N21: 0.00097072104 | O21: 0.14605601 | P21: 0.0079364115 | Q21: 0.42031427 | R21: 0.021168766 | S21: 0.22611271 | T21: 0.01322272 | U21: 0.049492742 | V21: 0.029420115 | W21: 0.0093887901 | X21: 0.23145323 | Y21: 0.0054366511 | Z21: 0.36894456 | AA21: 0.20368498 | AB21: 0.90651858 | AC21: 0.20068944 | AD21: 0.047490037 | AE21: 0.00085672648 | AF21: 0.0025842073 | AG21: 0 | AH21: 0.67653026 | AI21: 0.052898255
C22: CARTERA DE CRÉDITOS VIVIENDA DE INTERÉS SOCIAL Y PÚBLICO | D22: 0 | E22: 0.00034893266 | F22: 0.00034611953 | G22: 0 | H22: 0.00021700871 | I22: 0 | J22: 0 | K22: 0 | L22: 0 | M22: 0.0098153564 | N22: 4.7544679e-05 | O22: 0 | P22: 0 | Q22: 0 | R22: 0.0005777029 | S22: 0 | T22: 0 | U22: 0 | V22: 0 | W22: 0 | X22: 0 | Y22: 0 | Z22: 0 | AA22: 0 | AB22: 0 | AC22: 0 | AD22: 0.00032404319 | AE22: 4.196137e-05 | AF22: 0.0028773211 | AG22: 0 | AH22: 0 | AI22: 0.00016834107
C23: CARTERA DE CRÃ¿DITOS EDUCATIVO | D23: 0.00016903451 | E23: 0.012246797 | F23: 0.0016378248 | G23: 0.00010158754 | H23: 0.0031610513 | I23: 0 | J23: 0.00038257629 | K23: 0 | L23: 0 | M23: 0 | N23: 0 | O23: 0.00020080706 | P23: 0.00087118847 | Q23: 0 | R23: 0.00015157517 | S23: 2.5788241e-05 | T23: 0 | U23: 0 | V23: 0 | W23: 0 | X23: 0 | Y23: 0 | Z23: 0 | AA23: 0 | AB23: 0 | AC23: 8.004047e-06 | AD23: 0.0021198094 | AE23: 0 | AF23: 0 | AG23: 0 | AH23: 0 | AI23: 0.0025088753
C24: CARTERA DE CRÉDITO INVERSIÓN PÚBLICA | D24: 0 | E24: 0 | F24: 0 | G24: 0 | H24: 0 | I24: 0 | J24: 0 | K24: 0 | L24: 0 | M24: 0 | N24: 0 | O24: 0 | P24: 0 | Q24: 0 | R24: 0 | S24: 0 | T24: 0 | U24: 0 | V24: 0 | W24: 0 | X24: 0 | Y24: 0 | Z24: 0 | AA24: 0 | AB24: 0 | AC24: 0 | AD24: 0 | AE24: 0 | AF24: 0 | AG24: 0 | AH24: 0 | AI24: 0
B25: 1499 | C25: (PROVISIONES PARA CRÉDITOS INCOBRABLES) | D25: -0.023784144 | E25: -0.040784506 | F25: -0.073781273 | G25: -0.033886011 | H25: -0.050391347 | I25: -0.020362116 | J25: -0.016851923 | K25: -0.021245146 | L25: -0.061495333 | M25: -0.065455933 | N25: -0.028517264 | O25: -0.070589388 | P25: -0.027169496 | Q25: -0.077211397 | R25: -0.034027565 | S25: -0.027886202 | T25: -0.022745944 | U25: -0.0084235426 | V25: -0.057003684 | W25: -0.010429127 | X25: -0.01802656 | Y25: -0.019507239 | Z25: -0.021190194 | AA25: -0.055876806 | AB25: -0.06213472 | AC25: -0.030298787 | AD25: -0.044641662 | AE25: -0.027663278 | AF25: -0.062615715 | AG25: 0 | AH25: -0.044617573 | AI25: -0.045122028
B26: 149905 | C26: (CARTERA DE CRÉDITOS PRODUCTIVO) | D26: -0.0042870144 | E26: -0.0034792789 | F26: -0.0090292933 | G26: -0.0060121072 | H26: -0.0064736378 | I26: -0.0028586491 | J26: -0.0048945514 | K26: -0.013096651 | L26: -0.0018907914 | M26: -0.0030526809 | N26: -0.014138784 | O26: -0.012730167 | P26: -0.0046050779 | Q26: -2.79295e-07 | R26: -0.0068398988 | S26: -0.0080385225 | T26: -0.0058440951 | U26: -0.0020630996 | V26: -0.0045709294 | W26: -0.0063763634 | X26: -6.7779598e-05 | Y26: -0.010679783 | Z26: -0.0014650553 | AA26: -0.0010328819 | AB26: 0 | AC26: -0.004845295 | AD26: -0.0065402883 | AE26: -0.014016404 | AF26: -0.0022556472 | AG26: 0 | AH26: -0.00062678923 | AI26: -0.0060894284
B27: 149910 | C27: (CARTERA DE CRÉDITOS DE CONSUMO) | D27: -0.0070656442 | E27: -0.010799912 | F27: -0.0084342896 | G27: -0.006735524 | H27: -0.0083269269 | I27: -0.011034676 | J27: -0.0065192353 | K27: 0 | L27: -0.024545754 | M27: -0.016816444 | N27: -0.0070784665 | O27: -0.013805228 | P27: -0.0055304974 | Q27: -0.022159249 | R27: -0.010887178 | S27: -0.00053510072 | T27: -0.0069986325 | U27: -0.0023544665 | V27: -0.031087034 | W27: -4.5692408e-05 | X27: -0.0096444148 | Y27: -0.0021956266 | Z27: -0.0011135034 | AA27: -0.015476065 | AB27: -0.00034792593 | AC27: -0.0049038452 | AD27: -0.0090304609 | AE27: -0.0062472218 | AF27: -0.022339142 | AG27: 0 | AH27: -0.00067546012 | AI27: -0.0083876523
B28: 149915 | C28: (CARTERA DE CRÉDITOS INMOBILIARIO) | D28: -0.00035796243 | E28: -0.0012483851 | F28: -0.0010792994 | G28: -0.00082303306 | H28: -0.00092642685 | I28: -0.00060947027 | J28: -0.000444712 | K28: 0 | L28: -4.99234e-07 | M28: -0.0011124769 | N28: -0.00056418147 | O28: -0.0016017725 | P28: -0.00067324092 | Q28: -5.0959e-08 | R28: -0.00050626554 | S28: -0.00044917377 | T28: -0.0001155914 | U28: 0 | V28: -2.3296e-08 | W28: -1.3473347e-05 | X28: 0 | Y28: -0.00038525341 | Z28: -1.0040154e-05 | AA28: -0.0010534399 | AB28: 0 | AC28: -0.00032460069 | AD28: -0.00077623094 | AE28: -0.00049792801 | AF28: -0.00032646544 | AG28: 0 | AH28: -4.295442e-06 | AI28: -0.00084207757
B29: 149920 | C29: (CARTERA DE CRÉDITOS PARA MICROCRÉDITO) | D29: -0.0016977219 | E29: -1.3931343e-05 | F29: -0.0050080175 | G29: -0.00011896071 | H29: -0.0025005579 | I29: -0.00036102165 | J29: -4.470183e-06 | K29: 0 | L29: -9.2846434e-05 | M29: -4.936694e-06 | N29: -1.5993916e-05 | O29: -0.006192526 | P29: -0.00067633653 | Q29: -0.038267191 | R29: -0.0015754753 | S29: -0.0043750614 | T29: -0.00016464977 | U29: -0.00060447413 | V29: -0.001837063 | W29: -0.00012938949 | X29: -0.0036878607 | Y29: -6.6279024e-05 | Z29: -0.01149694 | AA29: -0.023670452 | AB29: -0.048415639 | AC29: -0.0092250735 | AD29: -0.0024101901 | AE29: -1.4115704e-05 | AF29: -8.2860459e-05 | AG29: 0 | AH29: -0.032620847 | AI29: -0.0026989815
B30: 149940 | C30: (CARTERA DE CRÉDITOS DE VIVIENDA DE INTERÉS SOCIAL Y PÚBLICO) | D30: 0 | E30: -1.9149073e-05 | F30: -3.478909e-06 | G30: 0 | H30: -5.256303e-06 | I30: 0 | J30: 0 | K30: 0 | L30: 0 | M30: -0.00028613551 | N30: -2.067765e-06 | O30: 0 | P30: 0 | Q30: 0 | R30: -1.7012037e-05 | S30: 0 | T30: 0 | U30: 0 | V30: 0 | W30: 0 | X30: 0 | Y30: 0 | Z30: 0 | AA30: 0 | AB30: 0 | AC30: 0 | AD30: -8.798998e-06 | AE30: -1.824941e-06 | AF30: -8.3879148e-05 | AG30: 0 | AH30: 0 | AI30: -4.077494e-06
B31: 149945 | C31: (CARTERA DE CRÉDITO REFINANCIADA) | D31: -0.0017524699 | E31: -0.0007704982 | F31: -0.00055612089 | G31: -0.0022824714 | H31: -0.0011423028 | I31: -0.0020046971 | J31: -5.5832489e-05 | K31: 0 | L31: -0.0016770472 | M31: -0.0034484364 | N31: -0.00097702065 | O31: -0.004766685 | P31: -0.0044579603 | Q31: -0.0010833637 | R31: -0.0014315774 | S31: -0.0039944319 | T31: -0.0028432593 | U31: -0.00040403372 | V31: -0.013195951 | W31: -3.77142e-07 | X31: -0.00029366276 | Y31: -0.0019928419 | Z31: -0.0029741068 | AA31: -0.010328619 | AB31: -0.0020786412 | AC31: -0.0039120147 | AD31: -0.0013160307 | AE31: -0.0008622863 | AF31: -0.0023005613 | AG31: 0 | AH31: -0.002461745 | AI31: -0.0012868113
B32: 149950 | C32: (CARTERA DE CRÉDITO REESTRUCTURADA) | D32: -0.0024017124 | E32: -0.0071243319 | F32: -0.01032085 | G32: -0.0095649732 | H32: -0.0080213282 | I32: -0.0033162269 | J32: -0.0012262749 | K32: 0 | L32: -0.015838852 | M32: -0.0021762358 | N32: -0.0037747604 | O32: -0.0062571931 | P32: -0.0077143081 | Q32: -0.0021335764 | R32: -0.0047500227 | S32: -0.010491741 | T32: -0.0065421603 | U32: -0.00014588022 | V32: -0.0054977423 | W32: 0 | X32: -0.00023860415 | Y32: -0.0010178595 | Z32: -0.0041305487 | AA32: -0.0042583975 | AB32: -0.00056864696 | AC32: -0.0054818163 | AD32: -0.0069160039 | AE32: -0.0033314794 | AF32: -0.011740144 | AG32: 0 | AH32: -0.0020925223 | AI32: -0.0069635928
B33: 149955 | C33: (CARTERA DE CRÉDITO EDUCATIVO) | D33: -6.739335e-06 | E33: -0.00029445015 | F33: -3.5964875e-05 | G33: -3.065951e-06 | H33: -7.5168761e-05 | I33: 0 | J33: -1.0133378e-05 | K33: 0 | L33: 0 | M33: 0 | N33: 0 | O33: -4.474281e-06 | P33: -1.0662958e-05 | Q33: 0 | R33: -3.336725e-06 | S33: -2.170597e-06 | T33: 0 | U33: 0 | V33: 0 | W33: 0 | X33: 0 | Y33: 0 | Z33: 0 | AA33: 0 | AB33: 0 | AC33: -6.73701e-07 | AD33: -5.0338561e-05 | AE33: 0 | AF33: 0 | AG33: 0 | AH33: 0 | AI33: -5.9577607e-05
B34: 149960 | C34: (CARTERA DE CRÉDITO DE INVERSIÓN PÚBLICA) | D34: 0 | E34: 0 | F34: 0 | G34: 0 | H34: 0 | I34: 0 | J34: 0 | K34: 0 | L34: 0 | M34: 0 | N34: 0 | O34: 0 | P34: 0 | Q34: 0 | R34: 0 | S34: 0 | T34: 0 | U34: 0 | V34: 0 | W34: 0 | X34: 0 | Y34: 0 | Z34: 0 | AA34: 0 | AB34: 0 | AC34: 0 | AD34: 0 | AE34: 0 | AF34: 0 | AG34: 0 | AH34: 0 | AI34: 0
B35: 149980 | C35: PROVISIÓN GÉNERICA POR TECNOLOGÍA CREDITICIA | D35: 0 | E35: 0 | F35: 0 | G35: 0 | H35: 0 | I35: 0 | J35: 0 | K35: 0 | L35: 0 | M35: 0 | N35: 0 | O35: 0 | P35: 0 | Q35: 0 | R35: 0 | S35: 0 | T35: 0 | U35: 0 | V35: 0 | W35: 0 | X35: 0 | Y35: 0 | Z35: 0 | AA35: 0 | AB35: 0 | AC35: 0 | AD35: 0 | AE35: 0 | AF35: 0 | AG35: 0 | AH35: 0 | AI35: 0
B36: 149985 | C36: PROVISIÓN ANTICÍCLICA | D36: -0.00012687447 | E36: -0.00086486946 | F36: -0.0016530756 | G36: -0.0004440568 | H36: -0.00098373747 | I36: 0 | J36: -0.00037838663 | K36: 0 | L36: 0 | M36: -0.00072481073 | N36: 0 | O36: 0 | P36: -0.00024410589 | Q36: 0 | R36: -0.00015143836 | S36: 0 | T36: -9.0485744e-05 | U36: 0 | V36: -0.00060802229 | W36: 0 | X36: -0.00038603255 | Y36: -0.0025368083 | Z36: 0 | AA36: 0 | AB36: 0 | AC36: -8.3775844e-05 | AD36: -0.00069493753 | AE36: 0 | AF36: -0.00021797684 | AG36: 0 | AH36: 0 | AI36: -0.00080652037
... B44: 1 | C44: TOTAL ACTIVO | D44: 1 | E44: 1 | F44: 1 | G44: 1 | H44: 1 | I44: 1 | J44: 1 | K44: 1 | L44: 1 | M44: 1 | N44: 1 | O44: 1 | P44: 1 | Q44: 1 | R44: 1 | S44: 1 | T44: 1 | U44: 1 | V44: 1 | W44: 1 | X44: 1 | Y44: 1 | Z44: 1 | AA44: 1 | AB44: 1 | AC44: 1 | AD44: 1 | AE44: 1 | AF44: 1 | AG44: 0 | AH44: 1 | AI44: 1
C47: PASIVOS
B48: 21 | C48: OBLIGACIONES CON EL PÚBLICO | D48: 0.87511352 | E48: 0.89543017 | F48: 0.91339034 | G48: 0.86319362 | H48: 0.89318966 | I48: 0.92625558 | J48: 0.8470722 | K48: 0.93597795 | L48: 0.67672622 | M48: 0.90734644 | N48: 0.9040162 | O48: 0.90426383 | P48: 0.8888429 | Q48: 0.55621834 | R48: 0.85413314 | S48: 0.94073685 | T48: 0.921451 | U48: 0.96346712 | V48: 0.9431205 | W48: 0.97733854 | X48: 0.90526812 | Y48: 0.82577446 | Z48: 0.8757552 | AA48: 0.86530808 | AB48: 0.44658811 | AC48: 0.8911487 | AD48: 0.88093351 | AE48: 0.90759673 | AF48: 0.75119202 | AG48: 0 | AH48: 0.63817134 | AI48: 0.88805426
B49: 2101 | C49: Depósitos a la vista | D49: 0.47562687 | E49: 0.4005692 | F49: 0.61135167 | G49: 0.48866389 | H49: 0.52146128 | I49: 0.46379628 | J49: 0.45087773 | K49: 0.935856 | L49: 0.068591656 | M49: 0.34921073 | N49: 0.49139178 | O49: 0.49413113 | P49: 0.46024032 | Q49: 0.14489289 | R49: 0.41796985 | S49: 0.54181652 | T49: 0.32701107 | U49: 0.39530552 | V49: 0.53291781 | W49: 0.53884448 | X49: 0.064092995 | Y49: 0.33890401 | Z49: 0.22924964 | AA49: 0.43579039 | AB49: 0.10445454 | AC49: 0.4123883 | AD49: 0.48591495 | AE49: 0.54118314 | AF49: 0.16029298 | AG49: 0 | AH49: 0.16016396 | AI49: 0.50379803
B50: 2102 | C50: Operaciones de reporto | D50: 0 | E50: 0 | F50: 0 | G50: 0 | H50: 0 | I50: 0 | J50: 0 | K50: 0 | L50: 0 | M50: 0 | N50: 0 | O50: 0 | P50: 0 | Q50: 0 | R50: 0 | S50: 0 | T50: 0 | U50: 0 | V50: 0 | W50: 0 | X50: 0 | Y50: 0 | Z50: 0 | AA50: 0 | AB50: 0 | AC50: 0 | AD50: 0 | AE50: 0 | AF50: 0 | AG50: 0 | AH50: 0 | AI50: 0
B51: 2103 | C51: Depósitos a plazo | D51: 0.37393511 | E51: 0.43896749 | F51: 0.27144857 | G51: 0.34916152 | H51: 0.33818533 | I51: 0.43977009 | J51: 0.36068515 | K51: 8.612739e-06 | L51: 0.60393633 | M51: 0.5581254 | N51: 0.38208292 | O51: 0.41012833 | P51: 0.39921478 | Q51: 0.40278774 | R51: 0.41354422 | S51: 0.38113124 | T51: 0.56649162 | U51: 0.48117944 | V51: 0.40872698 | W51: 0.42901527 | X51: 0.83994988 | Y51: 0.45680032 | Z51: 0.64650556 | AA51: 0.42204783 | AB51: 0.34176396 | AC51: 0.46012687 | AD51: 0.36532817 | AE51: 0.33928083 | AF51: 0.58803659 | AG51: 0 | AH51: 0.47780277 | AI51: 0.35232979
B52: 2104 | C52: Depósitos de garantía | D52: 0 | E52: 0 | F52: 1.6930162e-05 | G52: 0 | H52: 7.229442e-06 | I52: 0.00011936405 | J52: 5.0282844e-05 | K52: 0 | L52: 0 | M52: 0 | N52: 1.2363164e-05 | O52: 0 | P52: 0 | Q52: 0 | R52: 3.3312809e-05 | S52: 0 | T52: 1.1095909e-05 | U52: 2.490629e-06 | V52: 3.2105111e-05 | W52: 0 | X52: 0 | Y52: 0 | Z52: 0 | AA52: 0 | AB52: 0 | AC52: 2.687589e-06 | AD52: 1.5239665e-05 | AE52: 1.0978174e-05 | AF52: 2.49923e-07 | AG52: 0 | AH52: 0 | AI52: 1.6782974e-05
...

Sheet EPyG %
B3: ESTADO DE PÉRDIDAS Y GANANCIAS
B4: SISTEMA DE BANCOS PRIVADOS
B5: 31/12/2025
B6: (en porcentajes)
B8: CÓDIGO | C8: CUENTA | D8: BP GUAYAQUIL | E8: BP PACIFICO | F8: BP PICHINCHA | G8: BP PRODUBANCO | H8: BANCOS PRIVADOS GRANDES | I8: BP AUSTRO | J8: BP BOLIVARIANO | K8: BP CITIBANK | L8: BP DINERS | M8: BP GENERAL RUMIÑAHUI | N8: BP INTERNACIONAL | O8: BP LOJA | P8: BP MACHALA | Q8: BP SOLIDARIO | R8: BANCOS PRIVADOS MEDIANOS | S8: BP PROCREDIT | T8: BP AMAZONAS | U8: BP BANCO COMERCIAL DE MANABI | V8: BP LITORAL | W8: BP COOPNACIONAL | X8: BP CAPITAL | Y8: BP DELBANK | Z8: BANCO ATLÁNTIDA S.A. | AA8: BP BANCO DESARROLLO DE LOS PUEBLOS S.A., CODESARROLLO | AB8: BP VISIONFUND ECUADOR S.A. | AC8: BANCOS PRIVADOS PEQUEÑOS | AD8: TOTAL BANCOS PRIVADOS | AE8: BANCOS PRIVADOS COMERCIALES | AF8: BANCOS PRIVADOS CONSUMO | AG8: BANCOS PRIVADOS VIVIENDA | AH8: BANCOS PRIVADOS MICROCRÉDITO | AI8: BANCA MÚLTIPLE
C9: TOTAL INGRESOS | D9: 1 | E9: 1 | F9: 1 | G9: 1 | H9: 1 | I9: 1 | J9: 1 | K9: 1 | L9: 1 | M9: 1 | N9: 1 | O9: 1 | P9: 1 | Q9: 1 | R9: 1 | S9: 1 | T9: 1 | U9: 1 | V9: 1 | W9: 1 | X9: 1 | Y9: 1 | Z9: 1 | AA9: 1 | AB9: 1 | AC9: 1 | AD9: 1 | AE9: 1 | AF9: 1 | AG9: 0 | AH9: 1 | AI9: 1
B11: 51 | C11: INTERESES Y DESCUENTOS GANADOS | D11: 0.71070359 | E11: 0.64479734 | F11: 0.7026344 | G11: 0.7075919 | H11: 0.69366585 | I11: 0.74424268 | J11: 0.75971287 | K11: 0.62855335 | L11: 0.47721557 | M11: 0.79181087 | N11: 0.79731198 | O11: 0.87527814 | P11: 0.87766616 | Q11: 0.7462736 | R11: 0.70803644 | S11: 0.932897 | T11: 0.72968831 | U11: 0.78428963 | V11: 0.85292343 | W11: 0.88076798 | X11: 0.56970648 | Y11: 0.59674695 | Z11: 0.58331579 | AA11: 0.80972902 | AB11: 0.86679468 | AC11: 0.80660155 | AD11: 0.70125271 | AE11: 0.77798041 | AF11: 0.54729811 | AG11: 0 | AH11: 0.76498803 | AI11: 0.71094633
B12: 5101 | C12: Depósitos | D12: 0.0019188715 | E12: 0.0013744504 | F12: 0.011537341 | G12: 0.011899366 | H12: 0.0077314022 | I12: 0.016009059 | J12: 0.0098758106 | K12: 0.034767379 | L12: 0.0008703098 | M12: 0.025434954 | N12: 0.013473075 | O12: 0.019372646 | P12: 0.029319986 | Q12: 0.0011834937 | R12: 0.011690498 | S12: 0.0095463784 | T12: 0.01639612 | U12: 0.012743609 | V12: 3.55318e-05 | W12: 0.16962599 | X12: 0.0007034072 | Y12: 0.0078838887 | Z12: 0.012861825 | AA12: 0.0036227633 | AB12: 0.003537664 | AC12: 0.017298417 | AD12: 0.0091955487 | AE12: 0.015912371 | AF12: 0.0061327001 | AG12: 0 | AH12: 0.0068862786 | AI12: 0.009001151
B13: 5102 | C13: Operaciones interbancarias | D13: 0 | E13: 0 | F13: 5.4617e-06 | G13: 2.1603e-06 | H13: 2.8028e-06 | I13: 0 | J13: 1.21731e-05 | K13: 6.45386e-05 | L13: 0 | M13: 0 | N13: 3.44984e-05 | O13: 0 | P13: 0 | Q13: 0 | R13: 1.09504e-05 | S13: 0 | T13: 0 | U13: 0 | V13: 0 | W13: 0 | X13: 0 | Y13: 0 | Z13: 0 | AA13: 0 | AB13: 0 | AC13: 0 | AD13: 5.1625e-06 | AE13: 3.79396e-05 | AF13: 0 | AG13: 0 | AH13: 0 | AI13: 3.138e-06
B14: 5103 | C14: INTERESES y descuentos de inversiones en títulos valores | D14: 0.07937498 | E14: 0.049701191 | F14: 0.049940411 | G14: 0.031057836 | H14: 0.052618889 | I14: 0.061771521 | J14: 0.038893267 | K14: 0.19151386 | L14: 0.01880029 | M14: 0.034481336 | N14: 0.051713743 | O14: 0.040818503 | P14: 0.061902647 | Q14: 0.019515894 | R14: 0.043396698 | S14: 0.062901405 | T14: 0.061563918 | U14: 0.15331141 | V14: 0.029717672 | W14: 0.49005431 | X14: 0.028142781 | Y14: 0.033329734 | Z14: 0.19104599 | AA14: 0.046332098 | AB14: 0.0022197694 | AC14: 0.085855983 | AD14: 0.050821526 | AE14: 0.067728068 | AF14: 0.022239234 | AG14: 0 | AH14: 0.070033511 | AI14: 0.052357146
B15: 5104 | C15: INTERESES Y DESCUENTOS DE CARTERA DE CRÉDITOS | D15: 0.62940974 | E15: 0.59369312 | F15: 0.64059175 | G15: 0.66350891 | H15: 0.63287642 | I15: 0.66439584 | J15: 0.70997278 | K15: 0.37541881 | L15: 0.45554231 | M15: 0.73189458 | N15: 0.73149694 | O15: 0.81508699 | P15: 0.78644352 | Q15: 0.72557421 | R15: 0.65120587 | S15: 0.86044921 | T15: 0.61800928 | U15: 0.61518854 | V15: 0.82317022 | W15: 0.22108769 | X15: 0.52646323 | Y15: 0.55553333 | Z15: 0.37940798 | AA15: 0.75977416 | AB15: 0.86103724 | AC15: 0.69646764 | AD15: 0.6402157 | AE15: 0.69070763 | AF15: 0.51736694 | AG15: 0 | AH15: 0.68806824 | AI15: 0.64882546
B16: 5190 | C16: Otros INTERESES y descuentos | D16: 0 | E16: 2.85792e-05 | F16: 0.0005594385 | G16: 0.0011236266 | H16: 0.0004363408 | I16: 0.0020662661 | J16: 0.00095884 | K16: 0.026788759 | L16: 0.0020026603 | M16: 0 | N16: 0.0005937237 | O16: 0 | P16: 0 | Q16: 0 | R16: 0.0017324296 | S16: 0 | T16: 0.033718989 | U16: 0.0030460797 | V16: 0 | W16: 0 | X16: 0.014397064 | Y16: 0 | Z16: 0 | AA16: 0 | AB16: 0 | AC16: 0.0069795029 | AD16: 0.0010147694 | AE16: 0.0035944065 | AF16: 0.001559233 | AG16: 0 | AH16: 0 | AI16: 0.000759428
