Workbook

Sheet BALANCE
B2: ESTADO DE SITUACIÓN
B3: SISTEMA DE BANCOS PRIVADOS
B4: 31/05/2022
B5: (en miles de dólares)
B8: CÓDIGO | C8: CUENTA | D8: BP GUAYAQUIL | E8: BP PACIFICO | F8: BP PICHINCHA | G8: BP PRODUBANCO | H8: BANCOS PRIVADOS GRANDES | I8: BP AUSTRO | J8: BP BOLIVARIANO | K8: BP CITIBANK | L8: BP DINERS | M8: BP GENERAL RUMIÑAHUI | N8: BP INTERNACIONAL | O8: BP LOJA | P8: BP MACHALA | Q8: BP SOLIDARIO | R8: BANCOS PRIVADOS MEDIANOS | S8: BP PROCREDIT | T8: BP AMAZONAS | U8: BP COMERCIAL DE MANABI | V8: BP LITORAL | W8: BP COOPNACIONAL | X8: BP CAPITAL | Y8: BP FINCA S.A. | Z8: BP DELBANK | AA8: BP D-MIRO S.A. | AB8: BP BANCO DESARROLLO DE LOS PUEBLOS S.A., CODESARROLLO | AC8: BP VISIONFUND ECUADOR S.A. | AD8: BANCOS PRIVADOS PEQUEÑOS | AE8: TOTAL BANCOS PRIVADOS | AF8: BANCOS PRIVADOS COMERCIALES | AG8: BANCOS PRIVADOS CONSUMO | AH8: BANCOS PRIVADOS VIVIENDA | AI8: BANCOS PRIVADOS MICROCRÉDITO | AJ8: BANCA MÚLTIPLE
C9: ACTIVO
B10: 11 | C10: FONDOS DISPONIBLES | D10: 792200.41 | E10: 1236038.6 | F10: 1488170.3 | G10: 987314.77 | H10: 4503724 | I10: 366159.71 | J10: 768019.82 | K10: 204523.83 | L10: 121830.17 | M10: 168221.88 | N10: 548137.48 | O10: 141836.42 | P10: 163203.33 | Q10: 74083.198 | R10: 2556015.8 | S10: 58397.463 | T10: 30121.58 | U10: 7352.3701 | V10: 2360.7643 | W10: 64574.45 | X10: 2383.9728 | Y10: 11518.839 | Z10: 7097.2385 | AA10: 6089.1321 | AB10: 23600.842 | AC10: 3852.1231 | AD10: 217348.78 | AE10: 7277088.6 | AF10: 752661.31 | AG10: 292412.82 | AH10: 0 | AI10: 21460.095 | AJ10: 6210554.4
B11: 1101 | C11: Caja | D11: 210661.69 | E11: 276141.01 | F11: 292245.18 | G11: 112243.17 | H11: 891291.06 | I11: 71529.333 | J11: 165693.42 | K11: 302.857 | L11: 3.8 | M11: 13935.736 | N11: 90253.213 | O11: 25103.707 | P11: 28236.973 | Q11: 20341.038 | R11: 415400.08 | S11: 3519.8899 | T11: 3407.5709 | U11: 2951.1471 | V11: 666.48793 | W11: 8024.9419 | X11: 245.00216 | Y11: 720.7087 | Z11: 2364.3583 | AA11: 1674.8937 | AB11: 5241.8854 | AC11: 883.69505 | AD11: 29700.581 | AE11: 1336391.7 | AF11: 90556.07 | AG11: 14606.024 | AH11: 0 | AI11: 3279.2975 | AJ11: 1227950.3
B12: 110105 | C12: Efectivo | D12: 210661.69 | E12: 276141.01 | F12: 292214.08 | G12: 112243.17 | H12: 891259.96 | I12: 71527.233 | J12: 165692.82 | K12: 302.857 | L12: 0 | M12: 13934.986 | N12: 90243.243 | O12: 25100.987 | P12: 28236.773 | Q12: 20323.339 | R12: 415362.24 | S12: 3519.8899 | T12: 3407.1709 | U12: 2951.0471 | V12: 665.33793 | W12: 8009.9419 | X12: 244.30216 | Y12: 717.4087 | Z12: 2363.9583 | AA12: 1674.8937 | AB12: 5237.0854 | AC12: 871.49505 | AD12: 29662.531 | AE12: 1336284.7 | AF12: 90546.1 | AG12: 14600.324 | AH12: 0 | AI12: 3263.7975 | AJ12: 1227874.5
B13: 110110 | C13: Caja chica | D13: 0 | E13: 0 | F13: 31.1 | G13: 0 | H13: 31.1 | I13: 2.1 | J13: 0.6008 | K13: 0 | L13: 3.8 | M13: 0.75 | N13: 9.97 | O13: 2.72 | P13: 0.2 | Q13: 17.7 | R13: 37.8408 | S13: 0 | T13: 0.4 | U13: 0.1 | V13: 1.15 | W13: 15 | X13: 0.7 | Y13: 3.3 | Z13: 0.4 | AA13: 0 | AB13: 4.8 | AC13: 12.2 | AD13: 38.05 | AE13: 106.9908 | AF13: 9.97 | AG13: 5.7 | AH13: 0 | AI13: 15.5 | AJ13: 75.8208
B14: 1102 | C14: Depósitos para encaje | D14: 463515.35 | E14: 850193.68 | F14: 884528.46 | G14: 422073.52 | H14: 2620311 | I14: 135017.58 | J14: 233606.11 | K14: 134019.93 | L14: 45469.204 | M14: 29555.078 | N14: 195533.19 | O14: 77029.028 | P14: 61081.296 | Q14: 21370.708 | R14: 932682.12 | S14: 29411.383 | T14: 4859.5429 | U14: 3575.087 | V14: 1211.7347 | W14: 6119.6277 | X14: 1689.646 | Y14: 9036.5716 | Z14: 1001.0707 | AA14: 2082.1987 | AB14: 8165.4723 | AC14: 860.15499 | AD14: 68012.489 | AE14: 3621005.6 | AF14: 329553.11 | AG14: 76236.016 | AH14: 0 | AI14: 11978.925 | AJ14: 3203237.6
B15: 110205 | C15: Banco Central del Ecuador | D15: 463515.16 | E15: 850193.68 | F15: 884528.46 | G15: 422073.52 | H15: 2620310.8 | I15: 134978.42 | J15: 233606.11 | K15: 134019.93 | L15: 45469.204 | M15: 29555.078 | N15: 195533.19 | O15: 76977.351 | P15: 61081.296 | Q15: 21370.708 | R15: 932591.28 | S15: 29411.383 | T15: 4859.5429 | U15: 3575.087 | V15: 1211.7347 | W15: 6119.6277 | X15: 1689.646 | Y15: 9036.5716 | Z15: 1001.0707 | AA15: 2082.1987 | AB15: 8165.4723 | AC15: 860.15499 | AD15: 68012.489 | AE15: 3620914.6 | AF15: 329553.11 | AG15: 76236.016 | AH15: 0 | AI15: 11978.925 | AJ15: 3203146.5
B16: 110210 | C16: Banco Nacional de Fomento | D16: 0 | E16: 0 | F16: 0 | G16: 0 | H16: 0 | I16: 39.15989 | J16: 0 | K16: 0 | L16: 0 | M16: 0 | N16: 0 | O16: 51.67676 | P16: 0 | Q16: 0 | R16: 90.83665 | S16: 0 | T16: 0 | U16: 0 | V16: 0 | W16: 0 | X16: 0 | Y16: 0 | Z16: 0 | AA16: 0 | AB16: 0 | AC16: 0 | AD16: 0 | AE16: 90.83665 | AF16: 0 | AG16: 0 | AH16: 0 | AI16: 0 | AJ16: 90.83665
B17: 110215 | C17: Bancos locales | D17: 0.18952 | E17: 0 | F17: 0 | G17: 0 | H17: 0.18952 | I17: 0 | J17: 0 | K17: 0 | L17: 0 | M17: 0 | N17: 0 | O17: 0 | P17: 0 | Q17: 0 | R17: 0 | S17: 0 | T17: 0 | U17: 0 | V17: 0 | W17: 0 | X17: 0 | Y17: 0 | Z17: 0 | AA17: 0 | AB17: 0 | AC17: 0 | AD17: 0 | AE17: 0.18952 | AF17: 0 | AG17: 0 | AH17: 0 | AI17: 0 | AJ17: 0.18952
B18: 1103 | C18: Bancos y otras instituciones financieras | D18: 75499.074 | E18: 46085.319 | F18: 176029.6 | G18: 386545.32 | H18: 684159.31 | I18: 153632.49 | J18: 317806.54 | K18: 68087.035 | L18: 76357.169 | M18: 88238.284 | N18: 237649.25 | O18: 37053.445 | P18: 67291.111 | Q18: 32031.893 | R18: 1078147.2 | S18: 24336.873 | T18: 21578.436 | U18: 552.36562 | V18: 261.69236 | W18: 50344.235 | X18: 438.28388 | Y18: 1740.3002 | Z18: 3695.934 | AA18: 2217.2749 | AB18: 9918.0731 | AC18: 2108.2731 | AD18: 117191.74 | AE18: 1879498.3 | AF18: 305736.29 | AG18: 164857.15 | AH18: 0 | AI18: 6065.8482 | AJ18: 1402839
B19: 110305 | C19: Banco Central del Ecuador | D19: 0 | E19: 0 | F19: 0 | G19: 0 | H19: 0 | I19: 0 | J19: 0 | K19: 0 | L19: 0 | M19: 0 | N19: 0 | O19: 0 | P19: 0 | Q19: 0 | R19: 0 | S19: 0 | T19: 0 | U19: 0 | V19: 0 | W19: 0 | X19: 0 | Y19: 0.123 | Z19: 0 | AA19: 0 | AB19: 0 | AC19: 0 | AD19: 0.123 | AE19: 0.123 | AF19: 0 | AG19: 0 | AH19: 0 | AI19: 0.123 | AJ19: 0
B20: 110310 | C20: Bancos e instituciones financieras locales | D20: 45792.245 | E20: 2819.3998 | F20: 6309.2033 | G20: 284416.96 | H20: 339337.81 | I20: 133429.13 | J20: 165824.45 | K20: 25196.162 | L20: 67808.648 | M20: 67299.589 | N20: 91258.037 | O20: 20475.04 | P20: 51853.547 | Q20: 11006.177 | R20: 634150.77 | S20: 18883.319 | T20: 19999.559 | U20: 137.31506 | V20: 261.69236 | W20: 50344.235 | X20: 424.32019 | Y20: 719.64398 | Z20: 3361.6144 | AA20: 2217.2749 | AB20: 8493.4436 | AC20: 2108.2731 | AD20: 106950.69 | AE20: 1080439.3 | AF20: 116454.2 | AG20: 135369.93 | AH20: 0 | AI20: 5045.192 | AJ20: 823569.95
B21: 110315 | C21: Bancos e instituciones financieras del exterior | D21: 29706.829 | E21: 43265.919 | F21: 169720.39 | G21: 102128.36 | H21: 344821.5 | I21: 20203.357 | J21: 151982.09 | K21: 42890.873 | L21: 8548.5209 | M21: 20938.696 | N21: 146391.21 | O21: 16578.405 | P21: 15437.564 | Q21: 21025.716 | R21: 443996.44 | S21: 5453.5532 | T21: 1578.877 | U21: 415.05056 | V21: 0 | W21: 0 | X21: 13.96369 | Y21: 0 | Z21: 334.31962 | AA21: 0 | AB21: 1424.6294 | AC21: 0 | AD21: 9220.3936 | AE21: 798038.33 | AF21: 189282.09 | AG21: 29487.217 | AH21: 0 | AI21: 0 | AJ21: 579269.03
... B750: +1+4 | C750: TOTAL ACTIVO Y GASTOS | D750: 6720401.7 | E750: 7166919.2 | F750: 14459710 | G750: 6494865.8 | H750: 34841897 | I750: 2528857.7 | J750: 4508834.7 | K750: 649992.59 | L750: 2434861.2 | M750: 1056537.3 | N750: 4409829.8 | O750: 711134.47 | P750: 1003220 | Q750: 890489.84 | R750: 18193758 | S750: 619091.76 | T750: 302659.7 | U750: 63659.166 | V750: 42292.298 | W750: 208925.49 | X750: 42059.295 | Y750: 91765.34 | Z750: 34248.497 | AA750: 117124.11 | AB750: 254743.28 | AC750: 105520.36 | AD750: 1882089.3 | AE750: 54917743 | AF750: 5059822.4 | AG750: 3533690.7 | AH750: 0 | AI750: 314409.81 | AJ750: 46009820
C752: PASIVOS
B753: 21 | C753: OBLIGACIONES CON EL PÚBLICO | D753: 5098291.4 | E753: 5282140.4 | F753: 11260193 | G753: 4851768.7 | H753: 26492394 | I753: 2043022.2 | J753: 3498858.9 | K753: 506984.53 | L753: 1091780.9 | M753: 850333.16 | N753: 3577829.7 | O753: 569346.89 | P753: 830901.15 | Q753: 398910.15 | R753: 13367967 | S753: 345261.97 | T753: 243751.96 | U753: 46134.849 | V753: 27574.166 | W753: 168108.17 | X753: 30666.169 | Y753: 64693.752 | Z753: 18033.29 | AA753: 45329.211 | AB753: 178481.48 | AC753: 19702.17 | AD753: 1187737.2 | AE753: 41048098 | AF753: 4084814.2 | AG753: 1969688.2 | AH753: 0 | AI753: 129725.13 | AJ753: 34863871
B754: 2101 | C754: Depósitos a la vista | D754: 3091403.9 | E754: 2690974.5 | F754: 7653545.9 | G754: 2991157.7 | H754: 16427082 | I754: 1041303.6 | J754: 2251664.5 | K754: 506378.72 | L754: 15940.699 | M754: 383238.38 | N754: 2129772.6 | O754: 314083.2 | P754: 438619.01 | Q754: 81383.456 | R754: 7162384.1 | S754: 204989.79 | T754: 88498.148 | U754: 34342.513 | V754: 9971.3719 | W754: 118078.25 | X754: 3390.7132 | Y754: 6094.0138 | Z754: 9576.378 | AA754: 6153.6148 | AB754: 66437.076 | AC754: 6076.2931 | AD754: 553608.16 | AE754: 24143074 | AF754: 2636151.3 | AG754: 409150.45 | AH754: 0 | AI754: 18323.922 | AJ754: 21079449
B755: 210105 | C755: Depósitos monetarios que generan INTERESES | D755: 691912.26 | E755: 531285.49 | F755: 451679.73 | G755: 6040.5508 | H755: 1680918 | I755: 61202.732 | J755: 395908.36 | K755: 47152.536 | L755: 0 | M755: 47164.446 | N755: 1077389.9 | O755: 0 | P755: 0 | Q755: 9535.8907 | R755: 1638353.8 | S755: 58995.71 | T755: 691.70534 | U755: 4012.6628 | V755: 0 | W755: 0 | X755: 1584.5034 | Y755: 0 | Z755: 0 | AA755: 0 | AB755: 3551.7512 | AC755: 0 | AD755: 68836.333 | AE755: 3388108.2 | AF755: 1124542.4 | AG755: 47164.446 | AH755: 0 | AI755: 0 | AJ755: 2216401.3
B756: 210110 | C756: Depósitos monetarios que no generan INTERESES | D756: 925675.76 | E756: 882951.78 | F756: 2787864.2 | G756: 1564825.8 | H756: 6161317.5 | I756: 182572.73 | J756: 786227.92 | K756: 454130.7 | L756: 0 | M756: 40911.363 | N756: 179151.17 | O756: 73883.775 | P756: 146809.34 | Q756: 32.90972 | R756: 1863719.9 | S756: 0 | T756: 22115.828 | U756: 8662.6735 | V756: 3668.7931 | W756: 246.77431 | X756: 36.78497 | Y756: 0 | Z756: 2813.5583 | AA756: 0 | AB756: 0 | AC756: 0 | AD756: 37544.412 | AE756: 8062581.8 | AF756: 633281.87 | AG756: 44580.156 | AH756: 0 | AI756: 0 | AJ756: 7384719.8
B757: 210115 | C757: Depósitos monetarios de instituciones financieras | D757: 151385.35 | E757: 7614.7 | F757: 141271.27 | G757: 82116.089 | H757: 382387.41 | I757: 86485.354 | J757: 226649.46 | K757: 581.339 | L757: 0 | M757: 5227.5146 | N757: 134015.23 | O757: 3885.7995 | P757: 14563.529 | Q757: 5.75253 | R757: 471413.98 | S757: 5256.6248 | T757: 773.94065 | U757: 54.59913 | V757: 0 | W757: 0 | X757: 0 | Y757: 0 | Z757: 0 | AA757: 0 | AB757: 1898.3533 | AC757: 0 | AD757: 7983.5179 | AE757: 861784.9 | AF757: 134596.57 | AG757: 5227.5146 | AH757: 0 | AI757: 0 | AJ757: 721960.82
B758: 210120 | C758: EJECUCIÓN PRESUPUESTARIA | D758: 2082.0787 | E758: 5e-05 | F758: 0 | G758: 0 | H758: 2082.0787 | I758: 0 | J758: 12419.09 | K758: 0 | L758: 0 | M758: 0 | N758: 0 | O758: 366.52952 | P758: 621.44252 | Q758: 0 | R758: 13407.062 | S758: 0 | T758: 0 | U758: 0 | V758: 0 | W758: 0 | X758: 0 | Y758: 0 | Z758: 0 | AA758: 0 | AB758: 0 | AC758: 0 | AD758: 0 | AE758: 15489.141 | AF758: 0 | AG758: 0 | AH758: 0 | AI758: 0 | AJ758: 15489.141
B759: 210125 | C759: Depósitos de otras instituciones para encaje | D759: 0 | E759: 0 | F759: 0 | G759: 0 | H759: 0 | I759: 0 | J759: 0 | K759: 0 | L759: 0 | M759: 0 | N759: 0 | O759: 0 | P759: 0 | Q759: 0 | R759: 0 | S759: 0 | T759: 0 | U759: 0 | V759: 0 | W759: 0 | X759: 0 | Y759: 0 | Z759: 0 | AA759: 0 | AB759: 0 | AC759: 0 | AD759: 0 | AE759: 0 | AF759: 0 | AG759: 0 | AH759: 0 | AI759: 0 | AJ759: 0
B760: 210130 | C760: Cheques certificados | D760: 6526.5809 | E760: 9775.8722 | F760: 24154.877 | G760: 9711.5572 | H760: 50168.887 | I760: 2281.6839 | J760: 9360.0254 | K760: 2392.176 | L760: 0 | M760: 410.83918 | N760: 3946.1938 | O760: 317.48773 | P760: 1148.5665 | Q760: 6.17596 | R760: 19863.148 | S760: 99.50313 | T760: 112.74102 | U760: 37.33546 | V760: 170.75842 | W760: 34.60033 | X760: 39.8566 | Y760: 0 | Z760: 27.00323 | AA760: 0 | AB760: 6.74928 | AC760: 0 | AD760: 528.54747 | AE760: 70560.583 | AF760: 6338.3698 | AG760: 581.5976 | AH760: 0 | AI760: 0 | AJ760: 63640.616
B761: 210131 | C761: Cheques de emergencia | D761: 4079.5133 | E761: 0 | F761: 10521.58 | G761: 6642.9914 | H761: 21244.084 | I761: 1445.4536 | J761: 25657.924 | K761: 0 | L761: 0 | M761: 1192.5425 | N761: 2734.6426 | O761: 342.8401 | P761: 498.10961 | Q761: 501.15331 | R761: 32372.666 | S761: 39.10098 | T761: 0 | U761: 0 | V761: 416.97039 | W761: 120.03669 | X761: 0 | Y761: 0 | Z761: 42.14342 | AA761: 0 | AB761: 0 | AC761: 0 | AD761: 618.25148 | AE761: 54235.002 | AF761: 2734.6426 | AG761: 1609.5129 | AH761: 0 | AI761: 0 | AJ761: 49890.846
B762: 210135 | C762: Depósitos de ahorro | D762: 1246548.1 | E762: 1159518 | F762: 4140122.1 | G762: 1264794.6 | H762: 7810982.7 | I762: 698871.21 | J762: 739362.51 | K762: 0 | L762: 1487.0937 | M762: 285498.53 | N762: 704138.17 | O762: 232189.95 | P762: 270580.27 | Q762: 68902.635 | R762: 3001030.4 | S762: 139469.29 | T762: 60993.983 | U762: 21309.771 | V762: 5521.0313 | W762: 117604.13 | X762: 1651.1049 | Y762: 5778.6044 | Z762: 6475.3913 | AA762: 6153.6148 | AB762: 60872.492 | AC762: 6049.2068 | AD762: 431878.62 | AE762: 11243892 | AF762: 704138.17 | AG762: 292506.66 | AH762: 0 | AI762: 17981.426 | AJ762: 10229265
B763: 210140 | C763: Otros depósitos | D763: 2146.41 | E763: 73159.936 | F763: 14650.761 | G763: 18265.704 | H763: 108222.81 | I763: 83.49137 | J763: 20640.937 | K763: 0 | L763: 6094.9157 | M763: 1103.2338 | N763: 2425.7368 | O763: 1338.051 | P763: 190.03601 | Q763: 1732.3078 | R763: 33608.71 | S763: 0 | T763: 3422.4918 | U763: 2.71882 | V763: 56.18045 | W763: 0 | X763: 78.46336 | Y763: 294.15057 | Z763: 195.44974 | AA763: 0 | AB763: 66.98949 | AC763: 27.08626 | AD763: 4143.5305 | AE763: 145975.05 | AF763: 2425.7368 | AG763: 7254.3299 | AH763: 0 | AI763: 321.23683 | AJ763: 135973.75
B764: 210145 | C764: Fondos de tarjetahabientes | D764: 14709.39 | E764: 10707.65 | F764: 5309.3798 | G764: 5585.591 | H764: 36312.011 | I764: 1652.6086 | J764: 1313.7472 | K764: 0 | L764: 8358.6895 | M764: 406.99541 | N764: 1440.1814 | O764: 75.04551 | P764: 189.58823 | Q764: 614.43492 | R764: 14051.291 | S764: 0 | T764: 121.75672 | U764: 0 | V764: 0 | W764: 0 | X764: 0 | Y764: 0 | Z764: 0 | AA764: 0 | AB764: 0 | AC764: 0 | AD764: 121.75672 | AE764: 50485.058 | AF764: 1440.1814 | AG764: 8765.685 | AH764: 0 | AI764: 0 | AJ764: 40279.192
... B950: 2 | C950: TOTAL PASIVOS | D950: 5870316.9 | E950: 6047165.1 | F950: 12461234 | G950: 5761221 | H950: 30139937 | I950: 2200363.1 | J950: 3971910.8 | K950: 552845.32 | L950: 1764778.2 | M950: 916562.72 | N950: 3861409.6 | O950: 616619.95 | P950: 896526.4 | Q950: 665467.91 | R950: 15446484 | S950: 538183.58 | T950: 265984.79 | U950: 47337.254 | V950: 29001.672 | W950: 171819.94 | X950: 33376.217 | Y950: 76158.429 | Z950: 20359.347 | AA950: 88455.75 | AB950: 212512.56 | AC950: 78723.338 | AD950: 1561912.9 | AE950: 47148334 | AF950: 4414255 | AG950: 2710342.6 | AH950: 0 | AI950: 243337.52 | AJ950: 39780398
C952: PATRIMONIO
B953: 31 | C953: CAPITAL SOCIAL | D953: 483370 | E953: 582479.74 | F953: 919241.6 | G953: 394760 | H953: 2379851.3 | I953: 152900 | J953: 325000 | K953: 68559.042 | L953: 300000 | M953: 70334.805 | N953: 333706.68 | O953: 46700 | P953: 56300 | Q953: 93522.016 | R953: 1447022.5 | S953: 51931 | T953: 21083.923 | U953: 11010.6 | V953: 11090.785 | W953: 21738.121 | X953: 11000 | Y953: 18663.2 | Z953: 11356.808 | AA953: 20968.6 | AB953: 20846.8 | AC953: 16701.1 | AD953: 216390.94 | AE953: 4043264.8 | AF953: 402265.72 | AG953: 381425.59 | AH953: 0 | AI953: 56332.9 | AJ953: 3203240.6
B954: 3101 | C954: Capital pagado | D954: 483370 | E954: 582479.74 | F954: 919241.6 | G954: 394760 | H954: 2379851.3 | I954: 152900 | J954: 325000 | K954: 68559.042 | L954: 300000 | M954: 70334.805 | N954: 333706.68 | O954: 46700 | P954: 56300 | Q954: 100997.65 | R954: 1454498.2 | S954: 51931 | T954: 21083.923 | U954: 11010.6 | V954: 11090.785 | W954: 21738.121 | X954: 11000 | Y954: 18663.2 | Z954: 11356.808 | AA954: 20968.6 | AB954: 20846.8 | AC954: 16701.1 | AD954: 216390.94 | AE954: 4050740.5 | AF954: 402265.72 | AG954: 381425.59 | AH954: 0 | AI954: 56332.9 | AJ954: 3210716.2
B955: 3102 | C955: (Acciones en tesorería) | D955: 0 | E955: 0 | F955: 0 | G955: 0 | H955: 0 | I955: 0 | J955: 0 | K955: 0 | L955: 0 | M955: 0 | N955: 0 | O955: 0 | P955: 0 | Q955: -7475.634 | R955: -7475.634 | S955: 0 | T955: 0 | U955: 0 | V955: 0 | W955: 0 | X955: 0 | Y955: 0 | Z955: 0 | AA955: 0 | AB955: 0 | AC955: 0 | AD955: 0 | AE955: -7475.634 | AF955: 0 | AG955: 0 | AH955: 0 | AI955: 0 | AJ955: -7475.634
B956: 3103 | C956: Aportes de socios | D956: 0 | E956: 0 | F956: 0 | G956: 0 | H956: 0 | I956: 0 | J956: 0 | K956: 0 | L956: 0 | M956: 0 | N956: 0 | O956: 0 | P956: 0 | Q956: 0 | R956: 0 | S956: 0 | T956: 0 | U956: 0 | V956: 0 | W956: 0 | X956: 0 | Y956: 0 | Z956: 0 | AA956: 0 | AB956: 0 | AC956: 0 | AD956: 0 | AE956: 0 | AF956: 0 | AG956: 0 | AH956: 0 | AI956: 0 | AJ956: 0
B957: 32 | C957: PRIMA O DESCUENTO EN COLOCACIÓN DE ACCIONES Y CERTIFICADOS | D957: 0 | E957: 0 | F957: 0 | G957: 1104.7742 | H957: 1104.7742 | I957: 0 | J957: 0 | K957: 0 | L957: 0 | M957: 0 | N957: 0 | O957: 0 | P957: 0 | Q957: 1204.77 | R957: 1204.77 | S957: 0 | T957: 0 | U957: 0 | V957: 0 | W957: 0 | X957: 0 | Y957: 0 | Z957: 0 | AA957: 0 | AB957: 0 | AC957: 0 | AD957: 0 | AE957: 2309.5442 | AF957: 0 | AG957: 0 | AH957: 0 | AI957: 0 | AJ957: 2309.5442
B958: 3201 | C958: Prima EN COLOCACIÓN de acciones y certificados de aportación | D958: 0 | E958: 0 | F958: 0 | G958: 1104.7742 | H958: 1104.7742 | I958: 0 | J958: 0 | K958: 0 | L958: 0 | M958: 0 | N958: 0 | O958: 0 | P958: 0 | Q958: 1204.77 | R958: 1204.77 | S958: 0 | T958: 0 | U958: 0 | V958: 0 | W958: 0 | X958: 0 | Y958: 0 | Z958: 0 | AA958: 0 | AB958: 0 | AC958: 0 | AD958: 0 | AE958: 2309.5442 | AF958: 0 | AG958: 0 | AH958: 0 | AI958: 0 | AJ958: 2309.5442
...

Sheet PYG
B3: ESTADO DE PÉRDIDAS Y GANANCIAS
B4: SISTEMA DE BANCOS PRIVADOS
B5: 31/05/2022
B6: (en miles de dólares)
B8: CÓDIGO | C8: CUENTA | D8: BP GUAYAQUIL | E8: BP PACIFICO | F8: BP PICHINCHA | G8: BP PRODUBANCO | H8: BANCOS PRIVADOS GRANDES | I8: BP AUSTRO | J8: BP BOLIVARIANO | K8: BP CITIBANK | L8: BP DINERS | M8: BP GENERAL RUMIÑAHUI | N8: BP INTERNACIONAL | O8: BP LOJA | P8: BP MACHALA | Q8: BP SOLIDARIO | R8: BANCOS PRIVADOS MEDIANOS | S8: BP PROCREDIT | T8: BP AMAZONAS | U8: BP COMERCIAL DE MANABI | V8: BP LITORAL | W8: BP COOPNACIONAL | X8: BP CAPITAL | Y8: BP FINCA S.A. | Z8: BP DELBANK | AA8: BP D-MIRO S.A. | AB8: BP BANCO DESARROLLO DE LOS PUEBLOS S.A., CODESARROLLO | AC8: BP VISIONFUND ECUADOR S.A. | AD8: BANCOS PRIVADOS PEQUEÑOS | AE8: TOTAL BANCOS PRIVADOS | AF8: BANCOS PRIVADOS COMERCIALES | AG8: BANCOS PRIVADOS CONSUMO | AH8: BANCOS PRIVADOS VIVIENDA | AI8: BANCOS PRIVADOS MICROCRÉDITO | AJ8: BANCA MÚLTIPLE
B9: 5 | C9: INGRESOS | D9: 280589.69 | E9: 313909.88 | F9: 693081.01 | G9: 251156.38 | H9: 1538737 | I9: 103852.22 | J9: 141997.92 | K9: 14640.735 | L9: 204880.25 | M9: 50553.748 | N9: 137340.75 | O9: 30215.888 | P9: 34967.509 | Q9: 64978.528 | R9: 783427.55 | S9: 23028.038 | T9: 10146.072 | U9: 2551.0985 | V9: 1937.5385 | W9: 5316.8333 | X9: 1788.6673 | Y9: 6064.1115 | Z9: 2403.6031 | AA9: 8732.324 | AB9: 15393.983 | AC9: 9118.902 | AD9: 86481.172 | AE9: 2408645.7 | AF9: 151981.48 | AG9: 257371.54 | AH9: 0 | AI9: 23915.337 | AJ9: 1975377.3
B11: 51 | C11: INTERESES Y DESCUENTOS GANADOS | D11: 189422.83 | E11: 188353.53 | F11: 495094.73 | G11: 174265.78 | H11: 1047136.9 | I11: 73879.63 | J11: 106657.78 | K11: 8156.053 | L11: 95562.788 | M11: 41279.22 | N11: 105946.53 | O11: 26168.463 | P11: 29467.281 | Q11: 49986.87 | R11: 537104.61 | S11: 19359.314 | T11: 8165.1041 | U11: 2194.2895 | V11: 1744.4078 | W11: 4440.8967 | X11: 1344.9549 | Y11: 4762.6559 | Z11: 751.80424 | AA11: 6800.046 | AB11: 12162.182 | AC11: 7855.6289 | AD11: 69581.284 | AE11: 1653822.8 | AF11: 114102.58 | AG11: 138586.42 | AH11: 0 | AI11: 19418.331 | AJ11: 1381715.4
B12: 5101 | C12: Depósitos | D12: 157.83461 | E12: 17.99605 | F12: 153.9894 | G12: 773.74569 | H12: 1103.5657 | I12: 1446.8079 | J12: 1032.17 | K12: 124.082 | L12: 18.30715 | M12: 371.18347 | N12: 814.64618 | O12: 69.33644 | P12: 264.42677 | Q12: 33.09515 | R12: 4174.0551 | S12: 92.97459 | T12: 84.3205 | U12: 0.08611 | V12: 0.06393 | W12: 758.7828 | X12: 0.9562 | Y12: 0.40026 | Z12: 29.18173 | AA12: 4.56843 | AB12: 42.69692 | AC12: 19.13907 | AD12: 1033.1705 | AE12: 6310.7914 | AF12: 938.72818 | AG12: 389.55455 | AH12: 0 | AI12: 24.10776 | AJ12: 4958.4009
B13: 5102 | C13: Operaciones interbancarias | D13: 0 | E13: 0 | F13: 3.92777 | G13: 40.62495 | H13: 44.55272 | I13: 0 | J13: 12.50004 | K13: 6.417 | L13: 0.16667 | M13: 0 | N13: 0 | O13: 0 | P13: 0 | Q13: 0 | R13: 19.08371 | S13: 0 | T13: 0 | U13: 0 | V13: 0 | W13: 0 | X13: 0 | Y13: 0 | Z13: 0 | AA13: 0 | AB13: 0 | AC13: 0 | AD13: 0 | AE13: 63.63643 | AF13: 6.417 | AG13: 0.16667 | AH13: 0 | AI13: 0 | AJ13: 57.05276
B14: 5103 | C14: INTERESES y descuentos de inversiones en títulos valores | D14: 6965.9511 | E14: 9026.2905 | F14: 29774.536 | G14: 4416.2216 | H14: 50183 | I14: 7808.7106 | J14: 3872.2623 | K14: 2255.166 | L14: 937.25258 | M14: 1039.6202 | N14: 8203.024 | O14: 851.21106 | P14: 2408.4704 | Q14: 635.07073 | R14: 28010.788 | S14: 183.77729 | T14: 1072.1551 | U14: 124.10633 | V14: 55.4918 | W14: 1012.773 | X14: 38.0101 | Y14: 32.35608 | Z14: 81.53124 | AA14: 326.21716 | AB14: 359.07322 | AC14: 19.65691 | AD14: 3305.1482 | AE14: 81498.936 | AF14: 10458.19 | AG14: 2032.3646 | AH14: 0 | AI14: 378.23015 | AJ14: 68630.151
B15: 5104 | C15: INTERESES Y DESCUENTOS DE CARTERA DE CRÉDITOS | D15: 182299.04 | E15: 179296.71 | F15: 464055.01 | G15: 169035.19 | H15: 994685.95 | I15: 64621.977 | J15: 101559.5 | K15: 5750.991 | L15: 94599.849 | M15: 39868.417 | N15: 96928.858 | O15: 25247.915 | P15: 26794.384 | Q15: 49318.705 | R15: 504690.59 | S15: 19082.563 | T15: 7001.854 | U15: 2066.673 | V15: 1688.8521 | W15: 2669.3409 | X15: 1305.9886 | Y15: 4729.8995 | Z15: 641.09127 | AA15: 6469.2604 | AB15: 11760.412 | AC15: 7816.8329 | AD15: 65232.767 | AE15: 1564609.3 | AF15: 102679.85 | AG15: 136157.12 | AH15: 0 | AI15: 19015.993 | AJ15: 1306756.3
B16: 510405 | C16: CARTERA DE CRÉDITOS PRODUCTIVO | D16: 63615.006 | E16: 27985.813 | F16: 103171.15 | G16: 80216.316 | H16: 274988.28 | I16: 23334.552 | J16: 60782.535 | K16: 5653.649 | L16: 686.38203 | M16: 1903.1151 | N16: 67464.388 | O16: 4404.1178 | P16: 14656.796 | Q16: 0 | R16: 178885.53 | S16: 12897.094 | T16: 2422.5485 | U16: 706.84921 | V16: 270.03638 | W16: 1969.9934 | X16: 43.54542 | Y16: 0 | Z16: 277.6009 | AA16: 0 | AB16: 730.77961 | AC16: 0 | AD16: 19318.447 | AE16: 473192.26 | AF16: 73118.037 | AG16: 2859.5335 | AH16: 0 | AI16: 0 | AJ16: 397214.69
B17: 510410 | C17: CARTERA DE CRÉDITOS DE CONSUMO | D17: 85658.113 | E17: 104470 | F17: 183911.9 | G17: 68087.608 | H17: 442127.62 | I17: 30619.841 | J17: 36326.173 | K17: 0 | L17: 88902.298 | M17: 32332.094 | N17: 20420.194 | O17: 10741.283 | P17: 9976.0428 | Q17: 18020.953 | R17: 247338.88 | S17: 186.73662 | T17: 3969.1415 | U17: 572.65684 | V17: 1063.5489 | W17: 50.15229 | X17: 943.65635 | Y17: 255.76204 | Z17: 175.68583 | AA17: 0 | AB17: 3407.8222 | AC17: 2.81714 | AD17: 10627.98 | AE17: 700094.48 | AF17: 20420.194 | AG17: 122297.94 | AH17: 0 | AI17: 258.57918 | AJ17: 557117.76
B18: 510415 | C18: CARTERA DE CRÉDITOS INMOBILIARIO | D18: 7734.176 | E18: 14396.135 | F18: 26036.144 | G18: 10105.097 | H18: 58271.552 | I18: 2381.0797 | J18: 2936.2098 | K18: 0 | L18: 1.19067 | M18: 3469.1737 | N18: 4648.122 | O18: 1554.7755 | P18: 846.95498 | Q18: 0.76157 | R18: 15838.268 | S18: 1046.8981 | T18: 53.31391 | U18: 0.40337 | V18: 1.22424 | W18: 4.84579 | X18: 0 | Y18: 0 | Z18: 68.95093 | AA18: 0 | AB18: 270.0618 | AC18: 0 | AD18: 1445.6981 | AE18: 75555.518 | AF18: 4648.122 | AG18: 3471.5886 | AH18: 0 | AI18: 0 | AJ18: 67435.807
B19: 510420 | C19: CARTERA DE CRÉDITOS PARA MICROCRÉDITO | D19: 17663.01 | E19: 289.4033 | F19: 105967.67 | G19: 1483.6005 | H19: 125403.68 | I19: 474.22521 | J19: 0 | K19: 0 | L19: 0 | M19: 0 | N19: 143.73113 | O19: 5234.3942 | P19: 314.02009 | Q19: 30264.633 | R19: 36431.004 | S19: 3683.5234 | T19: 2.21905 | U19: 572.24107 | V19: 92.05135 | W19: 642.45023 | X19: 87.46005 | Y19: 3734.013 | Z19: 3.97093 | AA19: 6221.9044 | AB19: 4913.1418 | AC19: 7513.5875 | AD19: 27466.563 | AE19: 189301.25 | AF19: 143.73113 | AG19: 92.05135 | AH19: 0 | AI19: 17469.505 | AJ19: 171595.96
B20: 510427 | C20: CARTERA DE CRÉDITO DE VIVIENDA DE INTERÉS SOCIAL Y PÚBLICO | D20: 0 | E20: 583.12607 | F20: 1450.6134 | G20: 0 | H20: 2033.7395 | I20: 0 | J20: 0 | K20: 0 | L20: 0 | M20: 68.28818 | N20: 8.0266 | O20: 0 | P20: 0 | Q20: 0 | R20: 76.31478 | S20: 0 | T20: 0 | U20: 0 | V20: 0 | W20: 0 | X20: 0 | Y20: 0 | Z20: 0 | AA20: 0 | AB20: 0 | AC20: 0 | AD20: 0 | AE20: 2110.0543 | AF20: 8.0266 | AG20: 68.28818 | AH20: 0 | AI20: 0 | AJ20: 2033.7395
B21: 510428 | C21: CARTERA DE CRÉDITO EDUCATIVO | D21: 82.56158 | E21: 10648.847 | F21: 712.65514 | G21: 42.60958 | H21: 11486.673 | I21: 0 | J21: 106.63579 | K21: 0 | L21: 0 | M21: 0 | N21: 0 | O21: 12.03454 | P21: 103.01293 | Q21: 0 | R21: 221.68326 | S21: 9.77186 | T21: 0 | U21: 0 | V21: 0 | W21: 0 | X21: 0 | Y21: 0 | Z21: 0 | AA21: 0 | AB21: 0 | AC21: 0 | AD21: 9.77186 | AE21: 11718.128 | AF21: 0 | AG21: 0 | AH21: 0 | AI21: 0 | AJ21: 11718.128
... B33: 4105 | C33: Otros INTERESES | D33: 0 | E33: 0 | F33: 4.67618 | G33: 0 | H33: 4.67618 | I33: 0 | J33: 0 | K33: 0 | L33: 0 | M33: 0 | N33: 0 | O33: 0 | P33: 0 | Q33: 0 | R33: 0 | S33: 0 | T33: 0.59317 | U33: 0.03458 | V33: 0 | W33: 0 | X33: 0 | Y33: 0 | Z33: 0 | AA33: 0 | AB33: 0 | AC33: 0 | AD33: 0.62775 | AE33: 5.30393 | AF33: 0 | AG33: 0 | AH33: 0 | AI33: 0 | AJ33: 5.30393
C34: MARGEN NETO INTERESES | D34: 129741.97 | E34: 114579.78 | F34: 397790.34 | G34: 125039.98 | H34: 767152.08 | I34: 42094.41 | J34: 71430.342 | K34: 8130.844 | L34: 69827.586 | M34: 29558.155 | N34: 66545.445 | O34: 17861.672 | P34: 18939.694 | Q34: 36670.234 | R34: 361058.38 | S34: 11615.225 | T34: 3885.1855 | U34: 1850.1956 | V34: 1447.3331 | W34: 3325.7343 | X34: 472.20699 | Y34: 2317.4205 | Z34: 537.14093 | AA34: 3952.6966 | AB34: 7650.0081 | AC34: 6078.5977 | AD34: 43131.744 | AE34: 1171342.2 | AF34: 74676.289 | AG34: 100833.07 | AH34: 0 | AI34: 12348.715 | AJ34: 983484.12
B36: 52 | C36: COMISIONES GANADAS | D36: 21391.943 | E36: 19526.661 | F36: 11137.514 | G36: 11428.572 | H36: 63484.69 | I36: 4720.1361 | J36: 12745.621 | K36: 982.206 | L36: 24600.997 | M36: 1965.1973 | N36: 9779.6769 | O36: 576.79386 | P36: 703.42245 | Q36: 1559.8926 | R36: 57633.943 | S36: 34.82991 | T36: 111.13061 | U36: 7.142 | V36: 0 | W36: 0 | X36: 0 | Y36: 0 | Z36: 23.38586 | AA36: 0 | AB36: 33.56565 | AC36: 0 | AD36: 210.05403 | AE36: 121328.69 | AF36: 10761.883 | AG36: 26566.194 | AH36: 0 | AI36: 0 | AJ36: 84000.61
B37: 5201 | C37: Cartera de créditos | D37: 23.51674 | E37: 0 | F37: 0 | G37: 0 | H37: 23.51674 | I37: 0 | J37: 0 | K37: 0 | L37: 0 | M37: 1.25743 | N37: 0 | O37: 0 | P37: 0 | Q37: 0 | R37: 1.25743 | S37: 0 | T37: 0 | U37: 0 | V37: 0 | W37: 0 | X37: 0 | Y37: 0 | Z37: 0 | AA37: 0 | AB37: 0 | AC37: 0 | AD37: 0 | AE37: 24.77417 | AF37: 0 | AG37: 1.25743 | AH37: 0 | AI37: 0 | AJ37: 23.51674
B38: 520105 | C38: Cartera de créditos productivo | D38: 0.58326 | E38: 0 | F38: 0 | G38: 0 | H38: 0.58326 | I38: 0 | J38: 0 | K38: 0 | L38: 0 | M38: 1.25743 | N38: 0 | O38: 0 | P38: 0 | Q38: 0 | R38: 1.25743 | S38: 0 | T38: 0 | U38: 0 | V38: 0 | W38: 0 | X38: 0 | Y38: 0 | Z38: 0 | AA38: 0 | AB38: 0 | AC38: 0 | AD38: 0 | AE38: 1.84069 | AF38: 0 | AG38: 1.25743 | AH38: 0 | AI38: 0 | AJ38: 0.58326
B39: 520110 | C39: Cartera de créditos de consumo | D39: 17.48745 | E39: 0 | F39: 0 | G39: 0 | H39: 17.48745 | I39: 0 | J39: 0 | K39: 0 | L39: 0 | M39: 0 | N39: 0 | O39: 0 | P39: 0 | Q39: 0 | R39: 0 | S39: 0 | T39: 0 | U39: 0 | V39: 0 | W39: 0 | X39: 0 | Y39: 0 | Z39: 0 | AA39: 0 | AB39: 0 | AC39: 0 | AD39: 0 | AE39: 17.48745 | AF39: 0 | AG39: 0 | AH39: 0 | AI39: 0 | AJ39: 17.48745
B40: 520115 | C40: Cartera de créditos de vivienda | D40: 0 | E40: 0 | F40: 0 | G40: 0 | H40: 0 | I40: 0 | J40: 0 | K40: 0 | L40: 0 | M40: 0 | N40: 0 | O40: 0 | P40: 0 | Q40: 0 | R40: 0 | S40: 0 | T40: 0 | U40: 0 | V40: 0 | W40: 0 | X40: 0 | Y40: 0 | Z40: 0 | AA40: 0 | AB40: 0 | AC40: 0 | AD40: 0 | AE40: 0 | AF40: 0 | AG40: 0 | AH40: 0 | AI40: 0 | AJ40: 0
B41: 520120 | C41: Cartera de créditos PARA MICROCRÉDITO | D41: 5.44603 | E41: 0 | F41: 0 | G41: 0 | H41: 5.44603 | I41: 0 | J41: 0 | K41: 0 | L41: 0 | M41: 0 | N41: 0 | O41: 0 | P41: 0 | Q41: 0 | R41: 0 | S41: 0 | T41: 0 | U41: 0 | V41: 0 | W41: 0 | X41: 0 | Y41: 0 | Z41: 0 | AA41: 0 | AB41: 0 | AC41: 0 | AD41: 0 | AE41: 5.44603 | AF41: 0 | AG41: 0 | AH41: 0 | AI41: 0 | AJ41: 5.44603
B42: 520125 | C42: Cartera de créditos reestructurada | D42: 0 | E42: 0 | F42: 0 | G42: 0 | H42: 0 | I42: 0 | J42: 0 | K42: 0 | L42: 0 | M42: 0 | N42: 0 | O42: 0 | P42: 0 | Q42: 0 | R42: 0 | S42: 0 | T42: 0 | U42: 0 | V42: 0 | W42: 0 | X42: 0 | Y42: 0 | Z42: 0 | AA42: 0 | AB42: 0 | AC42: 0 | AD42: 0 | AE42: 0 | AF42: 0 | AG42: 0 | AH42: 0 | AI42: 0 | AJ42: 0
B43: 5202 | C43: Deudores por aceptación | D43: 0 | E43: 0 | F43: 0 | G43: 0 | H43: 0 | I43: 0 | J43: 13.70995 | K43: 1.268 | L43: 0 | M43: 0 | N43: 0 | O43: 0 | P43: 40.88477 | Q43: 0 | R43: 55.86272 | S43: 0 | T43: 0 | U43: 0 | V43: 0 | W43: 0 | X43: 0 | Y43: 0 | Z43: 0 | AA43: 0 | AB43: 0 | AC43: 0 | AD43: 0 | AE43: 55.86272 | AF43: 1.268 | AG43: 0 | AH43: 0 | AI43: 0 | AJ43: 54.59472
B44: 5203 | C44: Avales | D44: 0 | E44: 6.58925 | F44: 1045.6899 | G44: 180.76152 | H44: 1233.0407 | I44: 54.86167 | J44: 621.95757 | K44: 0 | L44: 0 | M44: 19.88659 | N44: 247.76885 | O44: 35.20413 | P44: 37.68387 | Q44: 0 | R44: 1017.3627 | S44: 0 | T44: 13.85643 | U44: 0 | V44: 0 | W44: 0 | X44: 0 | Y44: 0 | Z44: 0 | AA44: 0 | AB44: 0 | AC44: 0 | AD44: 13.85643 | AE44: 2264.2598 | AF44: 247.76885 | AG44: 19.88659 | AH44: 0 | AI44: 0 | AJ44: 1996.6044
B45: 5204 | C45: Fianzas | D45: 1922.4764 | E45: 1377.0398 | F45: 3534.6389 | G45: 1824.6905 | H45: 8658.8457 | I45: 194.83421 | J45: 1390.762 | K45: 916.181 | L45: 0 | M45: 83.42296 | N45: 1052.1835 | O45: 0 | P45: 160.19944 | Q45: 2.6739 | R45: 3800.257 | S45: 15.77597 | T45: 14.05471 | U45: 7.142 | V45: 0 | W45: 0 | X45: 0 | Y45: 0 | Z45: 0 | AA45: 0 | AB45: 15.4098 | AC45: 0 | AD45: 52.38248 | AE45: 12511.485 | AF45: 1968.3645 | AG45: 83.42296 | AH45: 0 | AI45: 0 | AJ45: 10459.698
B46: 5205 | C46: Cartas de Crédito | D46: 1305.7746 | E46: 334.19445 | F46: 554.79979 | G46: 1153.3802 | H46: 3348.149 | I46: 73.96228 | J46: 1063.7079 | K46: 4.24 | L46: 0 | M46: 9.16902 | N46: 1720.2504 | O46: 0 | P46: 51.29647 | Q46: 0 | R46: 2922.6261 | S46: 17.76155 | T46: 0 | U46: 0 | V46: 0 | W46: 0 | X46: 0 | Y46: 0 | Z46: 0 | AA46: 0 | AB46: 0 | AC46: 0 | AD46: 17.76155 | AE46: 6288.5367 | AF46: 1724.4904 | AG46: 9.16902 | AH46: 0 | AI46: 0 | AJ46: 4554.8773
B47: 5290 | C47: Otras | D47: 18140.175 | E47: 17808.837 | F47: 6002.3857 | G47: 8269.7393 | H47: 50221.137 | I47: 4396.478 | J47: 9655.4838 | K47: 60.517 | L47: 24600.997 | M47: 1851.4613 | N47: 6759.4742 | O47: 541.58973 | P47: 413.3579 | Q47: 1557.2187 | R47: 49836.577 | S47: 1.29239 | T47: 83.21947 | U47: 0 | V47: 0 | W47: 0 | X47: 0 | Y47: 0 | Z47: 23.38586 | AA47: 0 | AB47: 18.15585 | AC47: 0 | AD47: 126.05357 | AE47: 100183.77 | AF47: 6819.9911 | AG47: 26452.458 | AH47: 0 | AI47: 0 | AJ47: 66911.319
... B83: 4390 | C83: Otras | D83: 0 | E83: 0 | F83: 0 | G83: 0 | H83: 0 | I83: 0 | J83: 0 | K83: 0 | L83: 0 | M83: 0 | N83: 0 | O83: 0 | P83: 0 | Q83: 0 | R83: 0 | S83: 0 | T83: 0 | U83: 0 | V83: 0 | W83: 0 | X83: 0 | Y83: 0 | Z83: 0 | AA83: 0 | AB83: 0 | AC83: 0 | AD83: 0 | AE83: 0 | AF83: 0 | AG83: 0 | AH83: 0 | AI83: 0 | AJ83: 0
C84: MARGEN BRUTO FINANCIERO | D84: 195932.67 | E84: 166719.25 | F84: 490455.75 | G84: 174228.87 | H84: 1027336.6 | I84: 51992.468 | J84: 100717.35 | K84: 9769.025 | L84: 148236.41 | M84: 35043.374 | N84: 90404.532 | O84: 19850.19 | P84: 21893.54 | Q84: 44883.56 | R84: 522790.45 | S84: 11567.235 | T84: 4560.3299 | U84: 2034.5267 | V84: 1527.5534 | W84: 3619.715 | X84: 474.54049 | Y84: 2362.8619 | Z84: 1672.6346 | AA84: 4001.0521 | AB84: 8509.2831 | AC84: 6365.9488 | AD84: 46695.681 | AE84: 1596822.7 | AF84: 100173.56 | AG84: 184807.34 | AH84: 0 | AI84: 12729.863 | AJ84: 1299111.9
B86: 44 | C86: PROVISIONES | D86: 39995.063 | E86: 63246.108 | F86: 192322.56 | G86: 37040.822 | H86: 332604.55 | I86: 15662.4 | J86: 12999.859 | K86: 462.469 | L86: 53295.309 | M86: 8917.2994 | N86: 9549.3827 | O86: 5124.3914 | P86: 3558.633 | Q86: 7286.674 | R86: 116856.42 | S86: 4280.5358 | T86: 1262.3231 | U86: 148.92189 | V86: 10.81132 | W86: 155.86145 | X86: 210.28555 | Y86: 102.79245 | Z86: 170.43417 | AA86: 2299.9605 | AB86: 3957.0552 | AC86: 958.12672 | AD86: 13557.108 | AE86: 463018.08 | AF86: 10011.852 | AG86: 62223.419 | AH86: 0 | AI86: 3360.8797 | AJ86: 387421.93
B87: 4401 | C87: Inversiones | D87: 0 | E87: 0.0035 | F87: 1595.4372 | G87: 0 | H87: 1595.4407 | I87: 531.47234 | J87: 0 | K87: 0 | L87: 730.20311 | M87: 0 | N87: 182.28085 | O87: 0 | P87: 91.14237 | Q87: 0 | R87: 1535.0987 | S87: 0 | T87: 0 | U87: 0 | V87: 0 | W87: 0 | X87: 0 | Y87: 0 | Z87: 0 | AA87: 0 | AB87: 166.4 | AC87: 0 | AD87: 166.4 | AE87: 3296.9394 | AF87: 182.28085 | AG87: 730.20311 | AH87: 0 | AI87: 0 | AJ87: 2384.4554
B88: 4402 | C88: CARTERA DE CRÉDITOS | D88: 37752.536 | E88: 56968.808 | F88: 162942.93 | G88: 31439.041 | H88: 289103.31 | I88: 12182.348 | J88: 11799.699 | K88: 0 | L88: 51901.367 | M88: 8558.5643 | N88: 7532.8514 | O88: 5106.009 | P88: 3364.9089 | Q88: 7015.2458 | R88: 107460.99 | S88: 4191.9168 | T88: 828.03948 | U88: 75.79146 | V88: 0 | W88: 150.50021 | X88: 186.81089 | Y88: 59.51512 | Z88: 170.43417 | AA88: 1917.8682 | AB88: 3468.7531 | AC88: 903.85687 | AD88: 11953.486 | AE88: 408517.79 | AF88: 7532.8514 | AG88: 60459.931 | AH88: 0 | AI88: 2881.2402 | AJ88: 337643.77
B89: 440210 | C89: CRÉDITO PRODUCTIVO | D89: 2322.4239 | E89: 24243.75 | F89: 55445.89 | G89: 9740.4557 | H89: 91752.52 | I89: 0 | J89: 2626.894 | K89: 0 | L89: 549.88686 | M89: 0 | N89: 2712.8578 | O89: 1446.5573 | P89: 752.34864 | Q89: 0.40476 | R89: 8088.9494 | S89: 3263.8181 | T89: 240.97934 | U89: 28.52472 | V89: 0 | W89: 31.54073 | X89: 51.70183 | Y89: 0 | Z89: 86.99822 | AA89: 0 | AB89: 72.63903 | AC89: 0 | AD89: 3776.2019 | AE89: 103617.67 | AF89: 2712.8578 | AG89: 549.88686 | AH89: 0 | AI89: 0 | AJ89: 100354.93
B90: 440220 | C90: CRÉDITO DE CONSUMO | D90: 26990.551 | E90: 27661.544 | F90: 42898.448 | G90: 20792.279 | H90: 118342.82 | I90: 11854.196 | J90: 8912.458 | K90: 0 | L90: 51351.48 | M90: 8558.5643 | N90: 4610.1507 | O90: 3180.7056 | P90: 2272.2506 | Q90: 2757.7924 | R90: 93497.598 | S90: 12.14225 | T90: 570.16168 | U90: 22.78619 | V90: 0 | W90: 22.12883 | X90: 135.0804 | Y90: 0 | Z90: 69.65948 | AA90: 0 | AB90: 914.51587 | AC90: 0.03304 | AD90: 1746.5077 | AE90: 213586.93 | AF90: 4610.1507 | AG90: 59910.044 | AH90: 0 | AI90: 0.03304 | AJ90: 149066.7
B91: 440230 | C91: CRÉDITO INMOBILIARIO | D91: 1077.0969 | E91: 1790.1313 | F91: 14640.943 | G91: 540.4826 | H91: 18048.654 | I91: 223.74046 | J91: 257.548 | K91: 0 | L91: 0 | M91: 0 | N91: 190.99832 | O91: 128.91926 | P91: 62.64023 | Q91: 1.99841 | R91: 865.84468 | S91: 63.58117 | T91: 11.52001 | U91: 0.00315 | V91: 0 | W91: 0.05689 | X91: 0 | Y91: 0 | Z91: 11.03353 | AA91: 0 | AB91: 105.95578 | AC91: 0 | AD91: 192.15053 | AE91: 19106.649 | AF91: 190.99832 | AG91: 0 | AH91: 0 | AI91: 0 | AJ91: 18915.651
B92: 440235 | C92: CRÉDITO DE VIVIENDA DE INTERÉS SOCIAL Y PÚBLICO | D92: 0 | E92: 1957.9408 | F92: 0 | G92: 0 | H92: 1957.9408 | I92: 0 | J92: 0 | K92: 0 | L92: 0 | M92: 0 | N92: 0.27365 | O92: 0 | P92: 0 | Q92: 0 | R92: 0.27365 | S92: 0 | T92: 0 | U92: 0 | V92: 0 | W92: 0 | X92: 0 | Y92: 0 | Z92: 0 | AA92: 0 | AB92: 0 | AC92: 0 | AD92: 0 | AE92: 1958.2144 | AF92: 0.27365 | AG92: 0 | AH92: 0 | AI92: 0 | AJ92: 1957.9408
...

Sheet BALANCE %
B3: ESTADO DE SITUACIÓN CONSOLIDADO
B4: SISTEMA DE BANCOS PRIVADOS
B5: 31/05/2022
B6: (en porcentajes)
B8: CÓDIGO | C8: CUENTA | D8: BP GUAYAQUIL | E8: BP PACIFICO | F8: BP PICHINCHA | G8: BP PRODUBANCO | H8: BANCOS PRIVADOS GRANDES | I8: BP AUSTRO | J8: BP BOLIVARIANO | K8: BP CITIBANK | L8: BP DINERS | M8: BP GENERAL RUMIÑAHUI | N8: BP INTERNACIONAL | O8: BP LOJA | P8: BP MACHALA | Q8: BP SOLIDARIO | R8: BANCOS PRIVADOS MEDIANOS | S8: BP PROCREDIT | T8: BP AMAZONAS | U8: BP COMERCIAL DE MANABI | V8: BP LITORAL | W8: BP COOPNACIONAL | X8: BP CAPITAL | Y8: BP FINCA S.A. | Z8: BP DELBANK | AA8: BP D-MIRO S.A. | AB8: BP BANCO DESARROLLO DE LOS PUEBLOS S.A., CODESARROLLO | AC8: BP VISIONFUND ECUADOR S.A. | AD8: BANCOS PRIVADOS PEQUEÑOS | AE8: TOTAL BANCOS PRIVADOS | AF8: BANCOS PRIVADOS COMERCIALES | AG8: BANCOS PRIVADOS CONSUMO | AH8: BANCOS PRIVADOS VIVIENDA | AI8: BANCOS PRIVADOS MICROCRÉDITO | AJ8: BANCA MÚLTIPLE
C9: ACTIVO
B10: 11 | C10: FONDOS DISPONIBLES | D10: 0.1223079 | E10: 0.1792381 | F10: 0.10765839 | G10: 0.15734738 | H10: 0.13455603 | I10: 0.15070159 | J10: 0.17509124 | K10: 0.3211318 | L10: 0.054087783 | M10: 0.16630376 | N10: 0.1277802 | O10: 0.20755983 | P10: 0.16815633 | Q10: 0.089290588 | R10: 0.14613953 | S10: 0.097962447 | T10: 0.10296113 | U10: 0.12017489 | V10: 0.058301551 | W10: 0.31646765 | X10: 0.060145047 | Y10: 0.13494502 | Z10: 0.22369657 | AA10: 0.0567199 | AB10: 0.098309962 | AC10: 0.039394228 | AD10: 0.12099656 | AE10: 0.13793452 | AF10: 0.15277579 | AG10: 0.088489843 | AH10: 0 | AI10: 0.073873501 | AJ10: 0.14039591
B11: 12 | C11: OPERACIONES INTERBANCARIAS | D11: 0 | E11: 0 | F11: 0 | G11: 0 | H11: 0 | I11: 0 | J11: 0 | K11: 0 | L11: 0 | M11: 0 | N11: 0 | O11: 0 | P11: 0 | Q11: 0 | R11: 0 | S11: 0 | T11: 0 | U11: 0 | V11: 0 | W11: 0 | X11: 0 | Y11: 0 | Z11: 0 | AA11: 0 | AB11: 0 | AC11: 0 | AD11: 0 | AE11: 0 | AF11: 0 | AG11: 0 | AH11: 0 | AI11: 0 | AJ11: 0
B12: 13 | C12: INVERSIONES | D12: 0.1605074 | E12: 0.14791673 | F12: 0.1781162 | G12: 0.10935397 | H12: 0.15559589 | I12: 0.18894837 | J12: 0.16372374 | K12: 0.19915556 | L12: 0.080377521 | M12: 0.1410227 | N12: 0.16528492 | O12: 0.12406263 | P12: 0.17917559 | Q12: 0.099664487 | R12: 0.15312355 | S12: 0.061352845 | T12: 0.24088279 | U12: 0.1398001 | V12: 0.14706059 | W12: 0.25432885 | X12: 0.10618313 | Y12: 0.11236891 | Z12: 0.15741382 | AA12: 0.14375069 | AB12: 0.12929572 | AC12: 0.019344686 | AD12: 0.13394364 | AE12: 0.15403903 | AF12: 0.16966356 | AG12: 0.099758731 | AH12: 0 | AI12: 0.092653436 | AJ12: 0.15675684
C13: INVERSIONES DEL SECTOR PRIVADO | D13: 0.028466303 | E13: 0.045576132 | F13: 0.040240692 | G13: 0.035274823 | H13: 0.03813051 | I13: 0.089069565 | J13: 0.057209092 | K13: 0.010587812 | L13: 0.0037953668 | M13: 0.046109415 | N13: 0.059358012 | O13: 0.056695106 | P13: 0.036796644 | Q13: 0.058748509 | R13: 0.051863966 | S13: 0.015697955 | T13: 0.09435568 | U13: 0.074286801 | V13: 0.061070641 | W13: 0.191337 | X13: 0.016065473 | Y13: 0.056526826 | Z13: 0.10569533 | AA13: 0.10935843 | AB13: 0.075170185 | AC13: 0.0036702701 | AD13: 0.067906333 | AE13: 0.043697266 | AF13: 0.05305323 | AG13: 0.017449956 | AH13: 0 | AI13: 0.058258969 | AJ13: 0.044520367
C14: INVERSIONES DEL SECTOR PUBLICO | D14: 0.13251792 | E14: 0.08635945 | F14: 0.13427745 | G14: 0.071665659 | H14: 0.11232663 | I14: 0.075795448 | J14: 0.098161009 | K14: 0.18856775 | L14: 0.065477552 | M14: 0.099750831 | N14: 0.077292996 | O14: 0.067228498 | P14: 0.14108354 | Q14: 0.040915978 | R14: 0.08756853 | S14: 0.043284129 | T14: 0.14134786 | U14: 0.066182977 | V14: 0.085989952 | W14: 0.06338035 | X14: 0.080968787 | Y14: 0.05584208 | Z14: 0.050221343 | AA14: 0.03439226 | AB14: 0.05481868 | AC14: 0.0156391 | AD14: 0.064336377 | AE14: 0.1024848 | AF14: 0.091678072 | AG14: 0.076220298 | AH14: 0 | AI14: 0.03438258 | AJ14: 0.10609756
B15: 1307 | C15: De disponibilidad restringida | D15: 0 | E15: 0.016490136 | F15: 0.011827054 | G15: 0.0024177083 | H15: 0.0087351436 | I15: 0.024315809 | J15: 0.0086172149 | K15: 0 | L15: 0.011428783 | M15: 9.8802523e-05 | N15: 0.028676945 | O15: 0.00014633747 | P15: 0.0013893121 | Q15: 0 | R15: 0.014132737 | S15: 0.0023707614 | T15: 0.0051792492 | U15: 0.00081725271 | V15: 0 | W15: 0 | X15: 0.0091488711 | Y15: 0 | Z15: 0.0015759409 | AA15: 0 | AB15: 0 | AC15: 3.531551e-05 | AD15: 0.001889724 | AE15: 0.010291482 | AF15: 0.024969725 | AG15: 0.0078205174 | AH15: 0 | AI15: 1.1887488e-05 | AJ15: 0.008908853
B16: 1399 | C16: (Provisión para inversiones) | D16: -0.00047681492 | E16: -0.00050898539 | F16: -0.008228995 | G16: -4.215749e-06 | H16: -0.0035963937 | I16: -0.00023244846 | J16: -0.00026357765 | K16: 0 | L16: -0.00032418133 | M16: -0.0049363513 | N16: -4.3028099e-05 | O16: -7.316874e-06 | P16: -9.3908418e-05 | Q16: 0 | R16: -0.00044168316 | S16: 0 | T16: 0 | U16: -0.0014869356 | V16: 0 | W16: -0.00038850345 | X16: 0 | Y16: 0 | Z16: -7.8797044e-05 | AA16: 0 | AB16: -0.0006931438 | AC16: 0 | AD16: -0.00018879955 | AE16: -0.0024345168 | AF16: -3.7465629e-05 | AG16: -0.00173204 | AH16: 0 | AI16: 0 | AJ16: -0.0027699402
B17: 14 | C17: CARTERA DE CRÉDITOS | D17: 0.65434598 | E17: 0.5733756 | F17: 0.61189648 | G17: 0.67310584 | H17: 0.62364934 | I17: 0.56053398 | J17: 0.61628005 | K17: 0.45033101 | L17: 0.80027775 | M17: 0.65455406 | N17: 0.65805584 | O17: 0.61635111 | P17: 0.59320612 | Q17: 0.76027304 | R17: 0.64420153 | S17: 0.80163942 | T17: 0.53787655 | U17: 0.61963702 | V17: 0.71211684 | W17: 0.39462979 | X17: 0.53966589 | Y17: 0.67071447 | Z17: 0.46676788 | AA17: 0.71328527 | AB17: 0.71586893 | AC17: 0.91017958 | AD17: 0.67548151 | AE17: 0.63222764 | AF17: 0.63120215 | AG17: 0.75458998 | AH17: 0 | AI17: 0.76705255 | AJ17: 0.62231585
C18: CARTERA DE CRÉDITOS PRODUCTIVO | D18: 0.35005502 | E18: 0.21213691 | F18: 0.25789686 | G18: 0.43851518 | H18: 0.30016294 | I18: 0.31845217 | J18: 0.46751342 | K18: 0.47768885 | L18: 0.053484083 | M18: 0.071249421 | N18: 0.57330381 | O18: 0.20309367 | P18: 0.40346491 | Q18: 4.206197e-05 | R18: 0.3608248 | S18: 0.63511252 | T18: 0.26634282 | U18: 0.34605609 | V18: 0.21292292 | W18: 0.36490452 | X18: 0.046340553 | Y18: 0 | Z18: 0.33213658 | AA18: 0 | AB18: 0.090938365 | AC18: 0 | AD18: 0.33122151 | AE18: 0.32133113 | AF18: 0.56094316 | AG18: 0.060875955 | AH18: 0 | AI18: 0 | AJ18: 0.31621195
C19: CARTERA DE CRÉDITOS CONSUMO | D19: 0.25614143 | E19: 0.29518867 | F19: 0.25123968 | G19: 0.21874049 | H19: 0.25515054 | I19: 0.23824433 | J19: 0.15127197 | K19: 0 | L19: 0.85191733 | M19: 0.54100883 | N19: 0.083928812 | O19: 0.29988666 | P19: 0.17771778 | Q19: 0.37648461 | R19: 0.27205784 | S19: 0.0071157035 | T19: 0.281924 | U19: 0.17592976 | V19: 0.50424762 | W19: 0.004157191 | X19: 0.47212795 | Y19: 0.062708384 | Z19: 0.1070248 | AA19: 0 | AB19: 0.28893569 | AC19: 0.00041644412 | AD19: 0.12003181 | AE19: 0.25615506 | AF19: 0.07307889 | AG19: 0.75248488 | AH19: 0 | AI19: 0.018566324 | AJ19: 0.24102815
C20: CARTERA DE CRÉDITOS INMOBILIARIO | D20: 0.035438712 | E20: 0.059002268 | F20: 0.059814169 | G20: 0.041692546 | H20: 0.051532677 | I20: 0.026186803 | J20: 0.018619355 | K20: 0 | L20: 9.5475034e-05 | M20: 0.099638751 | N20: 0.027980413 | O20: 0.060653674 | P20: 0.021763349 | Q20: 3.1286611e-05 | R20: 0.024523638 | S20: 0.052525433 | T20: 0.0057192277 | U20: 0.00020686301 | V20: 0.0021392659 | W20: 0.00066837674 | X20: 2.5229e-08 | Y20: 0 | Z20: 0.050723786 | AA20: 0 | AB20: 0.052292564 | AC20: 0 | AD20: 0.026377962 | AE20: 0.041722128 | AF20: 0.024363237 | AG20: 0.030591707 | AH20: 0 | AI20: 0 | AJ20: 0.044760836
C21: CARTERA DE CRÉDITOS MICROCRÉDITO | D21: 0.041906965 | E21: 0.00092381842 | F21: 0.11813161 | G21: 0.0045431747 | H21: 0.057938406 | I21: 0.0032394687 | J21: 0 | K21: 0 | L21: 0 | M21: 1.5818e-08 | N21: 0.00048148179 | O21: 0.11363387 | P21: 0.005300895 | Q21: 0.46380284 | R21: 0.027303453 | S21: 0.12715489 | T21: 0.00071912933 | U21: 0.13649206 | V21: 0.038334003 | W21: 0.037079035 | X21: 0.059254521 | Y21: 0.64287553 | Z21: 0.0016899161 | AA21: 0.78013848 | AB21: 0.34330692 | AC21: 0.97829969 | AD21: 0.22968388 | AE21: 0.053629969 | AF21: 0.00041923809 | AG21: 0.0004697407 | AH21: 0 | AI21: 0.806508 | AJ21: 0.058583039
C22: CARTERA DE CRÉDITOS VIVIENDA DE INTERÉS SOCIAL Y PÚBLICO | D22: 0 | E22: 0.0029166991 | F22: 0.0003415332 | G22: 0 | H22: 0.00074197986 | I22: 0 | J22: 0 | K22: 0 | L22: 0 | M22: 0.0058546745 | N22: 9.2686992e-05 | O22: 0 | P22: 0 | Q22: 0 | R22: 0.0003613329 | S22: 0 | T22: 0 | U22: 0 | V22: 0 | W22: 0 | X22: 0 | Y22: 0 | Z22: 0 | AA22: 0 | AB22: 0 | AC22: 0 | AD22: 0 | AE22: 0.00059052397 | AF22: 8.0704854e-05 | AG22: 0.0017921741 | AH22: 0 | AI22: 0 | AJ22: 0.00056141602
C23: CARTERA DE CRÃ¿DITOS EDUCATIVO | D23: 0.00031895373 | E23: 0.043485168 | F23: 0.0015056475 | G23: 0.00022552375 | H23: 0.0096851163 | I23: 0 | J23: 0.0006301591 | K23: 0 | L23: 0 | M23: 0 | N23: 0 | O23: 0.00049605023 | P23: 0.0027936597 | Q23: 0 | R23: 0.00033244127 | S23: 0.00046289349 | T23: 0 | U23: 0 | V23: 0 | W23: 0 | X23: 0 | Y23: 0 | Z23: 0 | AA23: 0 | AB23: 0 | AC23: 0 | AD23: 0.00015361416 | AE23: 0.0062599728 | AF23: 0 | AG23: 0 | AH23: 0 | AI23: 0 | AJ23: 0.0074658837
C24: CARTERA DE CRÉDITO INVERSIÓN PÚBLICA | D24: 0 | E24: 0 | F24: 0 | G24: 0 | H24: 0 | I24: 0 | J24: 0 | K24: 0 | L24: 0 | M24: 0 | N24: 0 | O24: 0 | P24: 0 | Q24: 0 | R24: 0 | S24: 0 | T24: 0 | U24: 0 | V24: 0 | W24: 0 | X24: 0 | Y24: 0 | Z24: 0 | AA24: 0 | AB24: 0 | AC24: 0 | AD24: 0 | AE24: 0 | AF24: 0 | AG24: 0 | AH24: 0 | AI24: 0 | AJ24: 0
B25: 1499 | C25: (PROVISIONES PARA CRÉDITOS INCOBRABLES) | D25: -0.0295151 | E25: -0.040277929 | F25: -0.077033016 | G25: -0.030611085 | H25: -0.051562313 | I25: -0.025588793 | J25: -0.021754856 | K25: -0.027357839 | L25: -0.10521913 | M25: -0.063197632 | N25: -0.027731371 | O25: -0.061412813 | P25: -0.017834468 | Q25: -0.080087757 | R25: -0.041201969 | S25: -0.02073202 | T25: -0.016828626 | U25: -0.039047754 | V25: -0.045526971 | W25: -0.01217934 | X25: -0.038057159 | Y25: -0.034869444 | Z25: -0.024807197 | AA25: -0.066853208 | AB25: -0.059604613 | AC25: -0.068536551 | AD25: -0.031987267 | AE25: -0.047461137 | AF25: -0.027683083 | AG25: -0.091624479 | AH25: 0 | AI25: -0.058021769 | AJ25: -0.046295422
B26: 149905 | C26: (CARTERA DE CRÉDITOS PRODUCTIVO) | D26: -0.006611408 | E26: -0.0035214961 | F26: -0.018173328 | G26: -0.0071096433 | H26: -0.010843113 | I26: -0.0040419934 | J26: -0.0060766664 | K26: -0.013245232 | L26: -0.0013031147 | M26: -0.0034755127 | N26: -0.014493461 | O26: -0.0095907231 | P26: -0.0043085782 | Q26: -7.63891e-07 | R26: -0.0071051382 | S26: -0.0098190886 | T26: -0.004067978 | U26: -0.0054548563 | V26: -0.0020455547 | W26: -0.0036211616 | X26: -0.0014769158 | Y26: 0 | Z26: -0.0059575019 | AA26: 0 | AB26: -0.0014669754 | AC26: 0 | AD26: -0.0048981408 | AE26: -0.0094014775 | AF26: -0.014332096 | AG26: -0.001977205 | AH26: 0 | AI26: 0 | AJ26: -0.0094686943
B27: 149910 | C27: (CARTERA DE CRÉDITOS DE CONSUMO) | D27: -0.004886227 | E27: -0.0075313813 | F27: -0.0049783022 | G27: -0.003705466 | H27: -0.0052478822 | I27: -0.010428609 | J27: -0.0029204287 | K27: 0 | L27: -0.0221082 | M27: -0.013899097 | N27: -0.003016296 | O27: -0.0061029106 | P27: -0.0045501003 | Q27: -0.019378876 | R27: -0.0079821373 | S27: -0.00017719325 | T27: -0.006936158 | U27: -0.01016766 | V27: -0.019677447 | W27: -2.4711935e-05 | X27: -0.01285711 | Y27: -0.0029010583 | Z27: -0.0038020113 | AA27: 0 | AB27: -0.0052316671 | AC27: -4.421789e-06 | AD27: -0.0031692351 | AE27: -0.0060835704 | AF27: -0.0026263635 | AG27: -0.019565526 | AH27: 0 | AI27: -0.0008539314 | AJ27: -0.0054958263
B28: 149915 | C28: (CARTERA DE CRÉDITOS INMOBILIARIO) | D28: -0.00075725606 | E28: -0.0014353543 | F28: -0.0013858865 | G28: -0.00090976346 | H28: -0.0011851718 | I28: -0.00041509146 | J28: -0.00050542338 | K28: 0 | L28: 0 | M28: -0.0015263051 | N28: -0.00061042085 | O28: -0.00091289155 | P28: -0.00050366064 | Q28: -1.6364144e-05 | R28: -0.00048679657 | S28: -0.00066375789 | T28: -8.9355554e-05 | U28: -2.06863e-06 | V28: -2.4696e-08 | W28: -4.469252e-06 | X28: -2.5229e-08 | Y28: 0 | Z28: -0.001025512 | AA28: 0 | AB28: -0.0011683603 | AC28: 0 | AD28: -0.00040966005 | AE28: -0.00092724061 | AF28: -0.00053150851 | AG28: -0.00046721748 | AH28: 0 | AI28: 0 | AJ28: -0.0010117668
B29: 149920 | C29: (CARTERA DE CRÉDITOS PARA MICROCRÉDITO) | D29: -0.0010940151 | E29: -8.2857012e-05 | F29: -0.002264724 | G29: -9.5297902e-05 | H29: -0.0011819446 | I29: -0.0002774784 | J29: 0 | K29: 0 | L29: 0 | M29: -1.384e-08 | N29: -2.1590314e-05 | O29: -0.002551937 | P29: -0.00028683392 | Q29: -0.02964895 | R29: -0.0015659251 | S29: -0.003044766 | T29: -9.672434e-05 | U29: -0.012482829 | V29: -0.0013610909 | W29: -0.00033245804 | X29: -0.0024981316 | Y29: -0.010132082 | Z29: -6.5814758e-05 | AA29: -0.045709938 | AB29: -0.012688553 | AC29: -0.045074638 | AD29: -0.0089387124 | AE29: -0.0015733494 | AF29: -1.879922e-05 | AG29: -1.6682724e-05 | AH29: 0 | AI29: -0.035041942 | AJ29: -0.0016429765
B30: 149940 | C30: (CARTERA DE CRÉDITOS DE VIVIENDA DE INTERÉS SOCIAL Y PÚBLICO) | D30: 0 | E30: -0.00054939122 | F30: -5.050289e-06 | G30: 0 | H30: -0.00011527746 | I30: 0 | J30: 0 | K30: 0 | L30: 0 | M30: -8.669674e-05 | N30: -1.056505e-06 | O30: 0 | P30: 0 | Q30: 0 | R30: -5.273155e-06 | S30: 0 | T30: 0 | U30: 0 | V30: 0 | W30: 0 | X30: 0 | Y30: 0 | Z30: 0 | AA30: 0 | AB30: 0 | AC30: 0 | AD30: 0 | AE30: -7.4883675e-05 | AF30: -9.19925e-07 | AG30: -2.6538735e-05 | AH30: 0 | AI30: 0 | AJ30: -8.7224218e-05
B31: 149945 | C31: (CARTERA DE CRÉDITO REFINANCIADA) | D31: -0.00076187939 | E31: -0.002808541 | F31: -0.00093722098 | G31: -0.00063715819 | H31: -0.0012325881 | I31: -0.0021507433 | J31: -1.8136554e-05 | K31: 0 | L31: -0.0020662871 | M31: -0.00060443965 | N31: -0.00091836433 | O31: -0.0046161195 | P31: -0.00035362552 | Q31: -0.00047116933 | R31: -0.0010519526 | S31: -0.0049141897 | T31: -0.0013813139 | U31: -0.00186261 | V31: -0.010568414 | W31: -0.0005977507 | X31: -0.0001986338 | Y31: -0.0067064235 | Z31: -0.0034314367 | AA31: -0.0052713371 | AB31: -0.020504115 | AC31: -0.0047837168 | AD31: -0.0059246776 | AE31: -0.0013324628 | AF31: -0.00079964252 | AG31: -0.0017229841 | AH31: 0 | AI31: -0.0055288839 | AJ31: -0.0013350729
B32: 149950 | C32: (CARTERA DE CRÉDITO REESTRUCTURADA) | D32: -0.002790832 | E32: -0.0090265551 | F32: -0.0085820764 | G32: -0.0076752219 | H32: -0.0073829608 | I32: -0.0060959594 | J32: -0.0013013967 | K32: -0.0017995904 | L32: -0.022090344 | M32: -0.021080192 | N32: -0.0027480505 | O32: -0.015193525 | P32: -0.0033672769 | Q32: -0.0012960529 | R32: -0.0068187124 | S32: -0.0015680669 | T32: -0.0040588298 | U32: -7.4623999e-05 | V32: -0.010341173 | W32: 0 | X32: -0.0030969522 | Y32: -0.014961781 | Z32: -0.0079483089 | AA32: -0.0035521906 | AB32: -0.003324229 | AC32: -0.00063853671 | AD32: -0.0030280538 | AE32: -0.007047622 | AF32: -0.0026254381 | AG32: -0.021637155 | AH32: 0 | AI32: -0.0059240094 | AJ32: -0.0064576461
B33: 149955 | C33: (CARTERA DE CRÉDITO EDUCATIVO) | D33: -1.3722543e-05 | E33: -0.0012604986 | F33: -1.7898643e-05 | G33: -3.701315e-06 | H33: -0.00027044339 | I33: 0 | J33: -2.0812295e-05 | K33: 0 | L33: 0 | M33: 0 | N33: 0 | O33: -4.849053e-06 | P33: -3.9469422e-05 | Q33: 0 | R33: -7.599178e-06 | S33: -4.994222e-06 | T33: 0 | U33: 0 | V33: 0 | W33: 0 | X33: 0 | Y33: 0 | Z33: 0 | AA33: 0 | AB33: 0 | AC33: 0 | AD33: -1.657364e-06 | AE33: -0.0001741532 | AF33: 0 | AG33: 0 | AH33: 0 | AI33: 0 | AJ33: -0.00020770178
B34: 149960 | C34: (CARTERA DE CRÉDITO DE INVERSIÓN PÚBLICA) | D34: 0 | E34: 0 | F34: 0 | G34: 0 | H34: 0 | I34: 0 | J34: 0 | K34: 0 | L34: 0 | M34: 0 | N34: 0 | O34: 0 | P34: 0 | Q34: 0 | R34: 0 | S34: 0 | T34: 0 | U34: 0 | V34: 0 | W34: 0 | X34: 0 | Y34: 0 | Z34: 0 | AA34: 0 | AB34: 0 | AC34: 0 | AD34: 0 | AE34: 0 | AF34: 0 | AG34: 0 | AH34: 0 | AI34: 0 | AJ34: 0
B35: 149980 | C35: PROVISIÓN GÉNERICA POR TECNOLOGÍA CREDITICIA | D35: 0 | E35: 0 | F35: 0 | G35: 0 | H35: 0 | I35: 0 | J35: 0 | K35: 0 | L35: 0 | M35: 0 | N35: 0 | O35: 0 | P35: 0 | Q35: 0 | R35: 0 | S35: 0 | T35: 0 | U35: -0.0026785404 | V35: -0.0006693343 | W35: 0 | X35: -0.0073609812 | Y35: 0 | Z35: 0 | AA35: 0 | AB35: 0 | AC35: 0 | AD35: -0.00026874092 | AE35: -9.150257e-06 | AF35: 0 | AG35: -8.201865e-06 | AH35: 0 | AI35: 0 | AJ35: -1.0300259e-05
B36: 149985 | C36: PROVISIÓN ANTICÍCLICA | D36: -0.00019068459 | E36: -0.0012387494 | F36: -0.012414878 | G36: -0.00064306937 | H36: -0.0055398568 | I36: 0 | J36: -0.00053354442 | K36: 0 | L36: 0 | M36: -0.00099638467 | N36: 0 | O36: 0 | P36: -0.00093247458 | Q36: 0 | R36: -0.00024317693 | S36: 0 | T36: -0.00012919938 | U36: 0 | V36: -0.00064457404 | W36: 0 | X36: -0.00074126134 | Y36: 0 | Z36: -0.0018026356 | AA36: 0 | AB36: 0 | AC36: 0 | AD36: -8.3766572e-05 | AE36: -0.0035981234 | AF36: 0 | AG36: -0.00031290173 | AH36: 0 | AI36: 0 | AJ36: -0.0042678858
... B44: 1 | C44: TOTAL ACTIVO | D44: 1 | E44: 1 | F44: 1 | G44: 1 | H44: 1 | I44: 1 | J44: 1 | K44: 1 | L44: 1 | M44: 1 | N44: 1 | O44: 1 | P44: 1 | Q44: 1 | R44: 1 | S44: 1 | T44: 1 | U44: 1 | V44: 1 | W44: 1 | X44: 1 | Y44: 1 | Z44: 1 | AA44: 1 | AB44: 1 | AC44: 1 | AD44: 1 | AE44: 1 | AF44: 1 | AG44: 1 | AH44: 0 | AI44: 1 | AJ44: 1
C47: PASIVOS
B48: 21 | C48: OBLIGACIONES CON EL PÚBLICO | D48: 0.86848658 | E48: 0.87349035 | F48: 0.90361787 | G48: 0.84214244 | H48: 0.87897975 | I48: 0.92849319 | J48: 0.88090067 | K48: 0.91704589 | L48: 0.61865049 | M48: 0.92774138 | N48: 0.92656051 | O48: 0.92333518 | P48: 0.92680055 | Q48: 0.59944311 | R48: 0.86543756 | S48: 0.64153196 | T48: 0.91641313 | U48: 0.9745992 | V48: 0.9507785 | W48: 0.97839733 | X48: 0.91880302 | Y48: 0.8494628 | Z48: 0.8857499 | AA48: 0.5124507 | AB48: 0.8398632 | AC48: 0.25027102 | AD48: 0.76043753 | AE48: 0.8706161 | AF48: 0.92536889 | AG48: 0.72673035 | AH48: 0 | AI48: 0.53310782 | AJ48: 0.87640829
B49: 2101 | C49: Depósitos a la vista | D49: 0.52661618 | E49: 0.44499769 | F49: 0.61418847 | G49: 0.51918817 | H49: 0.54502709 | I49: 0.47324169 | J49: 0.56689705 | K49: 0.9159501 | L49: 0.0090326927 | M49: 0.41812565 | N49: 0.55155314 | O49: 0.50936271 | P49: 0.48924272 | Q49: 0.12229509 | R49: 0.46369026 | S49: 0.38089195 | T49: 0.33271883 | U49: 0.72548597 | V49: 0.34382059 | W49: 0.68722085 | X49: 0.1015907 | Y49: 0.080017588 | Z49: 0.47036763 | AA49: 0.069567154 | AB49: 0.31262659 | AC49: 0.077185409 | AD49: 0.35444241 | AE49: 0.51206634 | AF49: 0.59719054 | AG49: 0.15095894 | AH49: 0 | AI49: 0.075302493 | AJ49: 0.52989536
B50: 2102 | C50: Operaciones de reporto | D50: 0 | E50: 0 | F50: 0 | G50: 0 | H50: 0 | I50: 0 | J50: 0 | K50: 0 | L50: 0 | M50: 0 | N50: 0 | O50: 0 | P50: 0 | Q50: 0 | R50: 0 | S50: 0 | T50: 0 | U50: 0 | V50: 0 | W50: 0 | X50: 0 | Y50: 0 | Z50: 0 | AA50: 0 | AB50: 0 | AC50: 0 | AD50: 0 | AE50: 0 | AF50: 0 | AG50: 0 | AH50: 0 | AI50: 0 | AJ50: 0
B51: 2103 | C51: Depósitos a plazo | D51: 0.31467151 | E51: 0.37384489 | F51: 0.2541022 | G51: 0.30209125 | H51: 0.299097 | I51: 0.43560204 | J51: 0.27505757 | K51: 0 | L51: 0.60358618 | M51: 0.50960117 | N51: 0.35205195 | O51: 0.41394769 | P51: 0.39947307 | Q51: 0.47225819 | R51: 0.38004376 | S51: 0.23092976 | T51: 0.54307855 | U51: 0.20632396 | V51: 0.59355049 | W51: 0.25755795 | X51: 0.81480534 | Y51: 0.76944521 | Z51: 0.37377445 | AA51: 0.44288354 | AB51: 0.51587956 | AC51: 0.17292157 | AD51: 0.38145002 | AE51: 0.32834451 | AF51: 0.30796064 | AG51: 0.57169567 | AH51: 0 | AI51: 0.45775226 | AJ51: 0.31323467
B52: 2104 | C52: Depósitos de garantía | D52: 0 | E52: 0 | F52: 3.0284868e-05 | G52: 0 | H52: 1.2521155e-05 | I52: 0.00011225764 | J52: 0.00011464789 | K52: 0 | L52: 0 | M52: 0 | N52: 2.1465063e-05 | O52: 0 | P52: 0 | Q52: 0 | R52: 5.083773e-05 | S52: 0 | T52: 9.780751e-05 | U52: 6.337503e-06 | V52: 3.4480771e-05 | W52: 0 | X52: 0 | Y52: 0 | Z52: 0 | AA52: 0 | AB52: 0 | AC52: 0 | AD52: 1.748837e-05 | AE52: 2.5238778e-05 | AF52: 1.8776759e-05 | AG52: 3.68957e-07 | AH52: 0 | AI52: 0 | AJ52: 2.7804671e-05
...

Sheet EPyG %
B3: ESTADO DE PÉRDIDAS Y GANANCIAS
B4: SISTEMA DE BANCOS PRIVADOS
B5: 31/05/2022
B6: (en porcentajes)
B8: CÓDIGO | C8: CUENTA | D8: BP GUAYAQUIL | E8: BP PACIFICO | F8: BP PICHINCHA | G8: BP PRODUBANCO | H8: BANCOS PRIVADOS GRANDES | I8: BP AUSTRO | J8: BP BOLIVARIANO | K8: BP CITIBANK | L8: BP DINERS | M8: BP GENERAL RUMIÑAHUI | N8: BP INTERNACIONAL | O8: BP LOJA | P8: BP MACHALA | Q8: BP SOLIDARIO | R8: BANCOS PRIVADOS MEDIANOS | S8: BP PROCREDIT | T8: BP AMAZONAS | U8: BP COMERCIAL DE MANABI | V8: BP LITORAL | W8: BP COOPNACIONAL | X8: BP CAPITAL | Y8: BP FINCA S.A. | Z8: BP DELBANK | AA8: BP D-MIRO S.A. | AB8: BP BANCO DESARROLLO DE LOS PUEBLOS S.A., CODESARROLLO | AC8: BP VISIONFUND ECUADOR S.A. | AD8: BANCOS PRIVADOS PEQUEÑOS | AE8: TOTAL BANCOS PRIVADOS | AF8: BANCOS PRIVADOS COMERCIALES | AG8: BANCOS PRIVADOS CONSUMO | AH8: BANCOS PRIVADOS VIVIENDA | AI8: BANCOS PRIVADOS MICROCRÉDITO | AJ8: BANCA MÚLTIPLE
C9: TOTAL INGRESOS | D9: 1 | E9: 1 | F9: 1 | G9: 1 | H9: 1 | I9: 1 | J9: 1 | K9: 1 | L9: 1 | M9: 1 | N9: 1 | O9: 1 | P9: 1 | Q9: 1 | R9: 1 | S9: 1 | T9: 1 | U9: 1 | V9: 1 | W9: 1 | X9: 1 | Y9: 1 | Z9: 1 | AA9: 1 | AB9: 1 | AC9: 1 | AD9: 1 | AE9: 1 | AF9: 1 | AG9: 1 | AH9: 0 | AI9: 1 | AJ9: 1
B11: 51 | C11: INTERESES Y DESCUENTOS GANADOS | D11: 0.67508833 | E11: 0.60002421 | F11: 0.7143389 | G11: 0.69385369 | H11: 0.68051713 | I11: 0.7113919 | J11: 0.75112215 | K11: 0.55707948 | L11: 0.4664324 | M11: 0.81654124 | N11: 0.77141365 | O11: 0.86604976 | P11: 0.84270462 | Q11: 0.7692829 | R11: 0.68558301 | S11: 0.84068448 | T11: 0.80475518 | U11: 0.86013517 | V11: 0.90032165 | W11: 0.8352522 | X11: 0.75193128 | Y11: 0.78538396 | Z11: 0.31278219 | AA11: 0.77872122 | AB11: 0.79006077 | AC11: 0.86146654 | AD11: 0.80458305 | AE11: 0.68661936 | AF11: 0.75076633 | AG11: 0.5384683 | AH11: 0 | AI11: 0.8119614 | AJ11: 0.69946912
B12: 5101 | C12: Depósitos | D12: 0.0005625104 | E12: 5.73287e-05 | F12: 0.000222181 | G12: 0.0030807328 | H12: 0.0007171893 | I12: 0.01393141 | J12: 0.0072689096 | K12: 0.008475121 | L12: 8.93554e-05 | M12: 0.0073423531 | N12: 0.0059315694 | O12: 0.0022947014 | P12: 0.0075620705 | Q12: 0.0005093244 | R12: 0.0053279401 | S12: 0.0040374516 | T12: 0.0083106545 | U12: 3.37541e-05 | V12: 3.29955e-05 | W12: 0.14271329 | X12: 0.000534588 | Y12: 6.60047e-05 | Z12: 0.012140827 | AA12: 0.0005231631 | AB12: 0.002773611 | AC12: 0.0020988349 | AD12: 0.011946769 | AE12: 0.002620058 | AF12: 0.0061765957 | AG12: 0.0015135883 | AH12: 0 | AI12: 0.001008046 | AJ12: 0.0025101032
B13: 5102 | C13: Operaciones interbancarias | D13: 0 | E13: 0 | F13: 5.6671e-06 | G13: 0.0001617516 | H13: 2.89541e-05 | I13: 0 | J13: 8.80297e-05 | K13: 0.0004382977 | L13: 8.135e-07 | M13: 0 | N13: 0 | O13: 0 | P13: 0 | Q13: 0 | R13: 2.43593e-05 | S13: 0 | T13: 0 | U13: 0 | V13: 0 | W13: 0 | X13: 0 | Y13: 0 | Z13: 0 | AA13: 0 | AB13: 0 | AC13: 0 | AD13: 0 | AE13: 2.642e-05 | AF13: 4.22222e-05 | AG13: 6.476e-07 | AH13: 0 | AI13: 0 | AJ13: 2.8882e-05
